Workbook

Sheet journals
C1: eco_bus | F1: eco | H1: fin | J1: bus | L1: man
A2: journal | B2: publisher | C2: pub | D2: score | E2: rank | F2: score | G2: rank | H2: score | I2: rank | J2: score | K2: rank | L2: score | M2: rank | N2: wc1 | O2: wc2 | P2: wc3 | Q2: wc4 | R2: wc5 | S2: wc6
A3: QUARTERLY JOURNAL OF ECONOMICS | B3: OXFORD UNIV PRESS INC | C3: =IFERROR(VLOOKUP(A3,[1]eco_bus_journals!$B:$D,3,0),"") -> 40 | D3: =IFERROR(ROUND(VLOOKUP(A3,[1]eco_bus_journals!$B:$X,4,0),2),"") -> 10 | E3: =_xlfn.RANK.EQ(D3,D:D) -> 1 | F3: =IFERROR(ROUND(VLOOKUP(A3,[1]eco_journals!B:E,4,0),2),"") -> 10 | G3: =IFERROR(_xlfn.RANK.EQ(F3,F:F),"") -> 1 | H3: =IFERROR(ROUND(VLOOKUP(A3,[1]fin_journals!B:E,4,0),2),"") | I3: =IFERROR(_xlfn.RANK.EQ(H3,H:H),"") | J3: =IFERROR(ROUND(VLOOKUP(A3,[1]bus_journals!B:E,4,0),2),"") | K3: =IFERROR(_xlfn.RANK.EQ(J3,J:J),"") | L3: =IFERROR(ROUND(VLOOKUP(A3,[1]man_journals!B:E,4,0),2),"") | M3: =IFERROR(_xlfn.RANK.EQ(L3,L:L),"") | N3: ECONOMICS
A4: AMERICAN ECONOMIC REVIEW | B4: AMER ECONOMIC ASSOC | C4: =IFERROR(VLOOKUP(A4,[1]eco_bus_journals!$B:$D,3,0),"") -> 116 | D4: =IFERROR(ROUND(VLOOKUP(A4,[1]eco_bus_journals!$B:$X,4,0),2),"") -> 6.51 | E4: =_xlfn.RANK.EQ(D4,D:D) -> 2 | F4: =IFERROR(ROUND(VLOOKUP(A4,[1]eco_journals!B:E,4,0),2),"") -> 6.48 | G4: =IFERROR(_xlfn.RANK.EQ(F4,F:F),"") -> 2 | H4: =IFERROR(ROUND(VLOOKUP(A4,[1]fin_journals!B:E,4,0),2),"") | I4: =IFERROR(_xlfn.RANK.EQ(H4,H:H),"") | J4: =IFERROR(ROUND(VLOOKUP(A4,[1]bus_journals!B:E,4,0),2),"") | K4: =IFERROR(_xlfn.RANK.EQ(J4,J:J),"") | L4: =IFERROR(ROUND(VLOOKUP(A4,[1]man_journals!B:E,4,0),2),"") | M4: =IFERROR(_xlfn.RANK.EQ(L4,L:L),"") | N4: ECONOMICS
A5: JOURNAL OF POLITICAL ECONOMY | B5: UNIV CHICAGO PRESS | C5: =IFERROR(VLOOKUP(A5,[1]eco_bus_journals!$B:$D,3,0),"") -> 110 | D5: =IFERROR(ROUND(VLOOKUP(A5,[1]eco_bus_journals!$B:$X,4,0),2),"") -> 4.65 | E5: =_xlfn.RANK.EQ(D5,D:D) -> 4 | F5: =IFERROR(ROUND(VLOOKUP(A5,[1]eco_journals!B:E,4,0),2),"") -> 4.67 | G5: =IFERROR(_xlfn.RANK.EQ(F5,F:F),"") -> 3 | H5: =IFERROR(ROUND(VLOOKUP(A5,[1]fin_journals!B:E,4,0),2),"") | I5: =IFERROR(_xlfn.RANK.EQ(H5,H:H),"") | J5: =IFERROR(ROUND(VLOOKUP(A5,[1]bus_journals!B:E,4,0),2),"") | K5: =IFERROR(_xlfn.RANK.EQ(J5,J:J),"") | L5: =IFERROR(ROUND(VLOOKUP(A5,[1]man_journals!B:E,4,0),2),"") | M5: =IFERROR(_xlfn.RANK.EQ(L5,L:L),"") | N5: ECONOMICS
A6: REVIEW OF ECONOMIC STUDIES | B6: OXFORD UNIV PRESS | C6: =IFERROR(VLOOKUP(A6,[1]eco_bus_journals!$B:$D,3,0),"") -> 80 | D6: =IFERROR(ROUND(VLOOKUP(A6,[1]eco_bus_journals!$B:$X,4,0),2),"") -> 4.32 | E6: =_xlfn.RANK.EQ(D6,D:D) -> 6 | F6: =IFERROR(ROUND(VLOOKUP(A6,[1]eco_journals!B:E,4,0),2),"") -> 4.38 | G6: =IFERROR(_xlfn.RANK.EQ(F6,F:F),"") -> 4 | H6: =IFERROR(ROUND(VLOOKUP(A6,[1]fin_journals!B:E,4,0),2),"") | I6: =IFERROR(_xlfn.RANK.EQ(H6,H:H),"") | J6: =IFERROR(ROUND(VLOOKUP(A6,[1]bus_journals!B:E,4,0),2),"") | K6: =IFERROR(_xlfn.RANK.EQ(J6,J:J),"") | L6: =IFERROR(ROUND(VLOOKUP(A6,[1]man_journals!B:E,4,0),2),"") | M6: =IFERROR(_xlfn.RANK.EQ(L6,L:L),"") | N6: ECONOMICS
A7: ECONOMETRICA | B7: WILEY | C7: =IFERROR(VLOOKUP(A7,[1]eco_bus_journals!$B:$D,3,0),"") -> 76 | D7: =IFERROR(ROUND(VLOOKUP(A7,[1]eco_bus_journals!$B:$X,4,0),2),"") -> 4.53 | E7: =_xlfn.RANK.EQ(D7,D:D) -> 5 | F7: =IFERROR(ROUND(VLOOKUP(A7,[1]eco_journals!B:E,4,0),2),"") -> 4.38 | G7: =IFERROR(_xlfn.RANK.EQ(F7,F:F),"") -> 4 | H7: =IFERROR(ROUND(VLOOKUP(A7,[1]fin_journals!B:E,4,0),2),"") | I7: =IFERROR(_xlfn.RANK.EQ(H7,H:H),"") | J7: =IFERROR(ROUND(VLOOKUP(A7,[1]bus_journals!B:E,4,0),2),"") | K7: =IFERROR(_xlfn.RANK.EQ(J7,J:J),"") | L7: =IFERROR(ROUND(VLOOKUP(A7,[1]man_journals!B:E,4,0),2),"") | M7: =IFERROR(_xlfn.RANK.EQ(L7,L:L),"") | N7: ECONOMICS | O7: MATHEMATICS, INTERDISCIPLINARY APPLICATIONS | P7: SOCIAL SCIENCES, MATHEMATICAL METHODS | Q7: STATISTICS & PROBABILITY
A8: NBER MACROECONOMICS ANNUAL | B8: UNIV CHICAGO PRESS | C8: =IFERROR(VLOOKUP(A8,[1]eco_bus_journals!$B:$D,3,0),"") -> 7 | D8: =IFERROR(ROUND(VLOOKUP(A8,[1]eco_bus_journals!$B:$X,4,0),2),"") -> 4.25 | E8: =_xlfn.RANK.EQ(D8,D:D) -> 7 | F8: =IFERROR(ROUND(VLOOKUP(A8,[1]eco_journals!B:E,4,0),2),"") -> 4.36 | G8: =IFERROR(_xlfn.RANK.EQ(F8,F:F),"") -> 6 | H8: =IFERROR(ROUND(VLOOKUP(A8,[1]fin_journals!B:E,4,0),2),"") | I8: =IFERROR(_xlfn.RANK.EQ(H8,H:H),"") | J8: =IFERROR(ROUND(VLOOKUP(A8,[1]bus_journals!B:E,4,0),2),"") | K8: =IFERROR(_xlfn.RANK.EQ(J8,J:J),"") | L8: =IFERROR(ROUND(VLOOKUP(A8,[1]man_journals!B:E,4,0),2),"") | M8: =IFERROR(_xlfn.RANK.EQ(L8,L:L),"") | N8: ECONOMICS
A9: ACADEMY OF MANAGEMENT ANNALS | B9: ACAD MANAGEMENT | C9: =IFERROR(VLOOKUP(A9,[1]eco_bus_journals!$B:$D,3,0),"") -> 31 | D9: =IFERROR(ROUND(VLOOKUP(A9,[1]eco_bus_journals!$B:$X,4,0),2),"") -> 4.71 | E9: =_xlfn.RANK.EQ(D9,D:D) -> 3 | F9: =IFERROR(ROUND(VLOOKUP(A9,[1]eco_journals!B:E,4,0),2),"") | G9: =IFERROR(_xlfn.RANK.EQ(F9,F:F),"") | H9: =IFERROR(ROUND(VLOOKUP(A9,[1]fin_journals!B:E,4,0),2),"") | I9: =IFERROR(_xlfn.RANK.EQ(H9,H:H),"") | J9: =IFERROR(ROUND(VLOOKUP(A9,[1]bus_journals!B:E,4,0),2),"") -> 10 | K9: =IFERROR(_xlfn.RANK.EQ(J9,J:J),"") -> 1 | L9: =IFERROR(ROUND(VLOOKUP(A9,[1]man_journals!B:E,4,0),2),"") -> 10 | M9: =IFERROR(_xlfn.RANK.EQ(L9,L:L),"") -> 1 | N9: BUSINESS | O9: MANAGEMENT
A10: JOURNAL OF FINANCE | B10: WILEY | C10: =IFERROR(VLOOKUP(A10,[1]eco_bus_journals!$B:$D,3,0),"") -> 73 | D10: =IFERROR(ROUND(VLOOKUP(A10,[1]eco_bus_journals!$B:$X,4,0),2),"") -> 3.84 | E10: =_xlfn.RANK.EQ(D10,D:D) -> 9 | F10: =IFERROR(ROUND(VLOOKUP(A10,[1]eco_journals!B:E,4,0),2),"") -> 3.01 | G10: =IFERROR(_xlfn.RANK.EQ(F10,F:F),"") -> 11 | H10: =IFERROR(ROUND(VLOOKUP(A10,[1]fin_journals!B:E,4,0),2),"") -> 10 | I10: =IFERROR(_xlfn.RANK.EQ(H10,H:H),"") -> 1 | J10: =IFERROR(ROUND(VLOOKUP(A10,[1]bus_journals!B:E,4,0),2),"") | K10: =IFERROR(_xlfn.RANK.EQ(J10,J:J),"") | L10: =IFERROR(ROUND(VLOOKUP(A10,[1]man_journals!B:E,4,0),2),"") | M10: =IFERROR(_xlfn.RANK.EQ(L10,L:L),"") | N10: FINANCE | O10: ECONOMICS
A11: JOURNAL OF ECONOMIC LITERATURE | B11: AMER ECONOMIC ASSOC | C11: =IFERROR(VLOOKUP(A11,[1]eco_bus_journals!$B:$D,3,0),"") -> 16 | D11: =IFERROR(ROUND(VLOOKUP(A11,[1]eco_bus_journals!$B:$X,4,0),2),"") -> 4.14 | E11: =_xlfn.RANK.EQ(D11,D:D) -> 8 | F11: =IFERROR(ROUND(VLOOKUP(A11,[1]eco_journals!B:E,4,0),2),"") -> 4.1 | G11: =IFERROR(_xlfn.RANK.EQ(F11,F:F),"") -> 7 | H11: =IFERROR(ROUND(VLOOKUP(A11,[1]fin_journals!B:E,4,0),2),"") | I11: =IFERROR(_xlfn.RANK.EQ(H11,H:H),"") | J11: =IFERROR(ROUND(VLOOKUP(A11,[1]bus_journals!B:E,4,0),2),"") | K11: =IFERROR(_xlfn.RANK.EQ(J11,J:J),"") | L11: =IFERROR(ROUND(VLOOKUP(A11,[1]man_journals!B:E,4,0),2),"") | M11: =IFERROR(_xlfn.RANK.EQ(L11,L:L),"") | N11: ECONOMICS
A12: AMERICAN ECONOMIC REVIEW-INSIGHTS | B12: AMER ECONOMIC ASSOC | C12: =IFERROR(VLOOKUP(A12,[1]eco_bus_journals!$B:$D,3,0),"") -> 32 | D12: =IFERROR(ROUND(VLOOKUP(A12,[1]eco_bus_journals!$B:$X,4,0),2),"") -> 3.72 | E12: =_xlfn.RANK.EQ(D12,D:D) -> 10 | F12: =IFERROR(ROUND(VLOOKUP(A12,[1]eco_journals!B:E,4,0),2),"") -> 3.72 | G12: =IFERROR(_xlfn.RANK.EQ(F12,F:F),"") -> 8 | H12: =IFERROR(ROUND(VLOOKUP(A12,[1]fin_journals!B:E,4,0),2),"") | I12: =IFERROR(_xlfn.RANK.EQ(H12,H:H),"") | J12: =IFERROR(ROUND(VLOOKUP(A12,[1]bus_journals!B:E,4,0),2),"") | K12: =IFERROR(_xlfn.RANK.EQ(J12,J:J),"") | L12: =IFERROR(ROUND(VLOOKUP(A12,[1]man_journals!B:E,4,0),2),"") | M12: =IFERROR(_xlfn.RANK.EQ(L12,L:L),"") | N12: ECONOMICS
A13: BROOKINGS PAPERS ON ECONOMIC ACTIVITY | B13: JOHNS HOPKINS UNIV PRESS | C13: =IFERROR(VLOOKUP(A13,[1]eco_bus_journals!$B:$D,3,0),"") -> 24 | D13: =IFERROR(ROUND(VLOOKUP(A13,[1]eco_bus_journals!$B:$X,4,0),2),"") -> 3.63 | E13: =_xlfn.RANK.EQ(D13,D:D) -> 12 | F13: =IFERROR(ROUND(VLOOKUP(A13,[1]eco_journals!B:E,4,0),2),"") -> 3.69 | G13: =IFERROR(_xlfn.RANK.EQ(F13,F:F),"") -> 9 | H13: =IFERROR(ROUND(VLOOKUP(A13,[1]fin_journals!B:E,4,0),2),"") | I13: =IFERROR(_xlfn.RANK.EQ(H13,H:H),"") | J13: =IFERROR(ROUND(VLOOKUP(A13,[1]bus_journals!B:E,4,0),2),"") | K13: =IFERROR(_xlfn.RANK.EQ(J13,J:J),"") | L13: =IFERROR(ROUND(VLOOKUP(A13,[1]man_journals!B:E,4,0),2),"") | M13: =IFERROR(_xlfn.RANK.EQ(L13,L:L),"") | N13: ECONOMICS
A14: REVIEW OF FINANCIAL STUDIES | B14: OXFORD UNIV PRESS INC | C14: =IFERROR(VLOOKUP(A14,[1]eco_bus_journals!$B:$D,3,0),"") -> 141 | D14: =IFERROR(ROUND(VLOOKUP(A14,[1]eco_bus_journals!$B:$X,4,0),2),"") -> 3.16 | E14: =_xlfn.RANK.EQ(D14,D:D) -> 13 | F14: =IFERROR(ROUND(VLOOKUP(A14,[1]eco_journals!B:E,4,0),2),"") -> 2.23 | G14: =IFERROR(_xlfn.RANK.EQ(F14,F:F),"") -> 18 | H14: =IFERROR(ROUND(VLOOKUP(A14,[1]fin_journals!B:E,4,0),2),"") -> 9.15 | I14: =IFERROR(_xlfn.RANK.EQ(H14,H:H),"") -> 3 | J14: =IFERROR(ROUND(VLOOKUP(A14,[1]bus_journals!B:E,4,0),2),"") | K14: =IFERROR(_xlfn.RANK.EQ(J14,J:J),"") | L14: =IFERROR(ROUND(VLOOKUP(A14,[1]man_journals!B:E,4,0),2),"") | M14: =IFERROR(_xlfn.RANK.EQ(L14,L:L),"") | N14: FINANCE | O14: ECONOMICS
A15: ADMINISTRATIVE SCIENCE QUARTERLY | B15: SAGE PUBLICATIONS | C15: =IFERROR(VLOOKUP(A15,[1]eco_bus_journals!$B:$D,3,0),"") -> 39 | D15: =IFERROR(ROUND(VLOOKUP(A15,[1]eco_bus_journals!$B:$X,4,0),2),"") -> 3.66 | E15: =_xlfn.RANK.EQ(D15,D:D) -> 11 | F15: =IFERROR(ROUND(VLOOKUP(A15,[1]eco_journals!B:E,4,0),2),"") | G15: =IFERROR(_xlfn.RANK.EQ(F15,F:F),"") | H15: =IFERROR(ROUND(VLOOKUP(A15,[1]fin_journals!B:E,4,0),2),"") | I15: =IFERROR(_xlfn.RANK.EQ(H15,H:H),"") | J15: =IFERROR(ROUND(VLOOKUP(A15,[1]bus_journals!B:E,4,0),2),"") -> 8.4 | K15: =IFERROR(_xlfn.RANK.EQ(J15,J:J),"") -> 3 | L15: =IFERROR(ROUND(VLOOKUP(A15,[1]man_journals!B:E,4,0),2),"") -> 7.8 | M15: =IFERROR(_xlfn.RANK.EQ(L15,L:L),"") -> 2 | N15: BUSINESS | O15: MANAGEMENT
A16: AMERICAN ECONOMIC JOURNAL-APPLIED ECONOMICS | B16: AMER ECONOMIC ASSOC | C16: =IFERROR(VLOOKUP(A16,[1]eco_bus_journals!$B:$D,3,0),"") -> 43 | D16: =IFERROR(ROUND(VLOOKUP(A16,[1]eco_bus_journals!$B:$X,4,0),2),"") -> 3.11 | E16: =_xlfn.RANK.EQ(D16,D:D) -> 14 | F16: =IFERROR(ROUND(VLOOKUP(A16,[1]eco_journals!B:E,4,0),2),"") -> 3.22 | G16: =IFERROR(_xlfn.RANK.EQ(F16,F:F),"") -> 10 | H16: =IFERROR(ROUND(VLOOKUP(A16,[1]fin_journals!B:E,4,0),2),"") | I16: =IFERROR(_xlfn.RANK.EQ(H16,H:H),"") | J16: =IFERROR(ROUND(VLOOKUP(A16,[1]bus_journals!B:E,4,0),2),"") | K16: =IFERROR(_xlfn.RANK.EQ(J16,J:J),"") | L16: =IFERROR(ROUND(VLOOKUP(A16,[1]man_journals!B:E,4,0),2),"") | M16: =IFERROR(_xlfn.RANK.EQ(L16,L:L),"") | N16: ECONOMICS
A17: AMERICAN ECONOMIC JOURNAL-MACROECONOMICS | B17: AMER ECONOMIC ASSOC | C17: =IFERROR(VLOOKUP(A17,[1]eco_bus_journals!$B:$D,3,0),"") -> 38 | D17: =IFERROR(ROUND(VLOOKUP(A17,[1]eco_bus_journals!$B:$X,4,0),2),"") -> 2.8 | E17: =_xlfn.RANK.EQ(D17,D:D) -> 17 | F17: =IFERROR(ROUND(VLOOKUP(A17,[1]eco_journals!B:E,4,0),2),"") -> 2.91 | G17: =IFERROR(_xlfn.RANK.EQ(F17,F:F),"") -> 12 | H17: =IFERROR(ROUND(VLOOKUP(A17,[1]fin_journals!B:E,4,0),2),"") | I17: =IFERROR(_xlfn.RANK.EQ(H17,H:H),"") | J17: =IFERROR(ROUND(VLOOKUP(A17,[1]bus_journals!B:E,4,0),2),"") | K17: =IFERROR(_xlfn.RANK.EQ(J17,J:J),"") | L17: =IFERROR(ROUND(VLOOKUP(A17,[1]man_journals!B:E,4,0),2),"") | M17: =IFERROR(_xlfn.RANK.EQ(L17,L:L),"") | N17: ECONOMICS
A18: JOURNAL OF LABOR ECONOMICS | B18: UNIV CHICAGO PRESS | C18: =IFERROR(VLOOKUP(A18,[1]eco_bus_journals!$B:$D,3,0),"") -> 32 | D18: =IFERROR(ROUND(VLOOKUP(A18,[1]eco_bus_journals!$B:$X,4,0),2),"") -> 2.96 | E18: =_xlfn.RANK.EQ(D18,D:D) -> 15 | F18: =IFERROR(ROUND(VLOOKUP(A18,[1]eco_journals!B:E,4,0),2),"") -> 2.9 | G18: =IFERROR(_xlfn.RANK.EQ(F18,F:F),"") -> 13 | H18: =IFERROR(ROUND(VLOOKUP(A18,[1]fin_journals!B:E,4,0),2),"") | I18: =IFERROR(_xlfn.RANK.EQ(H18,H:H),"") | J18: =IFERROR(ROUND(VLOOKUP(A18,[1]bus_journals!B:E,4,0),2),"") | K18: =IFERROR(_xlfn.RANK.EQ(J18,J:J),"") | L18: =IFERROR(ROUND(VLOOKUP(A18,[1]man_journals!B:E,4,0),2),"") | M18: =IFERROR(_xlfn.RANK.EQ(L18,L:L),"") | N18: ECONOMICS | O18: INDUSTRIAL RELATIONS & LABOR
A19: JOURNAL OF FINANCIAL ECONOMICS | B19: ELSEVIER | C19: =IFERROR(VLOOKUP(A19,[1]eco_bus_journals!$B:$D,3,0),"") -> 152 | D19: =IFERROR(ROUND(VLOOKUP(A19,[1]eco_bus_journals!$B:$X,4,0),2),"") -> 2.65 | E19: =_xlfn.RANK.EQ(D19,D:D) -> 20 | F19: =IFERROR(ROUND(VLOOKUP(A19,[1]eco_journals!B:E,4,0),2),"") -> 1.77 | G19: =IFERROR(_xlfn.RANK.EQ(F19,F:F),"") -> 20 | H19: =IFERROR(ROUND(VLOOKUP(A19,[1]fin_journals!B:E,4,0),2),"") -> 7.81 | I19: =IFERROR(_xlfn.RANK.EQ(H19,H:H),"") -> 5 | J19: =IFERROR(ROUND(VLOOKUP(A19,[1]bus_journals!B:E,4,0),2),"") | K19: =IFERROR(_xlfn.RANK.EQ(J19,J:J),"") | L19: =IFERROR(ROUND(VLOOKUP(A19,[1]man_journals!B:E,4,0),2),"") | M19: =IFERROR(_xlfn.RANK.EQ(L19,L:L),"") | N19: FINANCE | O19: ECONOMICS
A20: JOURNAL OF MARKETING | B20: SAGE PUBLICATIONS | C20: =IFERROR(VLOOKUP(A20,[1]eco_bus_journals!$B:$D,3,0),"") -> 65 | D20: =IFERROR(ROUND(VLOOKUP(A20,[1]eco_bus_journals!$B:$X,4,0),2),"") -> 2.72 | E20: =_xlfn.RANK.EQ(D20,D:D) -> 18 | F20: =IFERROR(ROUND(VLOOKUP(A20,[1]eco_journals!B:E,4,0),2),"") | G20: =IFERROR(_xlfn.RANK.EQ(F20,F:F),"") | H20: =IFERROR(ROUND(VLOOKUP(A20,[1]fin_journals!B:E,4,0),2),"") | I20: =IFERROR(_xlfn.RANK.EQ(H20,H:H),"") | J20: =IFERROR(ROUND(VLOOKUP(A20,[1]bus_journals!B:E,4,0),2),"") -> 9.17 | K20: =IFERROR(_xlfn.RANK.EQ(J20,J:J),"") -> 2 | L20: =IFERROR(ROUND(VLOOKUP(A20,[1]man_journals!B:E,4,0),2),"") | M20: =IFERROR(_xlfn.RANK.EQ(L20,L:L),"") | N20: BUSINESS
A21: JOURNAL OF ECONOMIC PERSPECTIVES | B21: AMER ECONOMIC ASSOC | C21: =IFERROR(VLOOKUP(A21,[1]eco_bus_journals!$B:$D,3,0),"") -> 41 | D21: =IFERROR(ROUND(VLOOKUP(A21,[1]eco_bus_journals!$B:$X,4,0),2),"") -> 2.81 | E21: =_xlfn.RANK.EQ(D21,D:D) -> 16 | F21: =IFERROR(ROUND(VLOOKUP(A21,[1]eco_journals!B:E,4,0),2),"") -> 2.67 | G21: =IFERROR(_xlfn.RANK.EQ(F21,F:F),"") -> 14 | H21: =IFERROR(ROUND(VLOOKUP(A21,[1]fin_journals!B:E,4,0),2),"") | I21: =IFERROR(_xlfn.RANK.EQ(H21,H:H),"") | J21: =IFERROR(ROUND(VLOOKUP(A21,[1]bus_journals!B:E,4,0),2),"") | K21: =IFERROR(_xlfn.RANK.EQ(J21,J:J),"") | L21: =IFERROR(ROUND(VLOOKUP(A21,[1]man_journals!B:E,4,0),2),"") | M21: =IFERROR(_xlfn.RANK.EQ(L21,L:L),"") | N21: ECONOMICS
A22: REVIEW OF ECONOMICS AND STATISTICS | B22: MIT PRESS | C22: =IFERROR(VLOOKUP(A22,[1]eco_bus_journals!$B:$D,3,0),"") -> 65 | D22: =IFERROR(ROUND(VLOOKUP(A22,[1]eco_bus_journals!$B:$X,4,0),2),"") -> 2.68 | E22: =_xlfn.RANK.EQ(D22,D:D) -> 19 | F22: =IFERROR(ROUND(VLOOKUP(A22,[1]eco_journals!B:E,4,0),2),"") -> 2.65 | G22: =IFERROR(_xlfn.RANK.EQ(F22,F:F),"") -> 15 | H22: =IFERROR(ROUND(VLOOKUP(A22,[1]fin_journals!B:E,4,0),2),"") | I22: =IFERROR(_xlfn.RANK.EQ(H22,H:H),"") | J22: =IFERROR(ROUND(VLOOKUP(A22,[1]bus_journals!B:E,4,0),2),"") | K22: =IFERROR(_xlfn.RANK.EQ(J22,J:J),"") | L22: =IFERROR(ROUND(VLOOKUP(A22,[1]man_journals!B:E,4,0),2),"") | M22: =IFERROR(_xlfn.RANK.EQ(L22,L:L),"") | N22: ECONOMICS | O22: SOCIAL SCIENCES, MATHEMATICAL METHODS
A23: AMERICAN ECONOMIC JOURNAL-ECONOMIC POLICY | B23: AMER ECONOMIC ASSOC | C23: =IFERROR(VLOOKUP(A23,[1]eco_bus_journals!$B:$D,3,0),"") -> 51 | D23: =IFERROR(ROUND(VLOOKUP(A23,[1]eco_bus_journals!$B:$X,4,0),2),"") -> 2.6 | E23: =_xlfn.RANK.EQ(D23,D:D) -> 21 | F23: =IFERROR(ROUND(VLOOKUP(A23,[1]eco_journals!B:E,4,0),2),"") -> 2.58 | G23: =IFERROR(_xlfn.RANK.EQ(F23,F:F),"") -> 16 | H23: =IFERROR(ROUND(VLOOKUP(A23,[1]fin_journals!B:E,4,0),2),"") | I23: =IFERROR(_xlfn.RANK.EQ(H23,H:H),"") | J23: =IFERROR(ROUND(VLOOKUP(A23,[1]bus_journals!B:E,4,0),2),"") | K23: =IFERROR(_xlfn.RANK.EQ(J23,J:J),"") | L23: =IFERROR(ROUND(VLOOKUP(A23,[1]man_journals!B:E,4,0),2),"") | M23: =IFERROR(_xlfn.RANK.EQ(L23,L:L),"") | N23: ECONOMICS
A24: ANNUAL REVIEW OF ECONOMICS | B24: ANNUAL REVIEWS | C24: =IFERROR(VLOOKUP(A24,[1]eco_bus_journals!$B:$D,3,0),"") -> 31 | D24: =IFERROR(ROUND(VLOOKUP(A24,[1]eco_bus_journals!$B:$X,4,0),2),"") -> 2.48 | E24: =_xlfn.RANK.EQ(D24,D:D) -> 23 | F24: =IFERROR(ROUND(VLOOKUP(A24,[1]eco_journals!B:E,4,0),2),"") -> 2.52 | G24: =IFERROR(_xlfn.RANK.EQ(F24,F:F),"") -> 17 | H24: =IFERROR(ROUND(VLOOKUP(A24,[1]fin_journals!B:E,4,0),2),"") | I24: =IFERROR(_xlfn.RANK.EQ(H24,H:H),"") | J24: =IFERROR(ROUND(VLOOKUP(A24,[1]bus_journals!B:E,4,0),2),"") | K24: =IFERROR(_xlfn.RANK.EQ(J24,J:J),"") | L24: =IFERROR(ROUND(VLOOKUP(A24,[1]man_journals!B:E,4,0),2),"") | M24: =IFERROR(_xlfn.RANK.EQ(L24,L:L),"") | N24: ECONOMICS
A25: ACADEMY OF MANAGEMENT JOURNAL | B25: ACAD MANAGEMENT | C25: =IFERROR(VLOOKUP(A25,[1]eco_bus_journals!$B:$D,3,0),"") -> 71 | D25: =IFERROR(ROUND(VLOOKUP(A25,[1]eco_bus_journals!$B:$X,4,0),2),"") -> 2.49 | E25: =_xlfn.RANK.EQ(D25,D:D) -> 22 | F25: =IFERROR(ROUND(VLOOKUP(A25,[1]eco_journals!B:E,4,0),2),"") | G25: =IFERROR(_xlfn.RANK.EQ(F25,F:F),"") | H25: =IFERROR(ROUND(VLOOKUP(A25,[1]fin_journals!B:E,4,0),2),"") | I25: =IFERROR(_xlfn.RANK.EQ(H25,H:H),"") | J25: =IFERROR(ROUND(VLOOKUP(A25,[1]bus_journals!B:E,4,0),2),"") -> 5.72 | K25: =IFERROR(_xlfn.RANK.EQ(J25,J:J),"") -> 5 | L25: =IFERROR(ROUND(VLOOKUP(A25,[1]man_journals!B:E,4,0),2),"") -> 5.22 | M25: =IFERROR(_xlfn.RANK.EQ(L25,L:L),"") -> 3 | N25: BUSINESS | O25: MANAGEMENT
A26: JOURNAL OF ACCOUNTING & ECONOMICS | B26: ELSEVIER | C26: =IFERROR(VLOOKUP(A26,[1]eco_bus_journals!$B:$D,3,0),"") -> 35 | D26: =IFERROR(ROUND(VLOOKUP(A26,[1]eco_bus_journals!$B:$X,4,0),2),"") -> 2.39 | E26: =_xlfn.RANK.EQ(D26,D:D) -> 24 | F26: =IFERROR(ROUND(VLOOKUP(A26,[1]eco_journals!B:E,4,0),2),"") -> 0.85 | G26: =IFERROR(_xlfn.RANK.EQ(F26,F:F),"") -> 38 | H26: =IFERROR(ROUND(VLOOKUP(A26,[1]fin_journals!B:E,4,0),2),"") -> 9.36 | I26: =IFERROR(_xlfn.RANK.EQ(H26,H:H),"") -> 2 | J26: =IFERROR(ROUND(VLOOKUP(A26,[1]bus_journals!B:E,4,0),2),"") | K26: =IFERROR(_xlfn.RANK.EQ(J26,J:J),"") | L26: =IFERROR(ROUND(VLOOKUP(A26,[1]man_journals!B:E,4,0),2),"") | M26: =IFERROR(_xlfn.RANK.EQ(L26,L:L),"") | N26: FINANCE | O26: ECONOMICS
A27: JOURNAL OF PUBLIC ECONOMICS | B27: ELSEVIER | C27: =IFERROR(VLOOKUP(A27,[1]eco_bus_journals!$B:$D,3,0),"") -> 133 | D27: =IFERROR(ROUND(VLOOKUP(A27,[1]eco_bus_journals!$B:$X,4,0),2),"") -> 2.16 | E27: =_xlfn.RANK.EQ(D27,D:D) -> 25 | F27: =IFERROR(ROUND(VLOOKUP(A27,[1]eco_journals!B:E,4,0),2),"") -> 2.16 | G27: =IFERROR(_xlfn.RANK.EQ(F27,F:F),"") -> 19 | H27: =IFERROR(ROUND(VLOOKUP(A27,[1]fin_journals!B:E,4,0),2),"") | I27: =IFERROR(_xlfn.RANK.EQ(H27,H:H),"") | J27: =IFERROR(ROUND(VLOOKUP(A27,[1]bus_journals!B:E,4,0),2),"") | K27: =IFERROR(_xlfn.RANK.EQ(J27,J:J),"") | L27: =IFERROR(ROUND(VLOOKUP(A27,[1]man_journals!B:E,4,0),2),"") | M27: =IFERROR(_xlfn.RANK.EQ(L27,L:L),"") | N27: ECONOMICS
A28: JOURNAL OF ACCOUNTING RESEARCH | B28: WILEY | C28: =IFERROR(VLOOKUP(A28,[1]eco_bus_journals!$B:$D,3,0),"") -> 34 | D28: =IFERROR(ROUND(VLOOKUP(A28,[1]eco_bus_journals!$B:$X,4,0),2),"") -> 2.16 | E28: =_xlfn.RANK.EQ(D28,D:D) -> 25 | F28: =IFERROR(ROUND(VLOOKUP(A28,[1]eco_journals!B:E,4,0),2),"") | G28: =IFERROR(_xlfn.RANK.EQ(F28,F:F),"") | H28: =IFERROR(ROUND(VLOOKUP(A28,[1]fin_journals!B:E,4,0),2),"") -> 8.64 | I28: =IFERROR(_xlfn.RANK.EQ(H28,H:H),"") -> 4 | J28: =IFERROR(ROUND(VLOOKUP(A28,[1]bus_journals!B:E,4,0),2),"") | K28: =IFERROR(_xlfn.RANK.EQ(J28,J:J),"") | L28: =IFERROR(ROUND(VLOOKUP(A28,[1]man_journals!B:E,4,0),2),"") | M28: =IFERROR(_xlfn.RANK.EQ(L28,L:L),"") | N28: FINANCE
A29: ACADEMY OF MANAGEMENT REVIEW | B29: ACAD MANAGEMENT | C29: =IFERROR(VLOOKUP(A29,[1]eco_bus_journals!$B:$D,3,0),"") -> 40 | D29: =IFERROR(ROUND(VLOOKUP(A29,[1]eco_bus_journals!$B:$X,4,0),2),"") -> 2.1 | E29: =_xlfn.RANK.EQ(D29,D:D) -> 27 | F29: =IFERROR(ROUND(VLOOKUP(A29,[1]eco_journals!B:E,4,0),2),"") | G29: =IFERROR(_xlfn.RANK.EQ(F29,F:F),"") | H29: =IFERROR(ROUND(VLOOKUP(A29,[1]fin_journals!B:E,4,0),2),"") | I29: =IFERROR(_xlfn.RANK.EQ(H29,H:H),"") | J29: =IFERROR(ROUND(VLOOKUP(A29,[1]bus_journals!B:E,4,0),2),"") -> 4.98 | K29: =IFERROR(_xlfn.RANK.EQ(J29,J:J),"") -> 6 | L29: =IFERROR(ROUND(VLOOKUP(A29,[1]man_journals!B:E,4,0),2),"") -> 4.66 | M29: =IFERROR(_xlfn.RANK.EQ(L29,L:L),"") -> 4 | N29: BUSINESS | O29: MANAGEMENT
A30: STRATEGIC MANAGEMENT JOURNAL | B30: WILEY | C30: =IFERROR(VLOOKUP(A30,[1]eco_bus_journals!$B:$D,3,0),"") -> 121 | D30: =IFERROR(ROUND(VLOOKUP(A30,[1]eco_bus_journals!$B:$X,4,0),2),"") -> 2.03 | E30: =_xlfn.RANK.EQ(D30,D:D) -> 28 | F30: =IFERROR(ROUND(VLOOKUP(A30,[1]eco_journals!B:E,4,0),2),"") | G30: =IFERROR(_xlfn.RANK.EQ(F30,F:F),"") | H30: =IFERROR(ROUND(VLOOKUP(A30,[1]fin_journals!B:E,4,0),2),"") | I30: =IFERROR(_xlfn.RANK.EQ(H30,H:H),"") | J30: =IFERROR(ROUND(VLOOKUP(A30,[1]bus_journals!B:E,4,0),2),"") -> 4.79 | K30: =IFERROR(_xlfn.RANK.EQ(J30,J:J),"") -> 7 | L30: =IFERROR(ROUND(VLOOKUP(A30,[1]man_journals!B:E,4,0),2),"") -> 3.86 | M30: =IFERROR(_xlfn.RANK.EQ(L30,L:L),"") -> 6 | N30: BUSINESS | O30: MANAGEMENT
A31: JOURNAL OF MANAGEMENT | B31: SAGE PUBLICATIONS | C31: =IFERROR(VLOOKUP(A31,[1]eco_bus_journals!$B:$D,3,0),"") -> 88 | D31: =IFERROR(ROUND(VLOOKUP(A31,[1]eco_bus_journals!$B:$X,4,0),2),"") -> 1.92 | E31: =_xlfn.RANK.EQ(D31,D:D) -> 29 | F31: =IFERROR(ROUND(VLOOKUP(A31,[1]eco_journals!B:E,4,0),2),"") | G31: =IFERROR(_xlfn.RANK.EQ(F31,F:F),"") | H31: =IFERROR(ROUND(VLOOKUP(A31,[1]fin_journals!B:E,4,0),2),"") | I31: =IFERROR(_xlfn.RANK.EQ(H31,H:H),"") | J31: =IFERROR(ROUND(VLOOKUP(A31,[1]bus_journals!B:E,4,0),2),"") -> 4.66 | K31: =IFERROR(_xlfn.RANK.EQ(J31,J:J),"") -> 8 | L31: =IFERROR(ROUND(VLOOKUP(A31,[1]man_journals!B:E,4,0),2),"") -> 3.83 | M31: =IFERROR(_xlfn.RANK.EQ(L31,L:L),"") -> 7 | N31: BUSINESS | O31: MANAGEMENT | P31: PSYCHOLOGY, APPLIED
A32: ACADEMY OF MANAGEMENT PERSPECTIVES | B32: ACAD MANAGEMENT | C32: =IFERROR(VLOOKUP(A32,[1]eco_bus_journals!$B:$D,3,0),"") -> 30 | D32: =IFERROR(ROUND(VLOOKUP(A32,[1]eco_bus_journals!$B:$X,4,0),2),"") -> 1.76 | E32: =_xlfn.RANK.EQ(D32,D:D) -> 31 | F32: =IFERROR(ROUND(VLOOKUP(A32,[1]eco_journals!B:E,4,0),2),"") | G32: =IFERROR(_xlfn.RANK.EQ(F32,F:F),"") | H32: =IFERROR(ROUND(VLOOKUP(A32,[1]fin_journals!B:E,4,0),2),"") | I32: =IFERROR(_xlfn.RANK.EQ(H32,H:H),"") | J32: =IFERROR(ROUND(VLOOKUP(A32,[1]bus_journals!B:E,4,0),2),"") -> 4.38 | K32: =IFERROR(_xlfn.RANK.EQ(J32,J:J),"") -> 10 | L32: =IFERROR(ROUND(VLOOKUP(A32,[1]man_journals!B:E,4,0),2),"") -> 3.43 | M32: =IFERROR(_xlfn.RANK.EQ(L32,L:L),"") -> 8 | N32: BUSINESS | O32: MANAGEMENT
A33: JOURNAL OF THE ACADEMY OF MARKETING SCIENCE | B33: SPRINGER | C33: =IFERROR(VLOOKUP(A33,[1]eco_bus_journals!$B:$D,3,0),"") -> 71 | D33: =IFERROR(ROUND(VLOOKUP(A33,[1]eco_bus_journals!$B:$X,4,0),2),"") -> 1.89 | E33: =_xlfn.RANK.EQ(D33,D:D) -> 30 | F33: =IFERROR(ROUND(VLOOKUP(A33,[1]eco_journals!B:E,4,0),2),"") | G33: =IFERROR(_xlfn.RANK.EQ(F33,F:F),"") | H33: =IFERROR(ROUND(VLOOKUP(A33,[1]fin_journals!B:E,4,0),2),"") | I33: =IFERROR(_xlfn.RANK.EQ(H33,H:H),"") | J33: =IFERROR(ROUND(VLOOKUP(A33,[1]bus_journals!B:E,4,0),2),"") -> 6.26 | K33: =IFERROR(_xlfn.RANK.EQ(J33,J:J),"") -> 4 | L33: =IFERROR(ROUND(VLOOKUP(A33,[1]man_journals!B:E,4,0),2),"") | M33: =IFERROR(_xlfn.RANK.EQ(L33,L:L),"") | N33: BUSINESS
A34: PROCEEDINGS OF THE NATIONAL ACADEMY OF SCIENCES OF THE UNITED STATES OF AMERICA | B34: NATL ACAD SCIENCES | C34: =IFERROR(VLOOKUP(A34,[1]eco_bus_journals!$B:$D,3,0),"") -> 44 | D34: =IFERROR(ROUND(VLOOKUP(A34,[1]eco_bus_journals!$B:$X,4,0),2),"") -> 1.69 | E34: =_xlfn.RANK.EQ(D34,D:D) -> 34 | F34: =IFERROR(ROUND(VLOOKUP(A34,[1]eco_journals!B:E,4,0),2),"") | G34: =IFERROR(_xlfn.RANK.EQ(F34,F:F),"") | H34: =IFERROR(ROUND(VLOOKUP(A34,[1]fin_journals!B:E,4,0),2),"") | I34: =IFERROR(_xlfn.RANK.EQ(H34,H:H),"") | J34: =IFERROR(ROUND(VLOOKUP(A34,[1]bus_journals!B:E,4,0),2),"") | K34: =IFERROR(_xlfn.RANK.EQ(J34,J:J),"") | L34: =IFERROR(ROUND(VLOOKUP(A34,[1]man_journals!B:E,4,0),2),"") | M34: =IFERROR(_xlfn.RANK.EQ(L34,L:L),"") | N34: MULTIDISCIPLINARY SCIENCES
A35: REVIEW OF FINANCE | B35: OXFORD UNIV PRESS | C35: =IFERROR(VLOOKUP(A35,[1]eco_bus_journals!$B:$D,3,0),"") -> 17 | D35: =IFERROR(ROUND(VLOOKUP(A35,[1]eco_bus_journals!$B:$X,4,0),2),"") -> 1.66 | E35: =_xlfn.RANK.EQ(D35,D:D) -> 35 | F35: =IFERROR(ROUND(VLOOKUP(A35,[1]eco_journals!B:E,4,0),2),"") -> 0.91 | G35: =IFERROR(_xlfn.RANK.EQ(F35,F:F),"") -> 35 | H35: =IFERROR(ROUND(VLOOKUP(A35,[1]fin_journals!B:E,4,0),2),"") -> 4.36 | I35: =IFERROR(_xlfn.RANK.EQ(H35,H:H),"") -> 9 | J35: =IFERROR(ROUND(VLOOKUP(A35,[1]bus_journals!B:E,4,0),2),"") | K35: =IFERROR(_xlfn.RANK.EQ(J35,J:J),"") | L35: =IFERROR(ROUND(VLOOKUP(A35,[1]man_journals!B:E,4,0),2),"") | M35: =IFERROR(_xlfn.RANK.EQ(L35,L:L),"") | N35: FINANCE | O35: ECONOMICS
A36: JOURNAL OF FINANCIAL INTERMEDIATION | B36: ELSEVIER | C36: =IFERROR(VLOOKUP(A36,[1]eco_bus_journals!$B:$D,3,0),"") -> 26 | D36: =IFERROR(ROUND(VLOOKUP(A36,[1]eco_bus_journals!$B:$X,4,0),2),"") -> 1.71 | E36: =_xlfn.RANK.EQ(D36,D:D) -> 33 | F36: =IFERROR(ROUND(VLOOKUP(A36,[1]eco_journals!B:E,4,0),2),"") | G36: =IFERROR(_xlfn.RANK.EQ(F36,F:F),"") | H36: =IFERROR(ROUND(VLOOKUP(A36,[1]fin_journals!B:E,4,0),2),"") -> 4.97 | I36: =IFERROR(_xlfn.RANK.EQ(H36,H:H),"") -> 8 | J36: =IFERROR(ROUND(VLOOKUP(A36,[1]bus_journals!B:E,4,0),2),"") | K36: =IFERROR(_xlfn.RANK.EQ(J36,J:J),"") | L36: =IFERROR(ROUND(VLOOKUP(A36,[1]man_journals!B:E,4,0),2),"") | M36: =IFERROR(_xlfn.RANK.EQ(L36,L:L),"") | N36: FINANCE
A37: REVIEW OF ACCOUNTING STUDIES | B37: SPRINGER | C37: =IFERROR(VLOOKUP(A37,[1]eco_bus_journals!$B:$D,3,0),"") -> 51 | D37: =IFERROR(ROUND(VLOOKUP(A37,[1]eco_bus_journals!$B:$X,4,0),2),"") -> 1.73 | E37: =_xlfn.RANK.EQ(D37,D:D) -> 32 | F37: =IFERROR(ROUND(VLOOKUP(A37,[1]eco_journals!B:E,4,0),2),"") | G37: =IFERROR(_xlfn.RANK.EQ(F37,F:F),"") | H37: =IFERROR(ROUND(VLOOKUP(A37,[1]fin_journals!B:E,4,0),2),"") -> 6.32 | I37: =IFERROR(_xlfn.RANK.EQ(H37,H:H),"") -> 6 | J37: =IFERROR(ROUND(VLOOKUP(A37,[1]bus_journals!B:E,4,0),2),"") | K37: =IFERROR(_xlfn.RANK.EQ(J37,J:J),"") | L37: =IFERROR(ROUND(VLOOKUP(A37,[1]man_journals!B:E,4,0),2),"") | M37: =IFERROR(_xlfn.RANK.EQ(L37,L:L),"") | N37: FINANCE
A38: MARKETING SCIENCE | B38: INFORMS | C38: =IFERROR(VLOOKUP(A38,[1]eco_bus_journals!$B:$D,3,0),"") -> 57 | D38: =IFERROR(ROUND(VLOOKUP(A38,[1]eco_bus_journals!$B:$X,4,0),2),"") -> 1.61 | E38: =_xlfn.RANK.EQ(D38,D:D) -> 38 | F38: =IFERROR(ROUND(VLOOKUP(A38,[1]eco_journals!B:E,4,0),2),"") | G38: =IFERROR(_xlfn.RANK.EQ(F38,F:F),"") | H38: =IFERROR(ROUND(VLOOKUP(A38,[1]fin_journals!B:E,4,0),2),"") | I38: =IFERROR(_xlfn.RANK.EQ(H38,H:H),"") | J38: =IFERROR(ROUND(VLOOKUP(A38,[1]bus_journals!B:E,4,0),2),"") -> 3.64 | K38: =IFERROR(_xlfn.RANK.EQ(J38,J:J),"") -> 21 | L38: =IFERROR(ROUND(VLOOKUP(A38,[1]man_journals!B:E,4,0),2),"") | M38: =IFERROR(_xlfn.RANK.EQ(L38,L:L),"") | N38: BUSINESS
A39: JOURNAL OF THE EUROPEAN ECONOMIC ASSOCIATION | B39: OXFORD UNIV PRESS | C39: =IFERROR(VLOOKUP(A39,[1]eco_bus_journals!$B:$D,3,0),"") -> 84 | D39: =IFERROR(ROUND(VLOOKUP(A39,[1]eco_bus_journals!$B:$X,4,0),2),"") -> 1.64 | E39: =_xlfn.RANK.EQ(D39,D:D) -> 36 | F39: =IFERROR(ROUND(VLOOKUP(A39,[1]eco_journals!B:E,4,0),2),"") -> 1.74 | G39: =IFERROR(_xlfn.RANK.EQ(F39,F:F),"") -> 21 | H39: =IFERROR(ROUND(VLOOKUP(A39,[1]fin_journals!B:E,4,0),2),"") | I39: =IFERROR(_xlfn.RANK.EQ(H39,H:H),"") | J39: =IFERROR(ROUND(VLOOKUP(A39,[1]bus_journals!B:E,4,0),2),"") | K39: =IFERROR(_xlfn.RANK.EQ(J39,J:J),"") | L39: =IFERROR(ROUND(VLOOKUP(A39,[1]man_journals!B:E,4,0),2),"") | M39: =IFERROR(_xlfn.RANK.EQ(L39,L:L),"") | N39: ECONOMICS
A40: JOURNAL OF MONETARY ECONOMICS | B40: ELSEVIER | C40: =IFERROR(VLOOKUP(A40,[1]eco_bus_journals!$B:$D,3,0),"") -> 102 | D40: =IFERROR(ROUND(VLOOKUP(A40,[1]eco_bus_journals!$B:$X,4,0),2),"") -> 1.58 | E40: =_xlfn.RANK.EQ(D40,D:D) -> 39 | F40: =IFERROR(ROUND(VLOOKUP(A40,[1]eco_journals!B:E,4,0),2),"") -> 1.58 | G40: =IFERROR(_xlfn.RANK.EQ(F40,F:F),"") -> 22 | H40: =IFERROR(ROUND(VLOOKUP(A40,[1]fin_journals!B:E,4,0),2),"") -> 2.17 | I40: =IFERROR(_xlfn.RANK.EQ(H40,H:H),"") -> 15 | J40: =IFERROR(ROUND(VLOOKUP(A40,[1]bus_journals!B:E,4,0),2),"") | K40: =IFERROR(_xlfn.RANK.EQ(J40,J:J),"") | L40: =IFERROR(ROUND(VLOOKUP(A40,[1]man_journals!B:E,4,0),2),"") | M40: =IFERROR(_xlfn.RANK.EQ(L40,L:L),"") | N40: FINANCE | O40: ECONOMICS
...

Sheet institutions
C1: eco_bus | F1: eco | I1: fin | L1: bus | O1: man
A2: institution | B2: country | C2: pub | D2: score | E2: rank | F2: pub | G2: score | H2: rank | I2: pub | J2: score | K2: rank | L2: pub | M2: score | N2: rank | O2: pub | P2: score | Q2: rank
A3: Center for Economic & Policy Research (CEPR) | B3: USA | C3: =IFERROR(VLOOKUP(A3,[1]eco_bus_institutions!B:E,2,0),"") -> 158 | D3: =IFERROR(VLOOKUP(A3,[1]eco_bus_institutions!B:E,4,0),"") -> 8 | E3: =_xlfn.RANK.EQ(D3,D:D) -> 1 | F3: =IFERROR(VLOOKUP(A3,[1]eco_institutions!B:D,2,0),"") -> 151 | G3: =IFERROR(VLOOKUP(A3,[1]eco_institutions!B:E,4,0),"") -> 6.8528581 | H3: =IFERROR(_xlfn.RANK.EQ(G3,G:G),"") -> 4 | I3: =IFERROR(VLOOKUP(A3,[1]fin_institutions!B:D,2,0),"") -> 43 | J3: =IFERROR(VLOOKUP(A3,[1]fin_institutions!B:E,4,0),"") -> 5.9098339 | K3: =IFERROR(_xlfn.RANK.EQ(J3,J:J),"") -> 6 | L3: =IFERROR(VLOOKUP(A3,[1]bus_institutions!B:D,2,0),"") | M3: =IFERROR(VLOOKUP(A3,[1]bus_institutions!B:E,4,0),"") | N3: =IFERROR(_xlfn.RANK.EQ(M3,M:M),"") | O3: =IFERROR(VLOOKUP(A3,[1]man_institutions!B:E,2,0),"") | P3: =IFERROR(VLOOKUP(A3,[1]man_institutions!B:E,4,0),"") | Q3: =IFERROR(_xlfn.RANK.EQ(P3,P:P),"")
A4: University of Chicago | B4: USA | C4: =IFERROR(VLOOKUP(A4,[1]eco_bus_institutions!B:E,2,0),"") -> 203 | D4: =IFERROR(VLOOKUP(A4,[1]eco_bus_institutions!B:E,4,0),"") -> 7.916794 | E4: =_xlfn.RANK.EQ(D4,D:D) -> 2 | F4: =IFERROR(VLOOKUP(A4,[1]eco_institutions!B:D,2,0),"") -> 157 | G4: =IFERROR(VLOOKUP(A4,[1]eco_institutions!B:E,4,0),"") -> 7.7788765 | H4: =IFERROR(_xlfn.RANK.EQ(G4,G:G),"") -> 2 | I4: =IFERROR(VLOOKUP(A4,[1]fin_institutions!B:D,2,0),"") -> 49 | J4: =IFERROR(VLOOKUP(A4,[1]fin_institutions!B:E,4,0),"") -> 6.8858104 | K4: =IFERROR(_xlfn.RANK.EQ(J4,J:J),"") -> 3 | L4: =IFERROR(VLOOKUP(A4,[1]bus_institutions!B:D,2,0),"") -> 18 | M4: =IFERROR(VLOOKUP(A4,[1]bus_institutions!B:E,4,0),"") -> 2.9859333 | N4: =IFERROR(_xlfn.RANK.EQ(M4,M:M),"") -> 118 | O4: =IFERROR(VLOOKUP(A4,[1]man_institutions!B:E,2,0),"") -> 9 | P4: =IFERROR(VLOOKUP(A4,[1]man_institutions!B:E,4,0),"") -> 1.9264411 | Q4: =IFERROR(_xlfn.RANK.EQ(P4,P:P),"") -> 422
A5: University of California Santa Barbara | B5: USA | C5: =IFERROR(VLOOKUP(A5,[1]eco_bus_institutions!B:E,2,0),"") -> 56 | D5: =IFERROR(VLOOKUP(A5,[1]eco_bus_institutions!B:E,4,0),"") -> 7.8669057 | E5: =_xlfn.RANK.EQ(D5,D:D) -> 3 | F5: =IFERROR(VLOOKUP(A5,[1]eco_institutions!B:D,2,0),"") -> 44 | G5: =IFERROR(VLOOKUP(A5,[1]eco_institutions!B:E,4,0),"") -> 8 | H5: =IFERROR(_xlfn.RANK.EQ(G5,G:G),"") -> 1 | I5: =IFERROR(VLOOKUP(A5,[1]fin_institutions!B:D,2,0),"") -> 6 | J5: =IFERROR(VLOOKUP(A5,[1]fin_institutions!B:E,4,0),"") -> 1.9501291 | K5: =IFERROR(_xlfn.RANK.EQ(J5,J:J),"") -> 170 | L5: =IFERROR(VLOOKUP(A5,[1]bus_institutions!B:D,2,0),"") -> 5 | M5: =IFERROR(VLOOKUP(A5,[1]bus_institutions!B:E,4,0),"") -> 2.0534718 | N5: =IFERROR(_xlfn.RANK.EQ(M5,M:M),"") -> 311 | O5: =IFERROR(VLOOKUP(A5,[1]man_institutions!B:E,2,0),"") -> 10 | P5: =IFERROR(VLOOKUP(A5,[1]man_institutions!B:E,4,0),"") -> 5.3733352 | Q5: =IFERROR(_xlfn.RANK.EQ(P5,P:P),"") -> 31
A6: Swiss Finance Institute (SFI) | B6: SWITZERLAND | C6: =IFERROR(VLOOKUP(A6,[1]eco_bus_institutions!B:E,2,0),"") -> 39 | D6: =IFERROR(VLOOKUP(A6,[1]eco_bus_institutions!B:E,4,0),"") -> 5.1989096 | E6: =_xlfn.RANK.EQ(D6,D:D) -> 12 | F6: =IFERROR(VLOOKUP(A6,[1]eco_institutions!B:D,2,0),"") -> 28 | G6: =IFERROR(VLOOKUP(A6,[1]eco_institutions!B:E,4,0),"") -> 4.0017151 | H6: =IFERROR(_xlfn.RANK.EQ(G6,G:G),"") -> 26 | I6: =IFERROR(VLOOKUP(A6,[1]fin_institutions!B:D,2,0),"") -> 28 | J6: =IFERROR(VLOOKUP(A6,[1]fin_institutions!B:E,4,0),"") -> 4.7617702 | K6: =IFERROR(_xlfn.RANK.EQ(J6,J:J),"") -> 17 | L6: =IFERROR(VLOOKUP(A6,[1]bus_institutions!B:D,2,0),"") | M6: =IFERROR(VLOOKUP(A6,[1]bus_institutions!B:E,4,0),"") | N6: =IFERROR(_xlfn.RANK.EQ(M6,M:M),"") | O6: =IFERROR(VLOOKUP(A6,[1]man_institutions!B:E,2,0),"") | P6: =IFERROR(VLOOKUP(A6,[1]man_institutions!B:E,4,0),"") | Q6: =IFERROR(_xlfn.RANK.EQ(P6,P:P),"")
A7: London Business School | B7: ENGLAND | C7: =IFERROR(VLOOKUP(A7,[1]eco_bus_institutions!B:E,2,0),"") -> 61 | D7: =IFERROR(VLOOKUP(A7,[1]eco_bus_institutions!B:E,4,0),"") -> 6.899268 | E7: =_xlfn.RANK.EQ(D7,D:D) -> 4 | F7: =IFERROR(VLOOKUP(A7,[1]eco_institutions!B:D,2,0),"") -> 30 | G7: =IFERROR(VLOOKUP(A7,[1]eco_institutions!B:E,4,0),"") -> 7.4382434 | H7: =IFERROR(_xlfn.RANK.EQ(G7,G:G),"") -> 3 | I7: =IFERROR(VLOOKUP(A7,[1]fin_institutions!B:D,2,0),"") -> 16 | J7: =IFERROR(VLOOKUP(A7,[1]fin_institutions!B:E,4,0),"") -> 5.043986 | K7: =IFERROR(_xlfn.RANK.EQ(J7,J:J),"") -> 13 | L7: =IFERROR(VLOOKUP(A7,[1]bus_institutions!B:D,2,0),"") -> 23 | M7: =IFERROR(VLOOKUP(A7,[1]bus_institutions!B:E,4,0),"") -> 5.1544791 | N7: =IFERROR(_xlfn.RANK.EQ(M7,M:M),"") -> 11 | O7: =IFERROR(VLOOKUP(A7,[1]man_institutions!B:E,2,0),"") -> 22 | P7: =IFERROR(VLOOKUP(A7,[1]man_institutions!B:E,4,0),"") -> 5.7121906 | Q7: =IFERROR(_xlfn.RANK.EQ(P7,P:P),"") -> 21
A8: Princeton University | B8: USA | C8: =IFERROR(VLOOKUP(A8,[1]eco_bus_institutions!B:E,2,0),"") -> 113 | D8: =IFERROR(VLOOKUP(A8,[1]eco_bus_institutions!B:E,4,0),"") -> 6.7455878 | E8: =_xlfn.RANK.EQ(D8,D:D) -> 5 | F8: =IFERROR(VLOOKUP(A8,[1]eco_institutions!B:D,2,0),"") -> 101 | G8: =IFERROR(VLOOKUP(A8,[1]eco_institutions!B:E,4,0),"") -> 6.4527793 | H8: =IFERROR(_xlfn.RANK.EQ(G8,G:G),"") -> 5 | I8: =IFERROR(VLOOKUP(A8,[1]fin_institutions!B:D,2,0),"") -> 18 | J8: =IFERROR(VLOOKUP(A8,[1]fin_institutions!B:E,4,0),"") -> 3.9390818 | K8: =IFERROR(_xlfn.RANK.EQ(J8,J:J),"") -> 36 | L8: =IFERROR(VLOOKUP(A8,[1]bus_institutions!B:D,2,0),"") | M8: =IFERROR(VLOOKUP(A8,[1]bus_institutions!B:E,4,0),"") | N8: =IFERROR(_xlfn.RANK.EQ(M8,M:M),"") | O8: =IFERROR(VLOOKUP(A8,[1]man_institutions!B:E,2,0),"") | P8: =IFERROR(VLOOKUP(A8,[1]man_institutions!B:E,4,0),"") | Q8: =IFERROR(_xlfn.RANK.EQ(P8,P:P),"")
A9: Yale University | B9: USA | C9: =IFERROR(VLOOKUP(A9,[1]eco_bus_institutions!B:E,2,0),"") -> 165 | D9: =IFERROR(VLOOKUP(A9,[1]eco_bus_institutions!B:E,4,0),"") -> 6.0289883 | E9: =_xlfn.RANK.EQ(D9,D:D) -> 6 | F9: =IFERROR(VLOOKUP(A9,[1]eco_institutions!B:D,2,0),"") -> 134 | G9: =IFERROR(VLOOKUP(A9,[1]eco_institutions!B:E,4,0),"") -> 5.6264041 | H9: =IFERROR(_xlfn.RANK.EQ(G9,G:G),"") -> 9 | I9: =IFERROR(VLOOKUP(A9,[1]fin_institutions!B:D,2,0),"") -> 27 | J9: =IFERROR(VLOOKUP(A9,[1]fin_institutions!B:E,4,0),"") -> 7.5523197 | K9: =IFERROR(_xlfn.RANK.EQ(J9,J:J),"") -> 2 | L9: =IFERROR(VLOOKUP(A9,[1]bus_institutions!B:D,2,0),"") -> 13 | M9: =IFERROR(VLOOKUP(A9,[1]bus_institutions!B:E,4,0),"") -> 5.2209887 | N9: =IFERROR(_xlfn.RANK.EQ(M9,M:M),"") -> 10 | O9: =IFERROR(VLOOKUP(A9,[1]man_institutions!B:E,2,0),"") -> 14 | P9: =IFERROR(VLOOKUP(A9,[1]man_institutions!B:E,4,0),"") -> 5.3674033 | Q9: =IFERROR(_xlfn.RANK.EQ(P9,P:P),"") -> 32
A10: National Bureau of Economic Research | B10: USA | C10: =IFERROR(VLOOKUP(A10,[1]eco_bus_institutions!B:E,2,0),"") -> 724 | D10: =IFERROR(VLOOKUP(A10,[1]eco_bus_institutions!B:E,4,0),"") -> 5.8878175 | E10: =_xlfn.RANK.EQ(D10,D:D) -> 8 | F10: =IFERROR(VLOOKUP(A10,[1]eco_institutions!B:D,2,0),"") -> 710 | G10: =IFERROR(VLOOKUP(A10,[1]eco_institutions!B:E,4,0),"") -> 5.0418361 | H10: =IFERROR(_xlfn.RANK.EQ(G10,G:G),"") -> 13 | I10: =IFERROR(VLOOKUP(A10,[1]fin_institutions!B:D,2,0),"") | J10: =IFERROR(VLOOKUP(A10,[1]fin_institutions!B:E,4,0),"") | K10: =IFERROR(_xlfn.RANK.EQ(J10,J:J),"") | L10: =IFERROR(VLOOKUP(A10,[1]bus_institutions!B:D,2,0),"") | M10: =IFERROR(VLOOKUP(A10,[1]bus_institutions!B:E,4,0),"") | N10: =IFERROR(_xlfn.RANK.EQ(M10,M:M),"") | O10: =IFERROR(VLOOKUP(A10,[1]man_institutions!B:E,2,0),"") | P10: =IFERROR(VLOOKUP(A10,[1]man_institutions!B:E,4,0),"") | Q10: =IFERROR(_xlfn.RANK.EQ(P10,P:P),"")
A11: Stanford University | B11: USA | C11: =IFERROR(VLOOKUP(A11,[1]eco_bus_institutions!B:E,2,0),"") -> 273 | D11: =IFERROR(VLOOKUP(A11,[1]eco_bus_institutions!B:E,4,0),"") -> 5.9488521 | E11: =_xlfn.RANK.EQ(D11,D:D) -> 7 | F11: =IFERROR(VLOOKUP(A11,[1]eco_institutions!B:D,2,0),"") -> 196 | G11: =IFERROR(VLOOKUP(A11,[1]eco_institutions!B:E,4,0),"") -> 5.2596414 | H11: =IFERROR(_xlfn.RANK.EQ(G11,G:G),"") -> 11 | I11: =IFERROR(VLOOKUP(A11,[1]fin_institutions!B:D,2,0),"") -> 44 | J11: =IFERROR(VLOOKUP(A11,[1]fin_institutions!B:E,4,0),"") -> 6.358214 | K11: =IFERROR(_xlfn.RANK.EQ(J11,J:J),"") -> 4 | L11: =IFERROR(VLOOKUP(A11,[1]bus_institutions!B:D,2,0),"") -> 37 | M11: =IFERROR(VLOOKUP(A11,[1]bus_institutions!B:E,4,0),"") -> 5.1481253 | N11: =IFERROR(_xlfn.RANK.EQ(M11,M:M),"") -> 12 | O11: =IFERROR(VLOOKUP(A11,[1]man_institutions!B:E,2,0),"") -> 59 | P11: =IFERROR(VLOOKUP(A11,[1]man_institutions!B:E,4,0),"") -> 7.7233049 | Q11: =IFERROR(_xlfn.RANK.EQ(P11,P:P),"") -> 3
A12: Massachusetts Institute of Technology (MIT) | B12: USA | C12: =IFERROR(VLOOKUP(A12,[1]eco_bus_institutions!B:E,2,0),"") -> 244 | D12: =IFERROR(VLOOKUP(A12,[1]eco_bus_institutions!B:E,4,0),"") -> 5.8630032 | E12: =_xlfn.RANK.EQ(D12,D:D) -> 9 | F12: =IFERROR(VLOOKUP(A12,[1]eco_institutions!B:D,2,0),"") -> 152 | G12: =IFERROR(VLOOKUP(A12,[1]eco_institutions!B:E,4,0),"") -> 6.2364645 | H12: =IFERROR(_xlfn.RANK.EQ(G12,G:G),"") -> 6 | I12: =IFERROR(VLOOKUP(A12,[1]fin_institutions!B:D,2,0),"") -> 49 | J12: =IFERROR(VLOOKUP(A12,[1]fin_institutions!B:E,4,0),"") -> 3.3225305 | K12: =IFERROR(_xlfn.RANK.EQ(J12,J:J),"") -> 60 | L12: =IFERROR(VLOOKUP(A12,[1]bus_institutions!B:D,2,0),"") -> 33 | M12: =IFERROR(VLOOKUP(A12,[1]bus_institutions!B:E,4,0),"") -> 3.0510826 | N12: =IFERROR(_xlfn.RANK.EQ(M12,M:M),"") -> 108 | O12: =IFERROR(VLOOKUP(A12,[1]man_institutions!B:E,2,0),"") -> 65 | P12: =IFERROR(VLOOKUP(A12,[1]man_institutions!B:E,4,0),"") -> 5.1443482 | Q12: =IFERROR(_xlfn.RANK.EQ(P12,P:P),"") -> 36
A13: University of California Berkeley | B13: USA | C13: =IFERROR(VLOOKUP(A13,[1]eco_bus_institutions!B:E,2,0),"") -> 207 | D13: =IFERROR(VLOOKUP(A13,[1]eco_bus_institutions!B:E,4,0),"") -> 5.3261617 | E13: =_xlfn.RANK.EQ(D13,D:D) -> 10 | F13: =IFERROR(VLOOKUP(A13,[1]eco_institutions!B:D,2,0),"") -> 156 | G13: =IFERROR(VLOOKUP(A13,[1]eco_institutions!B:E,4,0),"") -> 5.2397573 | H13: =IFERROR(_xlfn.RANK.EQ(G13,G:G),"") -> 12 | I13: =IFERROR(VLOOKUP(A13,[1]fin_institutions!B:D,2,0),"") -> 28 | J13: =IFERROR(VLOOKUP(A13,[1]fin_institutions!B:E,4,0),"") -> 4.1640943 | K13: =IFERROR(_xlfn.RANK.EQ(J13,J:J),"") -> 28 | L13: =IFERROR(VLOOKUP(A13,[1]bus_institutions!B:D,2,0),"") -> 26 | M13: =IFERROR(VLOOKUP(A13,[1]bus_institutions!B:E,4,0),"") -> 3.8922579 | N13: =IFERROR(_xlfn.RANK.EQ(M13,M:M),"") -> 40 | O13: =IFERROR(VLOOKUP(A13,[1]man_institutions!B:E,2,0),"") -> 45 | P13: =IFERROR(VLOOKUP(A13,[1]man_institutions!B:E,4,0),"") -> 4.3768843 | Q13: =IFERROR(_xlfn.RANK.EQ(P13,P:P),"") -> 60
A14: Columbia University | B14: USA | C14: =IFERROR(VLOOKUP(A14,[1]eco_bus_institutions!B:E,2,0),"") -> 256 | D14: =IFERROR(VLOOKUP(A14,[1]eco_bus_institutions!B:E,4,0),"") -> 4.9337844 | E14: =_xlfn.RANK.EQ(D14,D:D) -> 15 | F14: =IFERROR(VLOOKUP(A14,[1]eco_institutions!B:D,2,0),"") -> 165 | G14: =IFERROR(VLOOKUP(A14,[1]eco_institutions!B:E,4,0),"") -> 4.6213955 | H14: =IFERROR(_xlfn.RANK.EQ(G14,G:G),"") -> 18 | I14: =IFERROR(VLOOKUP(A14,[1]fin_institutions!B:D,2,0),"") -> 61 | J14: =IFERROR(VLOOKUP(A14,[1]fin_institutions!B:E,4,0),"") -> 4.6779708 | K14: =IFERROR(_xlfn.RANK.EQ(J14,J:J),"") -> 19 | L14: =IFERROR(VLOOKUP(A14,[1]bus_institutions!B:D,2,0),"") -> 47 | M14: =IFERROR(VLOOKUP(A14,[1]bus_institutions!B:E,4,0),"") -> 5.0050458 | N14: =IFERROR(_xlfn.RANK.EQ(M14,M:M),"") -> 14 | O14: =IFERROR(VLOOKUP(A14,[1]man_institutions!B:E,2,0),"") -> 39 | P14: =IFERROR(VLOOKUP(A14,[1]man_institutions!B:E,4,0),"") -> 3.3402901 | Q14: =IFERROR(_xlfn.RANK.EQ(P14,P:P),"") -> 153
... A602: University of Novi Sad | B602: SERBIA | C602: =IFERROR(VLOOKUP(A602,[1]eco_bus_institutions!B:E,2,0),"") -> 42 | D602: =IFERROR(VLOOKUP(A602,[1]eco_bus_institutions!B:E,4,0),"") -> 1.0420764 | E602: =_xlfn.RANK.EQ(D602,D:D) -> 598 | F602: =IFERROR(VLOOKUP(A602,[1]eco_institutions!B:D,2,0),"") -> 30 | G602: =IFERROR(VLOOKUP(A602,[1]eco_institutions!B:E,4,0),"") -> 1.0436347 | H602: =IFERROR(_xlfn.RANK.EQ(G602,G:G),"") -> 587 | I602: =IFERROR(VLOOKUP(A602,[1]fin_institutions!B:D,2,0),"") -> 4 | J602: =IFERROR(VLOOKUP(A602,[1]fin_institutions!B:E,4,0),"") -> 1.0571042 | K602: =IFERROR(_xlfn.RANK.EQ(J602,J:J),"") -> 551 | L602: =IFERROR(VLOOKUP(A602,[1]bus_institutions!B:D,2,0),"") -> 9 | M602: =IFERROR(VLOOKUP(A602,[1]bus_institutions!B:E,4,0),"") -> 1.2593262 | N602: =IFERROR(_xlfn.RANK.EQ(M602,M:M),"") -> 537 | O602: =IFERROR(VLOOKUP(A602,[1]man_institutions!B:E,2,0),"") -> 12 | P602: =IFERROR(VLOOKUP(A602,[1]man_institutions!B:E,4,0),"") -> 1.0509602 | Q602: =IFERROR(_xlfn.RANK.EQ(P602,P:P),"") -> 575

Sheet institutions_spss
T1: fra | U1: spain | V1: country | W1: acronym | Y1: For comparisons, place two countries in Y1 and Y2
A2: institution | C2: country | D2: score | E2: score | F2: score | G2: score | H2: score | I2: rank | J2: rank | K2: rank | L2: rank | M2: rank | R2: ranks | T2: deu | V2: WALES | W2: UK | Y2: For a country alone, leave Y2 blank
A3: institution | C3: country | D3: ebscore | E3: escore | F3: fscore | G3: bscore | H3: mscore | I3: ebrank | J3: erank | K3: frank | L3: brank | M3: mrank | R3: pc1 | S3: pc2 | T3: country | U3: for plot | V3: VIETNAM | W3: VTN | Y3: First Component, pc1: associated with all four categories (comprehensive institutions perform better)
A4: Center for Economic & Policy Research (CEPR) | B4: CEPR | C4: USA | D4: =IFERROR(ROUND(VLOOKUP(A4,institutions!A:E,4,0),2),"") -> 8 | E4: =IFERROR(ROUND(VLOOKUP(A4,institutions!A:X,7,0),2),"") -> 6.85 | F4: =IFERROR(ROUND(VLOOKUP(A4,institutions!A:X,10,0),2),"") -> 5.91 | G4: =IFERROR(ROUND(VLOOKUP(A4,institutions!A:X,13,0),2),"") | H4: =IFERROR(ROUND(VLOOKUP(A4,institutions!A:X,16,0),2),"") | I4: =ROUND(IFERROR((601-_xlfn.RANK.EQ(D4,D:D))/600,0),3) -> 1 | J4: =ROUND(IFERROR((601-IFERROR(_xlfn.RANK.EQ(E4,E:E),""))/600,0),3) -> 0.995 | K4: =ROUND(IFERROR((601-IFERROR(_xlfn.RANK.EQ(F4,F:F),""))/600,0),3) -> 0.992 | L4: =ROUND(IFERROR((601-IFERROR(_xlfn.RANK.EQ(G4,G:G),""))/600,0),3) -> 0 | M4: =ROUND(IFERROR((601-IFERROR(_xlfn.RANK.EQ(H4,H:H),""))/600,0),3) -> 0 | N4: =VLOOKUP(A4,#REF!,11,0) -> #REF! | O4: =VLOOKUP(A4,#REF!,12,0) -> #REF! | P4: =VLOOKUP(A4,#REF!,13,0) -> #REF! | Q4: =VLOOKUP(A4,#REF!,14,0) -> #REF! | R4: -0.17798453 | S4: 3.3912835 | T4: =VLOOKUP(C4,V:W,2,0) -> USA | U4: =IF(T4=T$1,B4,IF(T4=T$2,B4,IF(T4=U$1,B4,""))) | V4: USA | W4: USA | Y4: Second Component: North (Economics and Finance), South (Business and Management)
A5: University of Chicago | B5: Chicago | C5: USA | D5: =IFERROR(ROUND(VLOOKUP(A5,institutions!A:E,4,0),2),"") -> 7.92 | E5: =IFERROR(ROUND(VLOOKUP(A5,institutions!A:X,7,0),2),"") -> 7.78 | F5: =IFERROR(ROUND(VLOOKUP(A5,institutions!A:X,10,0),2),"") -> 6.89 | G5: =IFERROR(ROUND(VLOOKUP(A5,institutions!A:X,13,0),2),"") -> 2.99 | H5: =IFERROR(ROUND(VLOOKUP(A5,institutions!A:X,16,0),2),"") -> 1.93 | I5: =ROUND(IFERROR((601-_xlfn.RANK.EQ(D5,D:D))/600,0),3) -> 0.998 | J5: =ROUND(IFERROR((601-IFERROR(_xlfn.RANK.EQ(E5,E:E),""))/600,0),3) -> 0.998 | K5: =ROUND(IFERROR((601-IFERROR(_xlfn.RANK.EQ(F5,F:F),""))/600,0),3) -> 0.997 | L5: =ROUND(IFERROR((601-IFERROR(_xlfn.RANK.EQ(G5,G:G),""))/600,0),3) -> 0.812 | M5: =ROUND(IFERROR((601-IFERROR(_xlfn.RANK.EQ(H5,H:H),""))/600,0),3) -> 0.3 | N5: =VLOOKUP(A5,#REF!,11,0) -> #REF! | O5: =VLOOKUP(A5,#REF!,12,0) -> #REF! | P5: =VLOOKUP(A5,#REF!,13,0) -> #REF! | Q5: =VLOOKUP(A5,#REF!,14,0) -> #REF! | R5: 1.8264022 | S5: 1.5762561 | T5: =VLOOKUP(C5,V:W,2,0) -> USA | U5: =IF(T5=T$1,B5,IF(T5=T$2,B5,IF(T5=U$1,B5,""))) | V5: UNITED ARAB EMIRATES | W5: UAE | Y5: 88% of the variance explained
A6: University of California Santa Barbara | B6: UCSB | C6: USA | D6: =IFERROR(ROUND(VLOOKUP(A6,institutions!A:E,4,0),2),"") -> 7.87 | E6: =IFERROR(ROUND(VLOOKUP(A6,institutions!A:X,7,0),2),"") -> 8 | F6: =IFERROR(ROUND(VLOOKUP(A6,institutions!A:X,10,0),2),"") -> 1.95 | G6: =IFERROR(ROUND(VLOOKUP(A6,institutions!A:X,13,0),2),"") -> 2.05 | H6: =IFERROR(ROUND(VLOOKUP(A6,institutions!A:X,16,0),2),"") -> 5.37 | I6: =ROUND(IFERROR((601-_xlfn.RANK.EQ(D6,D:D))/600,0),3) -> 0.997 | J6: =ROUND(IFERROR((601-IFERROR(_xlfn.RANK.EQ(E6,E:E),""))/600,0),3) -> 1 | K6: =ROUND(IFERROR((601-IFERROR(_xlfn.RANK.EQ(F6,F:F),""))/600,0),3) -> 0.72 | L6: =ROUND(IFERROR((601-IFERROR(_xlfn.RANK.EQ(G6,G:G),""))/600,0),3) -> 0.483 | M6: =ROUND(IFERROR((601-IFERROR(_xlfn.RANK.EQ(H6,H:H),""))/600,0),3) -> 0.95 | N6: =VLOOKUP(A6,#REF!,11,0) -> #REF! | O6: =VLOOKUP(A6,#REF!,12,0) -> #REF! | P6: =VLOOKUP(A6,#REF!,13,0) -> #REF! | Q6: =VLOOKUP(A6,#REF!,14,0) -> #REF! | R6: 1.94297 | S6: 0.6946489 | T6: =VLOOKUP(C6,V:W,2,0) -> USA | U6: =IF(T6=T$1,B6,IF(T6=T$2,B6,IF(T6=U$1,B6,""))) | V6: TURKIYE | W6: TUR
A7: Princeton University | B7: Princeton | C7: USA | D7: =IFERROR(ROUND(VLOOKUP(A7,institutions!A:E,4,0),2),"") -> 6.75 | E7: =IFERROR(ROUND(VLOOKUP(A7,institutions!A:X,7,0),2),"") -> 6.45 | F7: =IFERROR(ROUND(VLOOKUP(A7,institutions!A:X,10,0),2),"") -> 3.94 | G7: =IFERROR(ROUND(VLOOKUP(A7,institutions!A:X,13,0),2),"") | H7: =IFERROR(ROUND(VLOOKUP(A7,institutions!A:X,16,0),2),"") | I7: =ROUND(IFERROR((601-_xlfn.RANK.EQ(D7,D:D))/600,0),3) -> 0.993 | J7: =ROUND(IFERROR((601-IFERROR(_xlfn.RANK.EQ(E7,E:E),""))/600,0),3) -> 0.993 | K7: =ROUND(IFERROR((601-IFERROR(_xlfn.RANK.EQ(F7,F:F),""))/600,0),3) -> 0.943 | L7: =ROUND(IFERROR((601-IFERROR(_xlfn.RANK.EQ(G7,G:G),""))/600,0),3) -> 0 | M7: =ROUND(IFERROR((601-IFERROR(_xlfn.RANK.EQ(H7,H:H),""))/600,0),3) -> 0 | N7: =VLOOKUP(A7,#REF!,11,0) -> #REF! | O7: =VLOOKUP(A7,#REF!,12,0) -> #REF! | P7: =VLOOKUP(A7,#REF!,13,0) -> #REF! | Q7: =VLOOKUP(A7,#REF!,14,0) -> #REF! | R7: -0.2648982 | S7: 3.3157124 | T7: =VLOOKUP(C7,V:W,2,0) -> USA | U7: =IF(T7=T$1,B7,IF(T7=T$2,B7,IF(T7=U$1,B7,""))) | V7: TUNISIA | W7: TUN | Y7: NorthEast Direction signals excellence
A8: London Business School | B8: LBS | C8: ENGLAND | D8: =IFERROR(ROUND(VLOOKUP(A8,institutions!A:E,4,0),2),"") -> 6.9 | E8: =IFERROR(ROUND(VLOOKUP(A8,institutions!A:X,7,0),2),"") -> 7.44 | F8: =IFERROR(ROUND(VLOOKUP(A8,institutions!A:X,10,0),2),"") -> 5.04 | G8: =IFERROR(ROUND(VLOOKUP(A8,institutions!A:X,13,0),2),"") -> 5.15 | H8: =IFERROR(ROUND(VLOOKUP(A8,institutions!A:X,16,0),2),"") -> 5.71 | I8: =ROUND(IFERROR((601-_xlfn.RANK.EQ(D8,D:D))/600,0),3) -> 0.995 | J8: =ROUND(IFERROR((601-IFERROR(_xlfn.RANK.EQ(E8,E:E),""))/600,0),3) -> 0.997 | K8: =ROUND(IFERROR((601-IFERROR(_xlfn.RANK.EQ(F8,F:F),""))/600,0),3) -> 0.98 | L8: =ROUND(IFERROR((601-IFERROR(_xlfn.RANK.EQ(G8,G:G),""))/600,0),3) -> 0.983 | M8: =ROUND(IFERROR((601-IFERROR(_xlfn.RANK.EQ(H8,H:H),""))/600,0),3) -> 0.968 | N8: =VLOOKUP(A8,#REF!,11,0) -> #REF! | O8: =VLOOKUP(A8,#REF!,12,0) -> #REF! | P8: =VLOOKUP(A8,#REF!,13,0) -> #REF! | Q8: =VLOOKUP(A8,#REF!,14,0) -> #REF! | R8: 3.3072869 | S8: 0.20496759 | T8: =VLOOKUP(C8,V:W,2,0) -> UK | U8: =IF(T8=T$1,B8,IF(T8=T$2,B8,IF(T8=U$1,B8,""))) | V8: TAIWAN | W8: TWN | Y8: To compare, move an imaginary NW to SE line: better to be on the right of that line
A9: Yale University | B9: Yale | C9: USA | D9: =IFERROR(ROUND(VLOOKUP(A9,institutions!A:E,4,0),2),"") -> 6.03 | E9: =IFERROR(ROUND(VLOOKUP(A9,institutions!A:X,7,0),2),"") -> 5.63 | F9: =IFERROR(ROUND(VLOOKUP(A9,institutions!A:X,10,0),2),"") -> 7.55 | G9: =IFERROR(ROUND(VLOOKUP(A9,institutions!A:X,13,0),2),"") -> 5.22 | H9: =IFERROR(ROUND(VLOOKUP(A9,institutions!A:X,16,0),2),"") -> 5.37 | I9: =ROUND(IFERROR((601-_xlfn.RANK.EQ(D9,D:D))/600,0),3) -> 0.992 | J9: =ROUND(IFERROR((601-IFERROR(_xlfn.RANK.EQ(E9,E:E),""))/600,0),3) -> 0.987 | K9: =ROUND(IFERROR((601-IFERROR(_xlfn.RANK.EQ(F9,F:F),""))/600,0),3) -> 0.998 | L9: =ROUND(IFERROR((601-IFERROR(_xlfn.RANK.EQ(G9,G:G),""))/600,0),3) -> 0.985 | M9: =ROUND(IFERROR((601-IFERROR(_xlfn.RANK.EQ(H9,H:H),""))/600,0),3) -> 0.95 | N9: =VLOOKUP(A9,#REF!,11,0) -> #REF! | O9: =VLOOKUP(A9,#REF!,12,0) -> #REF! | P9: =VLOOKUP(A9,#REF!,13,0) -> #REF! | Q9: =VLOOKUP(A9,#REF!,14,0) -> #REF! | R9: 3.2931033 | S9: 0.2350235 | T9: =VLOOKUP(C9,V:W,2,0) -> USA | U9: =IF(T9=T$1,B9,IF(T9=T$2,B9,IF(T9=U$1,B9,""))) | V9: SWITZERLAND | W9: CHE
A10: National Bureau of Economic Research | B10: NBER | C10: USA | D10: =IFERROR(ROUND(VLOOKUP(A10,institutions!A:E,4,0),2),"") -> 5.89 | E10: =IFERROR(ROUND(VLOOKUP(A10,institutions!A:X,7,0),2),"") -> 5.04 | F10: =IFERROR(ROUND(VLOOKUP(A10,institutions!A:X,10,0),2),"") | G10: =IFERROR(ROUND(VLOOKUP(A10,institutions!A:X,13,0),2),"") | H10: =IFERROR(ROUND(VLOOKUP(A10,institutions!A:X,16,0),2),"") | I10: =ROUND(IFERROR((601-_xlfn.RANK.EQ(D10,D:D))/600,0),3) -> 0.988 | J10: =ROUND(IFERROR((601-IFERROR(_xlfn.RANK.EQ(E10,E:E),""))/600,0),3) -> 0.98 | K10: =ROUND(IFERROR((601-IFERROR(_xlfn.RANK.EQ(F10,F:F),""))/600,0),3) -> 0 | L10: =ROUND(IFERROR((601-IFERROR(_xlfn.RANK.EQ(G10,G:G),""))/600,0),3) -> 0 | M10: =ROUND(IFERROR((601-IFERROR(_xlfn.RANK.EQ(H10,H:H),""))/600,0),3) -> 0 | N10: =VLOOKUP(A10,#REF!,11,0) -> #REF! | O10: =VLOOKUP(A10,#REF!,12,0) -> #REF! | P10: =VLOOKUP(A10,#REF!,13,0) -> #REF! | Q10: =VLOOKUP(A10,#REF!,14,0) -> #REF! | R10: -1.8967602 | S10: 1.9157826 | T10: =VLOOKUP(C10,V:W,2,0) -> USA | U10: =IF(T10=T$1,B10,IF(T10=T$2,B10,IF(T10=U$1,B10,""))) | V10: SWEDEN | W10: SWE | Y10: For Australia
A11: Stanford University | B11: Stanford | C11: USA | D11: =IFERROR(ROUND(VLOOKUP(A11,institutions!A:E,4,0),2),"") -> 5.95 | E11: =IFERROR(ROUND(VLOOKUP(A11,institutions!A:X,7,0),2),"") -> 5.26 | F11: =IFERROR(ROUND(VLOOKUP(A11,institutions!A:X,10,0),2),"") -> 6.36 | G11: =IFERROR(ROUND(VLOOKUP(A11,institutions!A:X,13,0),2),"") -> 5.15 | H11: =IFERROR(ROUND(VLOOKUP(A11,institutions!A:X,16,0),2),"") -> 7.72 | I11: =ROUND(IFERROR((601-_xlfn.RANK.EQ(D11,D:D))/600,0),3) -> 0.99 | J11: =ROUND(IFERROR((601-IFERROR(_xlfn.RANK.EQ(E11,E:E),""))/600,0),3) -> 0.983 | K11: =ROUND(IFERROR((601-IFERROR(_xlfn.RANK.EQ(F11,F:F),""))/600,0),3) -> 0.995 | L11: =ROUND(IFERROR((601-IFERROR(_xlfn.RANK.EQ(G11,G:G),""))/600,0),3) -> 0.983 | M11: =ROUND(IFERROR((601-IFERROR(_xlfn.RANK.EQ(H11,H:H),""))/600,0),3) -> 0.997 | N11: =VLOOKUP(A11,#REF!,11,0) -> #REF! | O11: =VLOOKUP(A11,#REF!,12,0) -> #REF! | P11: =VLOOKUP(A11,#REF!,13,0) -> #REF! | Q11: =VLOOKUP(A11,#REF!,14,0) -> #REF! | R11: 3.3628844 | S11: 0.15090247 | T11: =VLOOKUP(C11,V:W,2,0) -> USA | U11: =IF(T11=T$1,B11,IF(T11=T$2,B11,IF(T11=U$1,B11,""))) | V11: SPAIN | W11: SPAIN | Y11: Cluster 1: Best performers | Z11: Adelaide, ANU, Melbourne
A12: Massachusetts Institute of Technology (MIT) | B12: MIT | C12: USA | D12: =IFERROR(ROUND(VLOOKUP(A12,institutions!A:E,4,0),2),"") -> 5.86 | E12: =IFERROR(ROUND(VLOOKUP(A12,institutions!A:X,7,0),2),"") -> 6.24 | F12: =IFERROR(ROUND(VLOOKUP(A12,institutions!A:X,10,0),2),"") -> 3.32 | G12: =IFERROR(ROUND(VLOOKUP(A12,institutions!A:X,13,0),2),"") -> 3.05 | H12: =IFERROR(ROUND(VLOOKUP(A12,institutions!A:X,16,0),2),"") -> 5.14 | I12: =ROUND(IFERROR((601-_xlfn.RANK.EQ(D12,D:D))/600,0),3) -> 0.987 | J12: =ROUND(IFERROR((601-IFERROR(_xlfn.RANK.EQ(E12,E:E),""))/600,0),3) -> 0.992 | K12: =ROUND(IFERROR((601-IFERROR(_xlfn.RANK.EQ(F12,F:F),""))/600,0),3) -> 0.902 | L12: =ROUND(IFERROR((601-IFERROR(_xlfn.RANK.EQ(G12,G:G),""))/600,0),3) -> 0.822 | M12: =ROUND(IFERROR((601-IFERROR(_xlfn.RANK.EQ(H12,H:H),""))/600,0),3) -> 0.942 | N12: =VLOOKUP(A12,#REF!,11,0) -> #REF! | O12: =VLOOKUP(A12,#REF!,12,0) -> #REF! | P12: =VLOOKUP(A12,#REF!,13,0) -> #REF! | Q12: =VLOOKUP(A12,#REF!,14,0) -> #REF! | R12: 2.831718 | S12: 0.39027412 | T12: =VLOOKUP(C12,V:W,2,0) -> USA | U12: =IF(T12=T$1,B12,IF(T12=T$2,B12,IF(T12=U$1,B12,""))) | V12: SOUTH KOREA | W12: KOREA | Y12: Cluster 2: Fast followers | Z12: UTAS,Western Aus, La Trobe, Wollongong, Maquarie, RMIT, Deakin, UTS, Sifney, Queensland
A13: University of California Berkeley | B13: UCB | C13: USA | D13: =IFERROR(ROUND(VLOOKUP(A13,institutions!A:E,4,0),2),"") -> 5.33 | E13: =IFERROR(ROUND(VLOOKUP(A13,institutions!A:X,7,0),2),"") -> 5.24 | F13: =IFERROR(ROUND(VLOOKUP(A13,institutions!A:X,10,0),2),"") -> 4.16 | G13: =IFERROR(ROUND(VLOOKUP(A13,institutions!A:X,13,0),2),"") -> 3.89 | H13: =IFERROR(ROUND(VLOOKUP(A13,institutions!A:X,16,0),2),"") -> 4.38 | I13: =ROUND(IFERROR((601-_xlfn.RANK.EQ(D13,D:D))/600,0),3) -> 0.985 | J13: =ROUND(IFERROR((601-IFERROR(_xlfn.RANK.EQ(E13,E:E),""))/600,0),3) -> 0.982 | K13: =ROUND(IFERROR((601-IFERROR(_xlfn.RANK.EQ(F13,F:F),""))/600,0),3) -> 0.955 | L13: =ROUND(IFERROR((601-IFERROR(_xlfn.RANK.EQ(G13,G:G),""))/600,0),3) -> 0.935 | M13: =ROUND(IFERROR((601-IFERROR(_xlfn.RANK.EQ(H13,H:H),""))/600,0),3) -> 0.902 | N13: =VLOOKUP(A13,#REF!,11,0) -> #REF! | O13: =VLOOKUP(A13,#REF!,12,0) -> #REF! | P13: =VLOOKUP(A13,#REF!,13,0) -> #REF! | Q13: =VLOOKUP(A13,#REF!,14,0) -> #REF! | R13: 3.035717 | S13: 0.32121493 | T13: =VLOOKUP(C13,V:W,2,0) -> USA | U13: =IF(T13=T$1,B13,IF(T13=T$2,B13,IF(T13=U$1,B13,""))) | V13: SOUTH AFRICA | W13: ZAF | Y13: Cluster 3: Followers | Z13: Edith Cowan, South Australia
A14: Swiss Finance Institute (SFI) | B14: SFI | C14: SWITZERLAND | D14: =IFERROR(ROUND(VLOOKUP(A14,institutions!A:E,4,0),2),"") -> 5.2 | E14: =IFERROR(ROUND(VLOOKUP(A14,institutions!A:X,7,0),2),"") -> 4 | F14: =IFERROR(ROUND(VLOOKUP(A14,institutions!A:X,10,0),2),"") -> 4.76 | G14: =IFERROR(ROUND(VLOOKUP(A14,institutions!A:X,13,0),2),"") | H14: =IFERROR(ROUND(VLOOKUP(A14,institutions!A:X,16,0),2),"") | I14: =ROUND(IFERROR((601-_xlfn.RANK.EQ(D14,D:D))/600,0),3) -> 0.982 | J14: =ROUND(IFERROR((601-IFERROR(_xlfn.RANK.EQ(E14,E:E),""))/600,0),3) -> 0.958 | K14: =ROUND(IFERROR((601-IFERROR(_xlfn.RANK.EQ(F14,F:F),""))/600,0),3) -> 0.973 | L14: =ROUND(IFERROR((601-IFERROR(_xlfn.RANK.EQ(G14,G:G),""))/600,0),3) -> 0 | M14: =ROUND(IFERROR((601-IFERROR(_xlfn.RANK.EQ(H14,H:H),""))/600,0),3) -> 0 | N14: =VLOOKUP(A14,#REF!,11,0) -> #REF! | O14: =VLOOKUP(A14,#REF!,12,0) -> #REF! | P14: =VLOOKUP(A14,#REF!,13,0) -> #REF! | Q14: =VLOOKUP(A14,#REF!,14,0) -> #REF! | R14: -0.26964348 | S14: 3.2846281 | T14: =VLOOKUP(C14,V:W,2,0) -> CHE | U14: =IF(T14=T$1,B14,IF(T14=T$2,B14,IF(T14=U$1,B14,""))) | V14: SLOVAKIA | W14: SLK | Y14: Cluster 4: Laggers | Z14: Curtin, Griffith, QUT, Newcastle, Swinburne
A15: Harvard University | B15: Harvard | C15: USA | D15: =IFERROR(ROUND(VLOOKUP(A15,institutions!A:E,4,0),2),"") -> 5.26 | E15: =IFERROR(ROUND(VLOOKUP(A15,institutions!A:X,7,0),2),"") -> 5.71 | F15: =IFERROR(ROUND(VLOOKUP(A15,institutions!A:X,10,0),2),"") -> 4.14 | G15: =IFERROR(ROUND(VLOOKUP(A15,institutions!A:X,13,0),2),"") -> 3.39 | H15: =IFERROR(ROUND(VLOOKUP(A15,institutions!A:X,16,0),2),"") -> 4.43 | I15: =ROUND(IFERROR((601-_xlfn.RANK.EQ(D15,D:D))/600,0),3) -> 0.983 | J15: =ROUND(IFERROR((601-IFERROR(_xlfn.RANK.EQ(E15,E:E),""))/600,0),3) -> 0.988 | K15: =ROUND(IFERROR((601-IFERROR(_xlfn.RANK.EQ(F15,F:F),""))/600,0),3) -> 0.952 | L15: =ROUND(IFERROR((601-IFERROR(_xlfn.RANK.EQ(G15,G:G),""))/600,0),3) -> 0.875 | M15: =ROUND(IFERROR((601-IFERROR(_xlfn.RANK.EQ(H15,H:H),""))/600,0),3) -> 0.908 | N15: =VLOOKUP(A15,#REF!,11,0) -> #REF! | O15: =VLOOKUP(A15,#REF!,12,0) -> #REF! | P15: =VLOOKUP(A15,#REF!,13,0) -> #REF! | Q15: =VLOOKUP(A15,#REF!,14,0) -> #REF! | R15: 2.9439368 | S15: 0.42011172 | T15: =VLOOKUP(C15,V:W,2,0) -> USA | U15: =IF(T15=T$1,B15,IF(T15=T$2,B15,IF(T15=U$1,B15,""))) | V15: SINGAPORE | W15: SGP
A16: Columbia University | B16: Columbia | C16: USA | D16: =IFERROR(ROUND(VLOOKUP(A16,institutions!A:E,4,0),2),"") -> 4.93 | E16: =IFERROR(ROUND(VLOOKUP(A16,institutions!A:X,7,0),2),"") -> 4.62 | F16: =IFERROR(ROUND(VLOOKUP(A16,institutions!A:X,10,0),2),"") -> 4.68 | G16: =IFERROR(ROUND(VLOOKUP(A16,institutions!A:X,13,0),2),"") -> 5.01 | H16: =IFERROR(ROUND(VLOOKUP(A16,institutions!A:X,16,0),2),"") -> 3.34 | I16: =ROUND(IFERROR((601-_xlfn.RANK.EQ(D16,D:D))/600,0),3) -> 0.977 | J16: =ROUND(IFERROR((601-IFERROR(_xlfn.RANK.EQ(E16,E:E),""))/600,0),3) -> 0.972 | K16: =ROUND(IFERROR((601-IFERROR(_xlfn.RANK.EQ(F16,F:F),""))/600,0),3) -> 0.97 | L16: =ROUND(IFERROR((601-IFERROR(_xlfn.RANK.EQ(G16,G:G),""))/600,0),3) -> 0.978 | M16: =ROUND(IFERROR((601-IFERROR(_xlfn.RANK.EQ(H16,H:H),""))/600,0),3) -> 0.747 | N16: =VLOOKUP(A16,#REF!,11,0) -> #REF! | O16: =VLOOKUP(A16,#REF!,12,0) -> #REF! | P16: =VLOOKUP(A16,#REF!,13,0) -> #REF! | Q16: =VLOOKUP(A16,#REF!,14,0) -> #REF! | R16: 2.8421818 | S16: 0.49589009 | T16: =VLOOKUP(C16,V:W,2,0) -> USA | U16: =IF(T16=T$1,B16,IF(T16=T$2,B16,IF(T16=U$1,B16,""))) | V16: SERBIA | W16: SERBIA
A17: Boston University | B17: Boston | C17: USA | D17: =IFERROR(ROUND(VLOOKUP(A17,institutions!A:E,4,0),2),"") -> 5.13 | E17: =IFERROR(ROUND(VLOOKUP(A17,institutions!A:X,7,0),2),"") -> 4.72 | F17: =IFERROR(ROUND(VLOOKUP(A17,institutions!A:X,10,0),2),"") -> 2.82 | G17: =IFERROR(ROUND(VLOOKUP(A17,institutions!A:X,13,0),2),"") -> 6.88 | H17: =IFERROR(ROUND(VLOOKUP(A17,institutions!A:X,16,0),2),"") -> 6.77 | I17: =ROUND(IFERROR((601-_xlfn.RANK.EQ(D17,D:D))/600,0),3) -> 0.98 | J17: =ROUND(IFERROR((601-IFERROR(_xlfn.RANK.EQ(E17,E:E),""))/600,0),3) -> 0.973 | K17: =ROUND(IFERROR((601-IFERROR(_xlfn.RANK.EQ(F17,F:F),""))/600,0),3) -> 0.872 | L17: =ROUND(IFERROR((601-IFERROR(_xlfn.RANK.EQ(G17,G:G),""))/600,0),3) -> 0.998 | M17: =ROUND(IFERROR((601-IFERROR(_xlfn.RANK.EQ(H17,H:H),""))/600,0),3) -> 0.988 | N17: =VLOOKUP(A17,#REF!,11,0) -> #REF! | O17: =VLOOKUP(A17,#REF!,12,0) -> #REF! | P17: =VLOOKUP(A17,#REF!,13,0) -> #REF! | Q17: =VLOOKUP(A17,#REF!,14,0) -> #REF! | R17: 3.1472659 | S17: -0.06014661 | T17: =VLOOKUP(C17,V:W,2,0) -> USA | U17: =IF(T17=T$1,B17,IF(T17=T$2,B17,IF(T17=U$1,B17,""))) | V17: SCOTLAND | W17: UK
A18: Pompeu Fabra University | B18: Pompeu Fabra | C18: SPAIN | D18: =IFERROR(ROUND(VLOOKUP(A18,institutions!A:E,4,0),2),"") -> 5.01 | E18: =IFERROR(ROUND(VLOOKUP(A18,institutions!A:X,7,0),2),"") -> 5.75 | F18: =IFERROR(ROUND(VLOOKUP(A18,institutions!A:X,10,0),2),"") -> 1.92 | G18: =IFERROR(ROUND(VLOOKUP(A18,institutions!A:X,13,0),2),"") -> 1.08 | H18: =IFERROR(ROUND(VLOOKUP(A18,institutions!A:X,16,0),2),"") -> 1.3 | I18: =ROUND(IFERROR((601-_xlfn.RANK.EQ(D18,D:D))/600,0),3) -> 0.978 | J18: =ROUND(IFERROR((601-IFERROR(_xlfn.RANK.EQ(E18,E:E),""))/600,0),3) -> 0.99 | K18: =ROUND(IFERROR((601-IFERROR(_xlfn.RANK.EQ(F18,F:F),""))/600,0),3) -> 0.712 | L18: =ROUND(IFERROR((601-IFERROR(_xlfn.RANK.EQ(G18,G:G),""))/600,0),3) -> 0.065 | M18: =ROUND(IFERROR((601-IFERROR(_xlfn.RANK.EQ(H18,H:H),""))/600,0),3) -> 0.068 | N18: =VLOOKUP(A18,#REF!,11,0) -> #REF! | O18: =VLOOKUP(A18,#REF!,12,0) -> #REF! | P18: =VLOOKUP(A18,#REF!,13,0) -> #REF! | Q18: =VLOOKUP(A18,#REF!,14,0) -> #REF! | R18: -0.42553529 | S18: 2.757024 | T18: =VLOOKUP(C18,V:W,2,0) -> SPAIN | U18: =IF(T18=T$1,B18,IF(T18=T$2,B18,IF(T18=U$1,B18,""))) -> Pompeu Fabra | V18: SAUDI ARABIA | W18: SAU
A19: Centre for Economic Policy Research - UK | B19: CEPRUK | C19: ENGLAND | D19: =IFERROR(ROUND(VLOOKUP(A19,institutions!A:E,4,0),2),"") -> 4.84 | E19: =IFERROR(ROUND(VLOOKUP(A19,institutions!A:X,7,0),2),"") -> 4.3 | F19: =IFERROR(ROUND(VLOOKUP(A19,institutions!A:X,10,0),2),"") -> 2.88 | G19: =IFERROR(ROUND(VLOOKUP(A19,institutions!A:X,13,0),2),"") | H19: =IFERROR(ROUND(VLOOKUP(A19,institutions!A:X,16,0),2),"") | I19: =ROUND(IFERROR((601-_xlfn.RANK.EQ(D19,D:D))/600,0),3) -> 0.973 | J19: =ROUND(IFERROR((601-IFERROR(_xlfn.RANK.EQ(E19,E:E),""))/600,0),3) -> 0.967 | K19: =ROUND(IFERROR((601-IFERROR(_xlfn.RANK.EQ(F19,F:F),""))/600,0),3) -> 0.878 | L19: =ROUND(IFERROR((601-IFERROR(_xlfn.RANK.EQ(G19,G:G),""))/600,0),3) -> 0 | M19: =ROUND(IFERROR((601-IFERROR(_xlfn.RANK.EQ(H19,H:H),""))/600,0),3) -> 0 | N19: =VLOOKUP(A19,#REF!,11,0) -> #REF! | O19: =VLOOKUP(A19,#REF!,12,0) -> #REF! | P19: =VLOOKUP(A19,#REF!,13,0) -> #REF! | Q19: =VLOOKUP(A19,#REF!,14,0) -> #REF! | R19: -0.417546 | S19: 3.1656108 | T19: =VLOOKUP(C19,V:W,2,0) -> UK | U19: =IF(T19=T$1,B19,IF(T19=T$2,B19,IF(T19=U$1,B19,""))) | V19: RUSSIA | W19: RUS
