Workbook

Sheet journals_spss
C1: eb | F1: e | H1: f | J1: b | L1: m
C2: pub | D2: ebscore | E2: ebrank | F2: score | G2: rank | H2: score | I2: rank | J2: score | K2: rank | L2: score | M2: rank | N2: wc1 | O2: wc2 | P2: wc3 | Q2: wc4 | R2: wc5 | S2: wc6
A3: journal | B3: publisher | C3: pub | D3: ebscore | E3: ebrank | F3: =CONCATENATE(F1,F2) -> escore | G3: =CONCATENATE(F1,G2) -> erank | H3: =CONCATENATE(H1,H2) -> fscore | I3: =CONCATENATE(H1,I2) -> frank | J3: =CONCATENATE(J1,J2) -> bscore | K3: =CONCATENATE(J1,K2) -> brank | L3: =CONCATENATE(L1,L2) -> mscore | M3: =CONCATENATE(L1,M2) -> mrank | N3: wc1 | O3: wc2 | P3: wc3 | Q3: wc4 | R3: wc5 | S3: wc6
A4: QUARTERLY JOURNAL OF ECONOMICS | B4: OXFORD UNIV PRESS INC | C4: 40 | D4: =IFERROR(VLOOKUP(A4,eco_bus_journals!A:D,4,0),"") -> 10 | E4: =_xlfn.RANK.EQ(D4,D:D) -> 1 | F4: =IFERROR(VLOOKUP(A4,eco_journals!A:D,4,0),"") -> 10 | G4: =IFERROR(_xlfn.RANK.EQ(F4,F:F),"") -> 1 | H4: =IFERROR(VLOOKUP(A4,fin_journals!A:D,4,0),"") | I4: =IFERROR(_xlfn.RANK.EQ(H4,H:H),"") | J4: =IFERROR(VLOOKUP(A4,bus_journals!A:D,4,0),"") | K4: =IFERROR(_xlfn.RANK.EQ(J4,J:J),"") | L4: =IFERROR(VLOOKUP(A4,man_journals!A:D,4,0),"") | M4: =IFERROR(_xlfn.RANK.EQ(L4,L:L),"") | N4: ECONOMICS | T4: journal
A5: AMERICAN ECONOMIC REVIEW | B5: AMER ECONOMIC ASSOC | C5: 116 | D5: =IFERROR(VLOOKUP(A5,eco_bus_journals!A:D,4,0),"") -> 8.4 | E5: =_xlfn.RANK.EQ(D5,D:D) -> 2 | F5: =IFERROR(VLOOKUP(A5,eco_journals!A:D,4,0),"") -> 8.32 | G5: =IFERROR(_xlfn.RANK.EQ(F5,F:F),"") -> 2 | H5: =IFERROR(VLOOKUP(A5,fin_journals!A:D,4,0),"") | I5: =IFERROR(_xlfn.RANK.EQ(H5,H:H),"") | J5: =IFERROR(VLOOKUP(A5,bus_journals!A:D,4,0),"") | K5: =IFERROR(_xlfn.RANK.EQ(J5,J:J),"") | L5: =IFERROR(VLOOKUP(A5,man_journals!A:D,4,0),"") | M5: =IFERROR(_xlfn.RANK.EQ(L5,L:L),"") | N5: ECONOMICS | T5: publisher
A6: ACADEMY OF MANAGEMENT ANNALS | B6: ACAD MANAGEMENT | C6: 31 | D6: =IFERROR(VLOOKUP(A6,eco_bus_journals!A:D,4,0),"") -> 7.04 | E6: =_xlfn.RANK.EQ(D6,D:D) -> 3 | F6: =IFERROR(VLOOKUP(A6,eco_journals!A:D,4,0),"") | G6: =IFERROR(_xlfn.RANK.EQ(F6,F:F),"") | H6: =IFERROR(VLOOKUP(A6,fin_journals!A:D,4,0),"") | I6: =IFERROR(_xlfn.RANK.EQ(H6,H:H),"") | J6: =IFERROR(VLOOKUP(A6,bus_journals!A:D,4,0),"") -> 10 | K6: =IFERROR(_xlfn.RANK.EQ(J6,J:J),"") -> 1 | L6: =IFERROR(VLOOKUP(A6,man_journals!A:D,4,0),"") -> 10 | M6: =IFERROR(_xlfn.RANK.EQ(L6,L:L),"") -> 1 | N6: BUSINESS | O6: MANAGEMENT | T6: pub
A7: NBER MACROECONOMICS ANNUAL | B7: UNIV CHICAGO PRESS | C7: 7 | D7: =IFERROR(VLOOKUP(A7,eco_bus_journals!A:D,4,0),"") -> 6.46 | E7: =_xlfn.RANK.EQ(D7,D:D) -> 4 | F7: =IFERROR(VLOOKUP(A7,eco_journals!A:D,4,0),"") -> 6.68 | G7: =IFERROR(_xlfn.RANK.EQ(F7,F:F),"") -> 3 | H7: =IFERROR(VLOOKUP(A7,fin_journals!A:D,4,0),"") | I7: =IFERROR(_xlfn.RANK.EQ(H7,H:H),"") | J7: =IFERROR(VLOOKUP(A7,bus_journals!A:D,4,0),"") | K7: =IFERROR(_xlfn.RANK.EQ(J7,J:J),"") | L7: =IFERROR(VLOOKUP(A7,man_journals!A:D,4,0),"") | M7: =IFERROR(_xlfn.RANK.EQ(L7,L:L),"") | N7: ECONOMICS | T7: ebscore
A8: ADMINISTRATIVE SCIENCE QUARTERLY | B8: SAGE PUBLICATIONS | C8: 39 | D8: =IFERROR(VLOOKUP(A8,eco_bus_journals!A:D,4,0),"") -> 6.4 | E8: =_xlfn.RANK.EQ(D8,D:D) -> 5 | F8: =IFERROR(VLOOKUP(A8,eco_journals!A:D,4,0),"") | G8: =IFERROR(_xlfn.RANK.EQ(F8,F:F),"") | H8: =IFERROR(VLOOKUP(A8,fin_journals!A:D,4,0),"") | I8: =IFERROR(_xlfn.RANK.EQ(H8,H:H),"") | J8: =IFERROR(VLOOKUP(A8,bus_journals!A:D,4,0),"") -> 9.14 | K8: =IFERROR(_xlfn.RANK.EQ(J8,J:J),"") -> 2 | L8: =IFERROR(VLOOKUP(A8,man_journals!A:D,4,0),"") -> 9.54 | M8: =IFERROR(_xlfn.RANK.EQ(L8,L:L),"") -> 2 | N8: BUSINESS | O8: MANAGEMENT | T8: ebrank
A9: REVIEW OF ECONOMIC STUDIES | B9: OXFORD UNIV PRESS | C9: 80 | D9: =IFERROR(VLOOKUP(A9,eco_bus_journals!A:D,4,0),"") -> 5.99 | E9: =_xlfn.RANK.EQ(D9,D:D) -> 6 | F9: =IFERROR(VLOOKUP(A9,eco_journals!A:D,4,0),"") -> 6.08 | G9: =IFERROR(_xlfn.RANK.EQ(F9,F:F),"") -> 4 | H9: =IFERROR(VLOOKUP(A9,fin_journals!A:D,4,0),"") | I9: =IFERROR(_xlfn.RANK.EQ(H9,H:H),"") | J9: =IFERROR(VLOOKUP(A9,bus_journals!A:D,4,0),"") | K9: =IFERROR(_xlfn.RANK.EQ(J9,J:J),"") | L9: =IFERROR(VLOOKUP(A9,man_journals!A:D,4,0),"") | M9: =IFERROR(_xlfn.RANK.EQ(L9,L:L),"") | N9: ECONOMICS | T9: escore
A10: JOURNAL OF POLITICAL ECONOMY | B10: UNIV CHICAGO PRESS | C10: 110 | D10: =IFERROR(VLOOKUP(A10,eco_bus_journals!A:D,4,0),"") -> 5.74 | E10: =_xlfn.RANK.EQ(D10,D:D) -> 7 | F10: =IFERROR(VLOOKUP(A10,eco_journals!A:D,4,0),"") -> 5.78 | G10: =IFERROR(_xlfn.RANK.EQ(F10,F:F),"") -> 5 | H10: =IFERROR(VLOOKUP(A10,fin_journals!A:D,4,0),"") | I10: =IFERROR(_xlfn.RANK.EQ(H10,H:H),"") | J10: =IFERROR(VLOOKUP(A10,bus_journals!A:D,4,0),"") | K10: =IFERROR(_xlfn.RANK.EQ(J10,J:J),"") | L10: =IFERROR(VLOOKUP(A10,man_journals!A:D,4,0),"") | M10: =IFERROR(_xlfn.RANK.EQ(L10,L:L),"") | N10: ECONOMICS | T10: erank
A11: ECONOMETRICA | B11: WILEY | C11: 76 | D11: =IFERROR(VLOOKUP(A11,eco_bus_journals!A:D,4,0),"") -> 5.32 | E11: =_xlfn.RANK.EQ(D11,D:D) -> 8 | F11: =IFERROR(VLOOKUP(A11,eco_journals!A:D,4,0),"") -> 5.73 | G11: =IFERROR(_xlfn.RANK.EQ(F11,F:F),"") -> 6 | H11: =IFERROR(VLOOKUP(A11,fin_journals!A:D,4,0),"") | I11: =IFERROR(_xlfn.RANK.EQ(H11,H:H),"") | J11: =IFERROR(VLOOKUP(A11,bus_journals!A:D,4,0),"") | K11: =IFERROR(_xlfn.RANK.EQ(J11,J:J),"") | L11: =IFERROR(VLOOKUP(A11,man_journals!A:D,4,0),"") | M11: =IFERROR(_xlfn.RANK.EQ(L11,L:L),"") | N11: ECONOMICS | O11: MATHEMATICS, INTERDISCIPLINARY APPLICATIONS | P11: SOCIAL SCIENCES, MATHEMATICAL METHODS | Q11: STATISTICS & PROBABILITY | T11: fscore
A12: JOURNAL OF FINANCE | B12: WILEY | C12: 73 | D12: =IFERROR(VLOOKUP(A12,eco_bus_journals!A:D,4,0),"") -> 5.01 | E12: =_xlfn.RANK.EQ(D12,D:D) -> 9 | F12: =IFERROR(VLOOKUP(A12,eco_journals!A:D,4,0),"") -> 3.58 | G12: =IFERROR(_xlfn.RANK.EQ(F12,F:F),"") -> 10 | H12: =IFERROR(VLOOKUP(A12,fin_journals!A:D,4,0),"") -> 8.57 | I12: =IFERROR(_xlfn.RANK.EQ(H12,H:H),"") -> 3 | J12: =IFERROR(VLOOKUP(A12,bus_journals!A:D,4,0),"") | K12: =IFERROR(_xlfn.RANK.EQ(J12,J:J),"") | L12: =IFERROR(VLOOKUP(A12,man_journals!A:D,4,0),"") | M12: =IFERROR(_xlfn.RANK.EQ(L12,L:L),"") | N12: FINANCE | O12: ECONOMICS | T12: frank
A13: AMERICAN ECONOMIC REVIEW-INSIGHTS | B13: AMER ECONOMIC ASSOC | C13: 32 | D13: =IFERROR(VLOOKUP(A13,eco_bus_journals!A:D,4,0),"") -> 4.72 | E13: =_xlfn.RANK.EQ(D13,D:D) -> 10 | F13: =IFERROR(VLOOKUP(A13,eco_journals!A:D,4,0),"") -> 4.73 | G13: =IFERROR(_xlfn.RANK.EQ(F13,F:F),"") -> 7 | H13: =IFERROR(VLOOKUP(A13,fin_journals!A:D,4,0),"") | I13: =IFERROR(_xlfn.RANK.EQ(H13,H:H),"") | J13: =IFERROR(VLOOKUP(A13,bus_journals!A:D,4,0),"") | K13: =IFERROR(_xlfn.RANK.EQ(J13,J:J),"") | L13: =IFERROR(VLOOKUP(A13,man_journals!A:D,4,0),"") | M13: =IFERROR(_xlfn.RANK.EQ(L13,L:L),"") | N13: ECONOMICS | T13: bscore
A14: ACADEMY OF MANAGEMENT JOURNAL | B14: ACAD MANAGEMENT | C14: 71 | D14: =IFERROR(VLOOKUP(A14,eco_bus_journals!A:D,4,0),"") -> 4.17 | E14: =_xlfn.RANK.EQ(D14,D:D) -> 11 | F14: =IFERROR(VLOOKUP(A14,eco_journals!A:D,4,0),"") | G14: =IFERROR(_xlfn.RANK.EQ(F14,F:F),"") | H14: =IFERROR(VLOOKUP(A14,fin_journals!A:D,4,0),"") | I14: =IFERROR(_xlfn.RANK.EQ(H14,H:H),"") | J14: =IFERROR(VLOOKUP(A14,bus_journals!A:D,4,0),"") -> 7.21 | K14: =IFERROR(_xlfn.RANK.EQ(J14,J:J),"") -> 4 | L14: =IFERROR(VLOOKUP(A14,man_journals!A:D,4,0),"") -> 6.84 | M14: =IFERROR(_xlfn.RANK.EQ(L14,L:L),"") -> 3 | N14: BUSINESS | O14: MANAGEMENT | T14: brank
A15: JOURNAL OF ECONOMIC LITERATURE | B15: AMER ECONOMIC ASSOC | C15: 16 | D15: =IFERROR(VLOOKUP(A15,eco_bus_journals!A:D,4,0),"") -> 3.8 | E15: =_xlfn.RANK.EQ(D15,D:D) -> 12 | F15: =IFERROR(VLOOKUP(A15,eco_journals!A:D,4,0),"") -> 3.56 | G15: =IFERROR(_xlfn.RANK.EQ(F15,F:F),"") -> 11 | H15: =IFERROR(VLOOKUP(A15,fin_journals!A:D,4,0),"") | I15: =IFERROR(_xlfn.RANK.EQ(H15,H:H),"") | J15: =IFERROR(VLOOKUP(A15,bus_journals!A:D,4,0),"") | K15: =IFERROR(_xlfn.RANK.EQ(J15,J:J),"") | L15: =IFERROR(VLOOKUP(A15,man_journals!A:D,4,0),"") | M15: =IFERROR(_xlfn.RANK.EQ(L15,L:L),"") | N15: ECONOMICS | T15: mscore
A16: AMERICAN ECONOMIC JOURNAL-APPLIED ECONOMICS | B16: AMER ECONOMIC ASSOC | C16: 43 | D16: =IFERROR(VLOOKUP(A16,eco_bus_journals!A:D,4,0),"") -> 3.77 | E16: =_xlfn.RANK.EQ(D16,D:D) -> 13 | F16: =IFERROR(VLOOKUP(A16,eco_journals!A:D,4,0),"") -> 3.88 | G16: =IFERROR(_xlfn.RANK.EQ(F16,F:F),"") -> 8 | H16: =IFERROR(VLOOKUP(A16,fin_journals!A:D,4,0),"") | I16: =IFERROR(_xlfn.RANK.EQ(H16,H:H),"") | J16: =IFERROR(VLOOKUP(A16,bus_journals!A:D,4,0),"") | K16: =IFERROR(_xlfn.RANK.EQ(J16,J:J),"") | L16: =IFERROR(VLOOKUP(A16,man_journals!A:D,4,0),"") | M16: =IFERROR(_xlfn.RANK.EQ(L16,L:L),"") | N16: ECONOMICS | T16: mrank
A17: AMERICAN ECONOMIC JOURNAL-MACROECONOMICS | B17: AMER ECONOMIC ASSOC | C17: 38 | D17: =IFERROR(VLOOKUP(A17,eco_bus_journals!A:D,4,0),"") -> 3.71 | E17: =_xlfn.RANK.EQ(D17,D:D) -> 14 | F17: =IFERROR(VLOOKUP(A17,eco_journals!A:D,4,0),"") -> 3.8 | G17: =IFERROR(_xlfn.RANK.EQ(F17,F:F),"") -> 9 | H17: =IFERROR(VLOOKUP(A17,fin_journals!A:D,4,0),"") | I17: =IFERROR(_xlfn.RANK.EQ(H17,H:H),"") | J17: =IFERROR(VLOOKUP(A17,bus_journals!A:D,4,0),"") | K17: =IFERROR(_xlfn.RANK.EQ(J17,J:J),"") | L17: =IFERROR(VLOOKUP(A17,man_journals!A:D,4,0),"") | M17: =IFERROR(_xlfn.RANK.EQ(L17,L:L),"") | N17: ECONOMICS | T17: wc1
A18: REVIEW OF FINANCIAL STUDIES | B18: OXFORD UNIV PRESS INC | C18: 141 | D18: =IFERROR(VLOOKUP(A18,eco_bus_journals!A:D,4,0),"") -> 3.56 | E18: =_xlfn.RANK.EQ(D18,D:D) -> 15 | F18: =IFERROR(VLOOKUP(A18,eco_journals!A:D,4,0),"") -> 1.99 | G18: =IFERROR(_xlfn.RANK.EQ(F18,F:F),"") -> 19 | H18: =IFERROR(VLOOKUP(A18,fin_journals!A:D,4,0),"") -> 7.73 | I18: =IFERROR(_xlfn.RANK.EQ(H18,H:H),"") -> 4 | J18: =IFERROR(VLOOKUP(A18,bus_journals!A:D,4,0),"") | K18: =IFERROR(_xlfn.RANK.EQ(J18,J:J),"") | L18: =IFERROR(VLOOKUP(A18,man_journals!A:D,4,0),"") | M18: =IFERROR(_xlfn.RANK.EQ(L18,L:L),"") | N18: FINANCE | O18: ECONOMICS | T18: wc2
A19: ACADEMY OF MANAGEMENT REVIEW | B19: ACAD MANAGEMENT | C19: 40 | D19: =IFERROR(VLOOKUP(A19,eco_bus_journals!A:D,4,0),"") -> 3.53 | E19: =_xlfn.RANK.EQ(D19,D:D) -> 16 | F19: =IFERROR(VLOOKUP(A19,eco_journals!A:D,4,0),"") | G19: =IFERROR(_xlfn.RANK.EQ(F19,F:F),"") | H19: =IFERROR(VLOOKUP(A19,fin_journals!A:D,4,0),"") | I19: =IFERROR(_xlfn.RANK.EQ(H19,H:H),"") | J19: =IFERROR(VLOOKUP(A19,bus_journals!A:D,4,0),"") -> 6.21 | K19: =IFERROR(_xlfn.RANK.EQ(J19,J:J),"") -> 5 | L19: =IFERROR(VLOOKUP(A19,man_journals!A:D,4,0),"") -> 5.92 | M19: =IFERROR(_xlfn.RANK.EQ(L19,L:L),"") -> 4 | N19: BUSINESS | O19: MANAGEMENT | T19: wc3
A20: ANNUAL REVIEW OF ECONOMICS | B20: ANNUAL REVIEWS | C20: 31 | D20: =IFERROR(VLOOKUP(A20,eco_bus_journals!A:D,4,0),"") -> 3.36 | E20: =_xlfn.RANK.EQ(D20,D:D) -> 17 | F20: =IFERROR(VLOOKUP(A20,eco_journals!A:D,4,0),"") -> 3.44 | G20: =IFERROR(_xlfn.RANK.EQ(F20,F:F),"") -> 12 | H20: =IFERROR(VLOOKUP(A20,fin_journals!A:D,4,0),"") | I20: =IFERROR(_xlfn.RANK.EQ(H20,H:H),"") | J20: =IFERROR(VLOOKUP(A20,bus_journals!A:D,4,0),"") | K20: =IFERROR(_xlfn.RANK.EQ(J20,J:J),"") | L20: =IFERROR(VLOOKUP(A20,man_journals!A:D,4,0),"") | M20: =IFERROR(_xlfn.RANK.EQ(L20,L:L),"") | N20: ECONOMICS | T20: wc4
A21: JOURNAL OF FINANCIAL ECONOMICS | B21: ELSEVIER | C21: 152 | D21: =IFERROR(VLOOKUP(A21,eco_bus_journals!A:D,4,0),"") -> 3.17 | E21: =_xlfn.RANK.EQ(D21,D:D) -> 18 | F21: =IFERROR(VLOOKUP(A21,eco_journals!A:D,4,0),"") -> 1.67 | G21: =IFERROR(_xlfn.RANK.EQ(F21,F:F),"") -> 22 | H21: =IFERROR(VLOOKUP(A21,fin_journals!A:D,4,0),"") -> 6.64 | I21: =IFERROR(_xlfn.RANK.EQ(H21,H:H),"") -> 5 | J21: =IFERROR(VLOOKUP(A21,bus_journals!A:D,4,0),"") | K21: =IFERROR(_xlfn.RANK.EQ(J21,J:J),"") | L21: =IFERROR(VLOOKUP(A21,man_journals!A:D,4,0),"") | M21: =IFERROR(_xlfn.RANK.EQ(L21,L:L),"") | N21: FINANCE | O21: ECONOMICS | T21: wc5
A22: STRATEGIC MANAGEMENT JOURNAL | B22: WILEY | C22: 121 | D22: =IFERROR(VLOOKUP(A22,eco_bus_journals!A:D,4,0),"") -> 2.98 | E22: =_xlfn.RANK.EQ(D22,D:D) -> 19 | F22: =IFERROR(VLOOKUP(A22,eco_journals!A:D,4,0),"") | G22: =IFERROR(_xlfn.RANK.EQ(F22,F:F),"") | H22: =IFERROR(VLOOKUP(A22,fin_journals!A:D,4,0),"") | I22: =IFERROR(_xlfn.RANK.EQ(H22,H:H),"") | J22: =IFERROR(VLOOKUP(A22,bus_journals!A:D,4,0),"") -> 4.86 | K22: =IFERROR(_xlfn.RANK.EQ(J22,J:J),"") -> 7 | L22: =IFERROR(VLOOKUP(A22,man_journals!A:D,4,0),"") -> 4.38 | M22: =IFERROR(_xlfn.RANK.EQ(L22,L:L),"") -> 5 | N22: BUSINESS | O22: MANAGEMENT | T22: wc6
A23: JOURNAL OF MARKETING | B23: SAGE PUBLICATIONS | C23: 65 | D23: =IFERROR(VLOOKUP(A23,eco_bus_journals!A:D,4,0),"") -> 2.97 | E23: =_xlfn.RANK.EQ(D23,D:D) -> 20 | F23: =IFERROR(VLOOKUP(A23,eco_journals!A:D,4,0),"") | G23: =IFERROR(_xlfn.RANK.EQ(F23,F:F),"") | H23: =IFERROR(VLOOKUP(A23,fin_journals!A:D,4,0),"") | I23: =IFERROR(_xlfn.RANK.EQ(H23,H:H),"") | J23: =IFERROR(VLOOKUP(A23,bus_journals!A:D,4,0),"") -> 7.99 | K23: =IFERROR(_xlfn.RANK.EQ(J23,J:J),"") -> 3 | L23: =IFERROR(VLOOKUP(A23,man_journals!A:D,4,0),"") | M23: =IFERROR(_xlfn.RANK.EQ(L23,L:L),"") | N23: BUSINESS
A24: JOURNAL OF ECONOMIC PERSPECTIVES | B24: AMER ECONOMIC ASSOC | C24: 41 | D24: =IFERROR(VLOOKUP(A24,eco_bus_journals!A:D,4,0),"") -> 2.9 | E24: =_xlfn.RANK.EQ(D24,D:D) -> 21 | F24: =IFERROR(VLOOKUP(A24,eco_journals!A:D,4,0),"") -> 2.67 | G24: =IFERROR(_xlfn.RANK.EQ(F24,F:F),"") -> 14 | H24: =IFERROR(VLOOKUP(A24,fin_journals!A:D,4,0),"") | I24: =IFERROR(_xlfn.RANK.EQ(H24,H:H),"") | J24: =IFERROR(VLOOKUP(A24,bus_journals!A:D,4,0),"") | K24: =IFERROR(_xlfn.RANK.EQ(J24,J:J),"") | L24: =IFERROR(VLOOKUP(A24,man_journals!A:D,4,0),"") | M24: =IFERROR(_xlfn.RANK.EQ(L24,L:L),"") | N24: ECONOMICS
A25: BROOKINGS PAPERS ON ECONOMIC ACTIVITY | B25: JOHNS HOPKINS UNIV PRESS | C25: 24 | D25: =IFERROR(VLOOKUP(A25,eco_bus_journals!A:D,4,0),"") -> 2.83 | E25: =_xlfn.RANK.EQ(D25,D:D) -> 22 | F25: =IFERROR(VLOOKUP(A25,eco_journals!A:D,4,0),"") -> 2.68 | G25: =IFERROR(_xlfn.RANK.EQ(F25,F:F),"") -> 13 | H25: =IFERROR(VLOOKUP(A25,fin_journals!A:D,4,0),"") | I25: =IFERROR(_xlfn.RANK.EQ(H25,H:H),"") | J25: =IFERROR(VLOOKUP(A25,bus_journals!A:D,4,0),"") | K25: =IFERROR(_xlfn.RANK.EQ(J25,J:J),"") | L25: =IFERROR(VLOOKUP(A25,man_journals!A:D,4,0),"") | M25: =IFERROR(_xlfn.RANK.EQ(L25,L:L),"") | N25: ECONOMICS
A26: JOURNAL OF MANAGEMENT | B26: SAGE PUBLICATIONS | C26: 88 | D26: =IFERROR(VLOOKUP(A26,eco_bus_journals!A:D,4,0),"") -> 2.8 | E26: =_xlfn.RANK.EQ(D26,D:D) -> 23 | F26: =IFERROR(VLOOKUP(A26,eco_journals!A:D,4,0),"") | G26: =IFERROR(_xlfn.RANK.EQ(F26,F:F),"") | H26: =IFERROR(VLOOKUP(A26,fin_journals!A:D,4,0),"") | I26: =IFERROR(_xlfn.RANK.EQ(H26,H:H),"") | J26: =IFERROR(VLOOKUP(A26,bus_journals!A:D,4,0),"") -> 4.79 | K26: =IFERROR(_xlfn.RANK.EQ(J26,J:J),"") -> 9 | L26: =IFERROR(VLOOKUP(A26,man_journals!A:D,4,0),"") -> 3.91 | M26: =IFERROR(_xlfn.RANK.EQ(L26,L:L),"") -> 8 | N26: BUSINESS | O26: MANAGEMENT | P26: PSYCHOLOGY, APPLIED
A27: AMERICAN ECONOMIC JOURNAL-ECONOMIC POLICY | B27: AMER ECONOMIC ASSOC | C27: 51 | D27: =IFERROR(VLOOKUP(A27,eco_bus_journals!A:D,4,0),"") -> 2.79 | E27: =_xlfn.RANK.EQ(D27,D:D) -> 24 | F27: =IFERROR(VLOOKUP(A27,eco_journals!A:D,4,0),"") -> 2.67 | G27: =IFERROR(_xlfn.RANK.EQ(F27,F:F),"") -> 14 | H27: =IFERROR(VLOOKUP(A27,fin_journals!A:D,4,0),"") | I27: =IFERROR(_xlfn.RANK.EQ(H27,H:H),"") | J27: =IFERROR(VLOOKUP(A27,bus_journals!A:D,4,0),"") | K27: =IFERROR(_xlfn.RANK.EQ(J27,J:J),"") | L27: =IFERROR(VLOOKUP(A27,man_journals!A:D,4,0),"") | M27: =IFERROR(_xlfn.RANK.EQ(L27,L:L),"") | N27: ECONOMICS
A28: ACADEMY OF MANAGEMENT PERSPECTIVES | B28: ACAD MANAGEMENT | C28: 30 | D28: =IFERROR(VLOOKUP(A28,eco_bus_journals!A:D,4,0),"") -> 2.6 | E28: =_xlfn.RANK.EQ(D28,D:D) -> 25 | F28: =IFERROR(VLOOKUP(A28,eco_journals!A:D,4,0),"") | G28: =IFERROR(_xlfn.RANK.EQ(F28,F:F),"") | H28: =IFERROR(VLOOKUP(A28,fin_journals!A:D,4,0),"") | I28: =IFERROR(_xlfn.RANK.EQ(H28,H:H),"") | J28: =IFERROR(VLOOKUP(A28,bus_journals!A:D,4,0),"") -> 4.85 | K28: =IFERROR(_xlfn.RANK.EQ(J28,J:J),"") -> 8 | L28: =IFERROR(VLOOKUP(A28,man_journals!A:D,4,0),"") -> 3.37 | M28: =IFERROR(_xlfn.RANK.EQ(L28,L:L),"") -> 9 | N28: BUSINESS | O28: MANAGEMENT
A29: ORGANIZATION SCIENCE | B29: INFORMS | C29: 74 | D29: =IFERROR(VLOOKUP(A29,eco_bus_journals!A:D,4,0),"") -> 2.55 | E29: =_xlfn.RANK.EQ(D29,D:D) -> 26 | F29: =IFERROR(VLOOKUP(A29,eco_journals!A:D,4,0),"") | G29: =IFERROR(_xlfn.RANK.EQ(F29,F:F),"") | H29: =IFERROR(VLOOKUP(A29,fin_journals!A:D,4,0),"") | I29: =IFERROR(_xlfn.RANK.EQ(H29,H:H),"") | J29: =IFERROR(VLOOKUP(A29,bus_journals!A:D,4,0),"") | K29: =IFERROR(_xlfn.RANK.EQ(J29,J:J),"") | L29: =IFERROR(VLOOKUP(A29,man_journals!A:D,4,0),"") -> 4.38 | M29: =IFERROR(_xlfn.RANK.EQ(L29,L:L),"") -> 5 | N29: MANAGEMENT
A30: JOURNAL OF ACCOUNTING & ECONOMICS | B30: ELSEVIER | C30: 35 | D30: =IFERROR(VLOOKUP(A30,eco_bus_journals!A:D,4,0),"") -> 2.46 | E30: =_xlfn.RANK.EQ(D30,D:D) -> 27 | F30: =IFERROR(VLOOKUP(A30,eco_journals!A:D,4,0),"") -> 0.54 | G30: =IFERROR(_xlfn.RANK.EQ(F30,F:F),"") -> 44 | H30: =IFERROR(VLOOKUP(A30,fin_journals!A:D,4,0),"") -> 9.8 | I30: =IFERROR(_xlfn.RANK.EQ(H30,H:H),"") -> 2 | J30: =IFERROR(VLOOKUP(A30,bus_journals!A:D,4,0),"") | K30: =IFERROR(_xlfn.RANK.EQ(J30,J:J),"") | L30: =IFERROR(VLOOKUP(A30,man_journals!A:D,4,0),"") | M30: =IFERROR(_xlfn.RANK.EQ(L30,L:L),"") | N30: FINANCE | O30: ECONOMICS
A31: ACADEMY OF MANAGEMENT DISCOVERIES | B31: ACAD MANAGEMENT | C31: 32 | D31: =IFERROR(VLOOKUP(A31,eco_bus_journals!A:D,4,0),"") -> 2.39 | E31: =_xlfn.RANK.EQ(D31,D:D) -> 28 | F31: =IFERROR(VLOOKUP(A31,eco_journals!A:D,4,0),"") | G31: =IFERROR(_xlfn.RANK.EQ(F31,F:F),"") | H31: =IFERROR(VLOOKUP(A31,fin_journals!A:D,4,0),"") | I31: =IFERROR(_xlfn.RANK.EQ(H31,H:H),"") | J31: =IFERROR(VLOOKUP(A31,bus_journals!A:D,4,0),"") | K31: =IFERROR(_xlfn.RANK.EQ(J31,J:J),"") | L31: =IFERROR(VLOOKUP(A31,man_journals!A:D,4,0),"") -> 4.03 | M31: =IFERROR(_xlfn.RANK.EQ(L31,L:L),"") -> 7 | N31: MANAGEMENT
A32: JOURNAL OF MANAGEMENT STUDIES | B32: WILEY | C32: 93 | D32: =IFERROR(VLOOKUP(A32,eco_bus_journals!A:D,4,0),"") -> 2.39 | E32: =_xlfn.RANK.EQ(D32,D:D) -> 28 | F32: =IFERROR(VLOOKUP(A32,eco_journals!A:D,4,0),"") | G32: =IFERROR(_xlfn.RANK.EQ(F32,F:F),"") | H32: =IFERROR(VLOOKUP(A32,fin_journals!A:D,4,0),"") | I32: =IFERROR(_xlfn.RANK.EQ(H32,H:H),"") | J32: =IFERROR(VLOOKUP(A32,bus_journals!A:D,4,0),"") -> 4.28 | K32: =IFERROR(_xlfn.RANK.EQ(J32,J:J),"") -> 11 | L32: =IFERROR(VLOOKUP(A32,man_journals!A:D,4,0),"") -> 3.29 | M32: =IFERROR(_xlfn.RANK.EQ(L32,L:L),"") -> 10 | N32: BUSINESS | O32: MANAGEMENT
A33: JOURNAL OF LABOR ECONOMICS | B33: UNIV CHICAGO PRESS | C33: 32 | D33: =IFERROR(VLOOKUP(A33,eco_bus_journals!A:D,4,0),"") -> 2.32 | E33: =_xlfn.RANK.EQ(D33,D:D) -> 30 | F33: =IFERROR(VLOOKUP(A33,eco_journals!A:D,4,0),"") -> 2.37 | G33: =IFERROR(_xlfn.RANK.EQ(F33,F:F),"") -> 16 | H33: =IFERROR(VLOOKUP(A33,fin_journals!A:D,4,0),"") | I33: =IFERROR(_xlfn.RANK.EQ(H33,H:H),"") | J33: =IFERROR(VLOOKUP(A33,bus_journals!A:D,4,0),"") | K33: =IFERROR(_xlfn.RANK.EQ(J33,J:J),"") | L33: =IFERROR(VLOOKUP(A33,man_journals!A:D,4,0),"") | M33: =IFERROR(_xlfn.RANK.EQ(L33,L:L),"") | N33: ECONOMICS | O33: INDUSTRIAL RELATIONS & LABOR
A34: REVIEW OF ECONOMICS AND STATISTICS | B34: MIT PRESS | C34: 65 | D34: =IFERROR(VLOOKUP(A34,eco_bus_journals!A:D,4,0),"") -> 2.31 | E34: =_xlfn.RANK.EQ(D34,D:D) -> 31 | F34: =IFERROR(VLOOKUP(A34,eco_journals!A:D,4,0),"") -> 2.37 | G34: =IFERROR(_xlfn.RANK.EQ(F34,F:F),"") -> 16 | H34: =IFERROR(VLOOKUP(A34,fin_journals!A:D,4,0),"") | I34: =IFERROR(_xlfn.RANK.EQ(H34,H:H),"") | J34: =IFERROR(VLOOKUP(A34,bus_journals!A:D,4,0),"") | K34: =IFERROR(_xlfn.RANK.EQ(J34,J:J),"") | L34: =IFERROR(VLOOKUP(A34,man_journals!A:D,4,0),"") | M34: =IFERROR(_xlfn.RANK.EQ(L34,L:L),"") | N34: ECONOMICS | O34: SOCIAL SCIENCES, MATHEMATICAL METHODS
A35: JOURNAL OF ACCOUNTING RESEARCH | B35: WILEY | C35: 34 | D35: =IFERROR(VLOOKUP(A35,eco_bus_journals!A:D,4,0),"") -> 2.21 | E35: =_xlfn.RANK.EQ(D35,D:D) -> 32 | F35: =IFERROR(VLOOKUP(A35,eco_journals!A:D,4,0),"") | G35: =IFERROR(_xlfn.RANK.EQ(F35,F:F),"") | H35: =IFERROR(VLOOKUP(A35,fin_journals!A:D,4,0),"") -> 10 | I35: =IFERROR(_xlfn.RANK.EQ(H35,H:H),"") -> 1 | J35: =IFERROR(VLOOKUP(A35,bus_journals!A:D,4,0),"") | K35: =IFERROR(_xlfn.RANK.EQ(J35,J:J),"") | L35: =IFERROR(VLOOKUP(A35,man_journals!A:D,4,0),"") | M35: =IFERROR(_xlfn.RANK.EQ(L35,L:L),"") | N35: FINANCE
A36: JOURNAL OF THE ACADEMY OF MARKETING SCIENCE | B36: SPRINGER | C36: 71 | D36: =IFERROR(VLOOKUP(A36,eco_bus_journals!A:D,4,0),"") -> 2.18 | E36: =_xlfn.RANK.EQ(D36,D:D) -> 33 | F36: =IFERROR(VLOOKUP(A36,eco_journals!A:D,4,0),"") | G36: =IFERROR(_xlfn.RANK.EQ(F36,F:F),"") | H36: =IFERROR(VLOOKUP(A36,fin_journals!A:D,4,0),"") | I36: =IFERROR(_xlfn.RANK.EQ(H36,H:H),"") | J36: =IFERROR(VLOOKUP(A36,bus_journals!A:D,4,0),"") -> 5.13 | K36: =IFERROR(_xlfn.RANK.EQ(J36,J:J),"") -> 6 | L36: =IFERROR(VLOOKUP(A36,man_journals!A:D,4,0),"") | M36: =IFERROR(_xlfn.RANK.EQ(L36,L:L),"") | N36: BUSINESS
A37: JOURNAL OF BUSINESS VENTURING | B37: ELSEVIER | C37: 60 | D37: =IFERROR(VLOOKUP(A37,eco_bus_journals!A:D,4,0),"") -> 2.16 | E37: =_xlfn.RANK.EQ(D37,D:D) -> 34 | F37: =IFERROR(VLOOKUP(A37,eco_journals!A:D,4,0),"") | G37: =IFERROR(_xlfn.RANK.EQ(F37,F:F),"") | H37: =IFERROR(VLOOKUP(A37,fin_journals!A:D,4,0),"") | I37: =IFERROR(_xlfn.RANK.EQ(H37,H:H),"") | J37: =IFERROR(VLOOKUP(A37,bus_journals!A:D,4,0),"") -> 4.31 | K37: =IFERROR(_xlfn.RANK.EQ(J37,J:J),"") -> 10 | L37: =IFERROR(VLOOKUP(A37,man_journals!A:D,4,0),"") | M37: =IFERROR(_xlfn.RANK.EQ(L37,L:L),"") | N37: BUSINESS
A38: STRATEGIC ENTREPRENEURSHIP JOURNAL | B38: WILEY | C38: 45 | D38: =IFERROR(VLOOKUP(A38,eco_bus_journals!A:D,4,0),"") -> 2.12 | E38: =_xlfn.RANK.EQ(D38,D:D) -> 35 | F38: =IFERROR(VLOOKUP(A38,eco_journals!A:D,4,0),"") | G38: =IFERROR(_xlfn.RANK.EQ(F38,F:F),"") | H38: =IFERROR(VLOOKUP(A38,fin_journals!A:D,4,0),"") | I38: =IFERROR(_xlfn.RANK.EQ(H38,H:H),"") | J38: =IFERROR(VLOOKUP(A38,bus_journals!A:D,4,0),"") -> 4.19 | K38: =IFERROR(_xlfn.RANK.EQ(J38,J:J),"") -> 12 | L38: =IFERROR(VLOOKUP(A38,man_journals!A:D,4,0),"") -> 2.49 | M38: =IFERROR(_xlfn.RANK.EQ(L38,L:L),"") -> 14 | N38: BUSINESS | O38: MANAGEMENT
A39: ENTREPRENEURSHIP THEORY AND PRACTICE | B39: SAGE PUBLICATIONS | C39: 91 | D39: =IFERROR(VLOOKUP(A39,eco_bus_journals!A:D,4,0),"") -> 2.11 | E39: =_xlfn.RANK.EQ(D39,D:D) -> 36 | F39: =IFERROR(VLOOKUP(A39,eco_journals!A:D,4,0),"") | G39: =IFERROR(_xlfn.RANK.EQ(F39,F:F),"") | H39: =IFERROR(VLOOKUP(A39,fin_journals!A:D,4,0),"") | I39: =IFERROR(_xlfn.RANK.EQ(H39,H:H),"") | J39: =IFERROR(VLOOKUP(A39,bus_journals!A:D,4,0),"") -> 4.15 | K39: =IFERROR(_xlfn.RANK.EQ(J39,J:J),"") -> 13 | L39: =IFERROR(VLOOKUP(A39,man_journals!A:D,4,0),"") | M39: =IFERROR(_xlfn.RANK.EQ(L39,L:L),"") | N39: BUSINESS
A40: ORGANIZATIONAL RESEARCH METHODS | B40: SAGE PUBLICATIONS | C40: 58 | D40: =IFERROR(VLOOKUP(A40,eco_bus_journals!A:D,4,0),"") -> 2.06 | E40: =_xlfn.RANK.EQ(D40,D:D) -> 37 | F40: =IFERROR(VLOOKUP(A40,eco_journals!A:D,4,0),"") | G40: =IFERROR(_xlfn.RANK.EQ(F40,F:F),"") | H40: =IFERROR(VLOOKUP(A40,fin_journals!A:D,4,0),"") | I40: =IFERROR(_xlfn.RANK.EQ(H40,H:H),"") | J40: =IFERROR(VLOOKUP(A40,bus_journals!A:D,4,0),"") | K40: =IFERROR(_xlfn.RANK.EQ(J40,J:J),"") | L40: =IFERROR(VLOOKUP(A40,man_journals!A:D,4,0),"") -> 3.28 | M40: =IFERROR(_xlfn.RANK.EQ(L40,L:L),"") -> 11 | N40: MANAGEMENT | O40: PSYCHOLOGY, APPLIED
...

Sheet institutions_spss
D1: eb | E1: e | F1: f | G1: b | H1: m | Y1: aus | AB1: For comparisons, place two countries in Y1 and Y2 | AR1: country | AT1: 0 | AU1: 1
A2: institution | C2: country | D2: pub | E2: pub | F2: pub | G2: pub | H2: pub | I2: score | J2: score | K2: score | L2: score | M2: score | N2: rank | O2: rank | P2: rank | Q2: rank | R2: rank | W2: ranks | AB2: For a country alone, leave Y2 blank | AR2: WALES | AS2: UK | AT2: -0.10518436 | AU2: 3.2209162 | AW2: institution
A3: institution | C3: country | D3: ebpub | E3: epub | F3: fpub | G3: bpub | H3: mpub | I3: ebscore | J3: escore | K3: fscore | L3: bscore | M3: mscore | N3: ebrank | O3: erank | P3: frank | Q3: brank | R3: mrank | W3: pc1 | X3: pc2 | Y3: country | Z3: for plot | AB3: First Component, pc1: associated with all four categories (comprehensive institutions perform better) | AR3: VIETNAM | AS3: VTN | AT3: 1.8566266 | AU3: 1.5835011 | AW3: institution
A4: Center for Economic & Policy Research (CEPR) | B4: CEPR | C4: USA | D4: =IFERROR(VLOOKUP(A4,eco_bus_institutions!A:D,3,0),"") -> 158 | E4: =IFERROR(VLOOKUP(A4,eco_institutions!A:D,3,0),"") -> 151 | F4: =IFERROR(VLOOKUP(A4,fin_institutions!A:D,3,0),"") -> 43 | G4: =IFERROR(VLOOKUP(A4,bus_institutions!A:D,3,0),0) -> 0 | H4: =IFERROR(VLOOKUP(A4,man_institutions!A:D,3,0),0) -> 0 | I4: =IFERROR(VLOOKUP(A4,eco_bus_institutions!A:D,4,0),0) -> 8 | J4: =IFERROR(VLOOKUP(A4,eco_institutions!A:D,4,0),0) -> 7.34 | K4: =IFERROR(VLOOKUP(A4,fin_institutions!A:D,4,0),0) -> 4.91 | L4: =IFERROR(VLOOKUP(A4,bus_institutions!A:D,4,0),0) -> 0 | M4: =IFERROR(VLOOKUP(A4,man_institutions!A:D,4,0),0) -> 0 | N4: =ROUND(IFERROR((601-_xlfn.RANK.EQ(I4,I:I))/600,0),3) -> 1 | O4: =ROUND(IFERROR((601-IFERROR(_xlfn.RANK.EQ(J4,J:J),""))/600,0),3) -> 0.997 | P4: =ROUND(IFERROR((601-IFERROR(_xlfn.RANK.EQ(K4,K:K),""))/600,0),3) -> 0.978 | Q4: =ROUND(IFERROR((601-IFERROR(_xlfn.RANK.EQ(L4,L:L),""))/600,0),3) -> 0.05 | R4: =ROUND(IFERROR((601-IFERROR(_xlfn.RANK.EQ(M4,M:M),""))/600,0),3) -> 0.04 | S4: =VLOOKUP(A4,#REF!,11,0) -> #REF! | T4: =VLOOKUP(A4,#REF!,12,0) -> #REF! | U4: =VLOOKUP(A4,#REF!,13,0) -> #REF! | V4: =VLOOKUP(A4,#REF!,14,0) -> #REF! | W4: -0.10518436 | X4: 3.2209162 | Y4: =VLOOKUP(C4,AR:AS,2,0) -> USA | Z4: =IF(Y4=Y$1,B4,IF(Y4=Y$2,B4,"")) | AB4: Second Component: North (Economics and Finance), South (Business and Management) | AR4: USA | AS4: USA | AT4: 3.3461328 | AU4: 0.29500451 | AW4: Center for Economic & Policy Research (CEPR)
A5: University of Chicago | B5: Chicago | C5: USA | D5: =IFERROR(VLOOKUP(A5,eco_bus_institutions!A:D,3,0),"") -> 203 | E5: =IFERROR(VLOOKUP(A5,eco_institutions!A:D,3,0),"") -> 157 | F5: =IFERROR(VLOOKUP(A5,fin_institutions!A:D,3,0),"") -> 49 | G5: =IFERROR(VLOOKUP(A5,bus_institutions!A:D,3,0),0) -> 18 | H5: =IFERROR(VLOOKUP(A5,man_institutions!A:D,3,0),0) -> 9 | I5: =IFERROR(VLOOKUP(A5,eco_bus_institutions!A:D,4,0),0) -> 7.88 | J5: =IFERROR(VLOOKUP(A5,eco_institutions!A:D,4,0),0) -> 7.96 | K5: =IFERROR(VLOOKUP(A5,fin_institutions!A:D,4,0),0) -> 6.92 | L5: =IFERROR(VLOOKUP(A5,bus_institutions!A:D,4,0),0) -> 3 | M5: =IFERROR(VLOOKUP(A5,man_institutions!A:D,4,0),0) -> 1.31 | N5: =ROUND(IFERROR((601-_xlfn.RANK.EQ(I5,I:I))/600,0),3) -> 0.998 | O5: =ROUND(IFERROR((601-IFERROR(_xlfn.RANK.EQ(J5,J:J),""))/600,0),3) -> 0.998 | P5: =ROUND(IFERROR((601-IFERROR(_xlfn.RANK.EQ(K5,K:K),""))/600,0),3) -> 0.995 | Q5: =ROUND(IFERROR((601-IFERROR(_xlfn.RANK.EQ(L5,L:L),""))/600,0),3) -> 0.797 | R5: =ROUND(IFERROR((601-IFERROR(_xlfn.RANK.EQ(M5,M:M),""))/600,0),3) -> 0.338 | S5: =VLOOKUP(A5,#REF!,11,0) -> #REF! | T5: =VLOOKUP(A5,#REF!,12,0) -> #REF! | U5: =VLOOKUP(A5,#REF!,13,0) -> #REF! | V5: =VLOOKUP(A5,#REF!,14,0) -> #REF! | W5: 1.8566266 | X5: 1.5835011 | Y5: =VLOOKUP(C5,AR:AS,2,0) -> USA | Z5: =IF(Y5=Y$1,B5,IF(Y5=Y$2,B5,"")) | AB5: 88% of the variance explained | AR5: UNITED ARAB EMIRATES | AS5: UAE | AT5: -0.28326645 | AU5: 3.0913155 | AW5: Chicago
A6: London Business School | B6: LBS | C6: ENGLAND | D6: =IFERROR(VLOOKUP(A6,eco_bus_institutions!A:D,3,0),"") -> 61 | E6: =IFERROR(VLOOKUP(A6,eco_institutions!A:D,3,0),"") -> 30 | F6: =IFERROR(VLOOKUP(A6,fin_institutions!A:D,3,0),"") -> 16 | G6: =IFERROR(VLOOKUP(A6,bus_institutions!A:D,3,0),0) -> 23 | H6: =IFERROR(VLOOKUP(A6,man_institutions!A:D,3,0),0) -> 22 | I6: =IFERROR(VLOOKUP(A6,eco_bus_institutions!A:D,4,0),0) -> 7.33 | J6: =IFERROR(VLOOKUP(A6,eco_institutions!A:D,4,0),0) -> 8 | K6: =IFERROR(VLOOKUP(A6,fin_institutions!A:D,4,0),0) -> 5.11 | L6: =IFERROR(VLOOKUP(A6,bus_institutions!A:D,4,0),0) -> 6.39 | M6: =IFERROR(VLOOKUP(A6,man_institutions!A:D,4,0),0) -> 5.05 | N6: =ROUND(IFERROR((601-_xlfn.RANK.EQ(I6,I:I))/600,0),3) -> 0.997 | O6: =ROUND(IFERROR((601-IFERROR(_xlfn.RANK.EQ(J6,J:J),""))/600,0),3) -> 1 | P6: =ROUND(IFERROR((601-IFERROR(_xlfn.RANK.EQ(K6,K:K),""))/600,0),3) -> 0.982 | Q6: =ROUND(IFERROR((601-IFERROR(_xlfn.RANK.EQ(L6,L:L),""))/600,0),3) -> 0.98 | R6: =ROUND(IFERROR((601-IFERROR(_xlfn.RANK.EQ(M6,M:M),""))/600,0),3) -> 0.97 | S6: =VLOOKUP(A6,#REF!,11,0) -> #REF! | T6: =VLOOKUP(A6,#REF!,12,0) -> #REF! | U6: =VLOOKUP(A6,#REF!,13,0) -> #REF! | V6: =VLOOKUP(A6,#REF!,14,0) -> #REF! | W6: 3.3461328 | X6: 0.29500451 | Y6: =VLOOKUP(C6,AR:AS,2,0) -> UK | Z6: =IF(Y6=Y$1,B6,IF(Y6=Y$2,B6,"")) | AR6: TURKIYE | AS6: TUR | AT6: 1.4781418 | AU6: -0.10513947 | AW6: London Business School
A7: Princeton University | B7: Princeton | C7: USA | D7: =IFERROR(VLOOKUP(A7,eco_bus_institutions!A:D,3,0),"") -> 113 | E7: =IFERROR(VLOOKUP(A7,eco_institutions!A:D,3,0),"") -> 101 | F7: =IFERROR(VLOOKUP(A7,fin_institutions!A:D,3,0),"") -> 18 | G7: =IFERROR(VLOOKUP(A7,bus_institutions!A:D,3,0),0) -> 0 | H7: =IFERROR(VLOOKUP(A7,man_institutions!A:D,3,0),0) -> 0 | I7: =IFERROR(VLOOKUP(A7,eco_bus_institutions!A:D,4,0),0) -> 7.19 | J7: =IFERROR(VLOOKUP(A7,eco_institutions!A:D,4,0),0) -> 7.18 | K7: =IFERROR(VLOOKUP(A7,fin_institutions!A:D,4,0),0) -> 2.75 | L7: =IFERROR(VLOOKUP(A7,bus_institutions!A:D,4,0),0) -> 0 | M7: =IFERROR(VLOOKUP(A7,man_institutions!A:D,4,0),0) -> 0 | N7: =ROUND(IFERROR((601-_xlfn.RANK.EQ(I7,I:I))/600,0),3) -> 0.995 | O7: =ROUND(IFERROR((601-IFERROR(_xlfn.RANK.EQ(J7,J:J),""))/600,0),3) -> 0.995 | P7: =ROUND(IFERROR((601-IFERROR(_xlfn.RANK.EQ(K7,K:K),""))/600,0),3) -> 0.878 | Q7: =ROUND(IFERROR((601-IFERROR(_xlfn.RANK.EQ(L7,L:L),""))/600,0),3) -> 0.05 | R7: =ROUND(IFERROR((601-IFERROR(_xlfn.RANK.EQ(M7,M:M),""))/600,0),3) -> 0.04 | S7: =VLOOKUP(A7,#REF!,11,0) -> #REF! | T7: =VLOOKUP(A7,#REF!,12,0) -> #REF! | U7: =VLOOKUP(A7,#REF!,13,0) -> #REF! | V7: =VLOOKUP(A7,#REF!,14,0) -> #REF! | W7: -0.28326645 | X7: 3.0913155 | Y7: =VLOOKUP(C7,AR:AS,2,0) -> USA | Z7: =IF(Y7=Y$1,B7,IF(Y7=Y$2,B7,"")) | AB7: NorthEast Direction signals excellence | AR7: TUNISIA | AS7: TUN | AT7: 3.4243678 | AU7: 0.21550734 | AW7: Princeton
A8: University of California Santa Barbara | B8: UCSB | C8: USA | D8: =IFERROR(VLOOKUP(A8,eco_bus_institutions!A:D,3,0),"") -> 56 | E8: =IFERROR(VLOOKUP(A8,eco_institutions!A:D,3,0),"") -> 44 | F8: =IFERROR(VLOOKUP(A8,fin_institutions!A:D,3,0),"") -> 6 | G8: =IFERROR(VLOOKUP(A8,bus_institutions!A:D,3,0),0) -> 5 | H8: =IFERROR(VLOOKUP(A8,man_institutions!A:D,3,0),0) -> 10 | I8: =IFERROR(VLOOKUP(A8,eco_bus_institutions!A:D,4,0),0) -> 6.86 | J8: =IFERROR(VLOOKUP(A8,eco_institutions!A:D,4,0),0) -> 6.93 | K8: =IFERROR(VLOOKUP(A8,fin_institutions!A:D,4,0),0) -> 1.06 | L8: =IFERROR(VLOOKUP(A8,bus_institutions!A:D,4,0),0) -> 2.31 | M8: =IFERROR(VLOOKUP(A8,man_institutions!A:D,4,0),0) -> 4.9 | N8: =ROUND(IFERROR((601-_xlfn.RANK.EQ(I8,I:I))/600,0),3) -> 0.993 | O8: =ROUND(IFERROR((601-IFERROR(_xlfn.RANK.EQ(J8,J:J),""))/600,0),3) -> 0.992 | P8: =ROUND(IFERROR((601-IFERROR(_xlfn.RANK.EQ(K8,K:K),""))/600,0),3) -> 0.262 | Q8: =ROUND(IFERROR((601-IFERROR(_xlfn.RANK.EQ(L8,L:L),""))/600,0),3) -> 0.662 | R8: =ROUND(IFERROR((601-IFERROR(_xlfn.RANK.EQ(M8,M:M),""))/600,0),3) -> 0.965 | S8: =VLOOKUP(A8,#REF!,11,0) -> #REF! | T8: =VLOOKUP(A8,#REF!,12,0) -> #REF! | U8: =VLOOKUP(A8,#REF!,13,0) -> #REF! | V8: =VLOOKUP(A8,#REF!,14,0) -> #REF! | W8: 1.4781418 | X8: -0.10513947 | Y8: =VLOOKUP(C8,AR:AS,2,0) -> USA | Z8: =IF(Y8=Y$1,B8,IF(Y8=Y$2,B8,"")) | AB8: To compare, move an imaginary NW to SE line: better to be on the right of that line | AR8: TAIWAN | AS8: TWN | AT8: 3.013365 | AU8: 0.40613106 | AW8: California Santa Barbara
A9: Stanford University | B9: Stanford | C9: USA | D9: =IFERROR(VLOOKUP(A9,eco_bus_institutions!A:D,3,0),"") -> 273 | E9: =IFERROR(VLOOKUP(A9,eco_institutions!A:D,3,0),"") -> 196 | F9: =IFERROR(VLOOKUP(A9,fin_institutions!A:D,3,0),"") -> 44 | G9: =IFERROR(VLOOKUP(A9,bus_institutions!A:D,3,0),0) -> 37 | H9: =IFERROR(VLOOKUP(A9,man_institutions!A:D,3,0),0) -> 59 | I9: =IFERROR(VLOOKUP(A9,eco_bus_institutions!A:D,4,0),0) -> 6.58 | J9: =IFERROR(VLOOKUP(A9,eco_institutions!A:D,4,0),0) -> 5.84 | K9: =IFERROR(VLOOKUP(A9,fin_institutions!A:D,4,0),0) -> 7.99 | L9: =IFERROR(VLOOKUP(A9,bus_institutions!A:D,4,0),0) -> 6.87 | M9: =IFERROR(VLOOKUP(A9,man_institutions!A:D,4,0),0) -> 6.92 | N9: =ROUND(IFERROR((601-_xlfn.RANK.EQ(I9,I:I))/600,0),3) -> 0.992 | O9: =ROUND(IFERROR((601-IFERROR(_xlfn.RANK.EQ(J9,J:J),""))/600,0),3) -> 0.985 | P9: =ROUND(IFERROR((601-IFERROR(_xlfn.RANK.EQ(K9,K:K),""))/600,0),3) -> 0.998 | Q9: =ROUND(IFERROR((601-IFERROR(_xlfn.RANK.EQ(L9,L:L),""))/600,0),3) -> 0.995 | R9: =ROUND(IFERROR((601-IFERROR(_xlfn.RANK.EQ(M9,M:M),""))/600,0),3) -> 0.995 | S9: =VLOOKUP(A9,#REF!,11,0) -> #REF! | T9: =VLOOKUP(A9,#REF!,12,0) -> #REF! | U9: =VLOOKUP(A9,#REF!,13,0) -> #REF! | V9: =VLOOKUP(A9,#REF!,14,0) -> #REF! | W9: 3.4243678 | X9: 0.21550734 | Y9: =VLOOKUP(C9,AR:AS,2,0) -> USA | Z9: =IF(Y9=Y$1,B9,IF(Y9=Y$2,B9,"")) | AR9: SWITZERLAND | AS9: CHE | AT9: 3.3847108 | AU9: 0.22807663 | AW9: Stanford
A10: Massachusetts Institute of Technology (MIT) | B10: MIT | C10: USA | D10: =IFERROR(VLOOKUP(A10,eco_bus_institutions!A:D,3,0),"") -> 244 | E10: =IFERROR(VLOOKUP(A10,eco_institutions!A:D,3,0),"") -> 152 | F10: =IFERROR(VLOOKUP(A10,fin_institutions!A:D,3,0),"") -> 49 | G10: =IFERROR(VLOOKUP(A10,bus_institutions!A:D,3,0),0) -> 33 | H10: =IFERROR(VLOOKUP(A10,man_institutions!A:D,3,0),0) -> 65 | I10: =IFERROR(VLOOKUP(A10,eco_bus_institutions!A:D,4,0),0) -> 6.37 | J10: =IFERROR(VLOOKUP(A10,eco_institutions!A:D,4,0),0) -> 6.95 | K10: =IFERROR(VLOOKUP(A10,fin_institutions!A:D,4,0),0) -> 3.57 | L10: =IFERROR(VLOOKUP(A10,bus_institutions!A:D,4,0),0) -> 3.91 | M10: =IFERROR(VLOOKUP(A10,man_institutions!A:D,4,0),0) -> 3.97 | N10: =ROUND(IFERROR((601-_xlfn.RANK.EQ(I10,I:I))/600,0),3) -> 0.99 | O10: =ROUND(IFERROR((601-IFERROR(_xlfn.RANK.EQ(J10,J:J),""))/600,0),3) -> 0.993 | P10: =ROUND(IFERROR((601-IFERROR(_xlfn.RANK.EQ(K10,K:K),""))/600,0),3) -> 0.928 | Q10: =ROUND(IFERROR((601-IFERROR(_xlfn.RANK.EQ(L10,L:L),""))/600,0),3) -> 0.892 | R10: =ROUND(IFERROR((601-IFERROR(_xlfn.RANK.EQ(M10,M:M),""))/600,0),3) -> 0.935 | S10: =VLOOKUP(A10,#REF!,11,0) -> #REF! | T10: =VLOOKUP(A10,#REF!,12,0) -> #REF! | U10: =VLOOKUP(A10,#REF!,13,0) -> #REF! | V10: =VLOOKUP(A10,#REF!,14,0) -> #REF! | W10: 3.013365 | X10: 0.40613106 | Y10: =VLOOKUP(C10,AR:AS,2,0) -> USA | Z10: =IF(Y10=Y$1,B10,IF(Y10=Y$2,B10,"")) | AB10: For Australia | AR10: SWEDEN | AS10: SWE | AT10: -1.7444902 | AU10: 2.02713 | AW10: MIT
A11: Yale University | B11: Yale | C11: USA | D11: =IFERROR(VLOOKUP(A11,eco_bus_institutions!A:D,3,0),"") -> 165 | E11: =IFERROR(VLOOKUP(A11,eco_institutions!A:D,3,0),"") -> 134 | F11: =IFERROR(VLOOKUP(A11,fin_institutions!A:D,3,0),"") -> 27 | G11: =IFERROR(VLOOKUP(A11,bus_institutions!A:D,3,0),0) -> 13 | H11: =IFERROR(VLOOKUP(A11,man_institutions!A:D,3,0),0) -> 14 | I11: =IFERROR(VLOOKUP(A11,eco_bus_institutions!A:D,4,0),0) -> 6.15 | J11: =IFERROR(VLOOKUP(A11,eco_institutions!A:D,4,0),0) -> 5.66 | K11: =IFERROR(VLOOKUP(A11,fin_institutions!A:D,4,0),0) -> 6.49 | L11: =IFERROR(VLOOKUP(A11,bus_institutions!A:D,4,0),0) -> 6.61 | M11: =IFERROR(VLOOKUP(A11,man_institutions!A:D,4,0),0) -> 6.09 | N11: =ROUND(IFERROR((601-_xlfn.RANK.EQ(I11,I:I))/600,0),3) -> 0.988 | O11: =ROUND(IFERROR((601-IFERROR(_xlfn.RANK.EQ(J11,J:J),""))/600,0),3) -> 0.983 | P11: =ROUND(IFERROR((601-IFERROR(_xlfn.RANK.EQ(K11,K:K),""))/600,0),3) -> 0.993 | Q11: =ROUND(IFERROR((601-IFERROR(_xlfn.RANK.EQ(L11,L:L),""))/600,0),3) -> 0.988 | R11: =ROUND(IFERROR((601-IFERROR(_xlfn.RANK.EQ(M11,M:M),""))/600,0),3) -> 0.987 | S11: =VLOOKUP(A11,#REF!,11,0) -> #REF! | T11: =VLOOKUP(A11,#REF!,12,0) -> #REF! | U11: =VLOOKUP(A11,#REF!,13,0) -> #REF! | V11: =VLOOKUP(A11,#REF!,14,0) -> #REF! | W11: 3.3847108 | X11: 0.22807663 | Y11: =VLOOKUP(C11,AR:AS,2,0) -> USA | Z11: =IF(Y11=Y$1,B11,IF(Y11=Y$2,B11,"")) | AB11: Cluster 1: Best performers | AC11: Adelaide, ANU, Melbourne | AR11: SPAIN | AS11: SPAIN | AT11: 3.055082 | AU11: 0.39959249 | AW11: Yale
A12: National Bureau of Economic Research | B12: NBER | C12: USA | D12: =IFERROR(VLOOKUP(A12,eco_bus_institutions!A:D,3,0),"") -> 724 | E12: =IFERROR(VLOOKUP(A12,eco_institutions!A:D,3,0),"") -> 710 | F12: =IFERROR(VLOOKUP(A12,fin_institutions!A:D,3,0),"") | G12: =IFERROR(VLOOKUP(A12,bus_institutions!A:D,3,0),0) -> 0 | H12: =IFERROR(VLOOKUP(A12,man_institutions!A:D,3,0),0) -> 0 | I12: =IFERROR(VLOOKUP(A12,eco_bus_institutions!A:D,4,0),0) -> 5.99 | J12: =IFERROR(VLOOKUP(A12,eco_institutions!A:D,4,0),0) -> 5.19 | K12: =IFERROR(VLOOKUP(A12,fin_institutions!A:D,4,0),0) -> 0 | L12: =IFERROR(VLOOKUP(A12,bus_institutions!A:D,4,0),0) -> 0 | M12: =IFERROR(VLOOKUP(A12,man_institutions!A:D,4,0),0) -> 0 | N12: =ROUND(IFERROR((601-_xlfn.RANK.EQ(I12,I:I))/600,0),3) -> 0.987 | O12: =ROUND(IFERROR((601-IFERROR(_xlfn.RANK.EQ(J12,J:J),""))/600,0),3) -> 0.978 | P12: =ROUND(IFERROR((601-IFERROR(_xlfn.RANK.EQ(K12,K:K),""))/600,0),3) -> 0.058 | Q12: =ROUND(IFERROR((601-IFERROR(_xlfn.RANK.EQ(L12,L:L),""))/600,0),3) -> 0.05 | R12: =ROUND(IFERROR((601-IFERROR(_xlfn.RANK.EQ(M12,M:M),""))/600,0),3) -> 0.04 | S12: =VLOOKUP(A12,#REF!,11,0) -> #REF! | T12: =VLOOKUP(A12,#REF!,12,0) -> #REF! | U12: =VLOOKUP(A12,#REF!,13,0) -> #REF! | V12: =VLOOKUP(A12,#REF!,14,0) -> #REF! | W12: -1.7444902 | X12: 2.02713 | Y12: =VLOOKUP(C12,AR:AS,2,0) -> USA | Z12: =IF(Y12=Y$1,B12,IF(Y12=Y$2,B12,"")) | AB12: Cluster 2: Fast followers | AC12: UTAS,Western Aus, La Trobe, Wollongong, Maquarie, RMIT, Deakin, UTS, Sifney, Queensland | AR12: SOUTH KOREA | AS12: KOREA | AT12: 2.8276361 | AU12: 0.56199511 | AW12: National Bureau of Economic Research
A13: Harvard University | B13: Harvard | C13: USA | D13: =IFERROR(VLOOKUP(A13,eco_bus_institutions!A:D,3,0),"") -> 430 | E13: =IFERROR(VLOOKUP(A13,eco_institutions!A:D,3,0),"") -> 265 | F13: =IFERROR(VLOOKUP(A13,fin_institutions!A:D,3,0),"") -> 52 | G13: =IFERROR(VLOOKUP(A13,bus_institutions!A:D,3,0),0) -> 85 | H13: =IFERROR(VLOOKUP(A13,man_institutions!A:D,3,0),0) -> 106 | I13: =IFERROR(VLOOKUP(A13,eco_bus_institutions!A:D,4,0),0) -> 5.87 | J13: =IFERROR(VLOOKUP(A13,eco_institutions!A:D,4,0),0) -> 6.65 | K13: =IFERROR(VLOOKUP(A13,fin_institutions!A:D,4,0),0) -> 3.92 | L13: =IFERROR(VLOOKUP(A13,bus_institutions!A:D,4,0),0) -> 4.04 | M13: =IFERROR(VLOOKUP(A13,man_institutions!A:D,4,0),0) -> 3.85 | N13: =ROUND(IFERROR((601-_xlfn.RANK.EQ(I13,I:I))/600,0),3) -> 0.985 | O13: =ROUND(IFERROR((601-IFERROR(_xlfn.RANK.EQ(J13,J:J),""))/600,0),3) -> 0.99 | P13: =ROUND(IFERROR((601-IFERROR(_xlfn.RANK.EQ(K13,K:K),""))/600,0),3) -> 0.943 | Q13: =ROUND(IFERROR((601-IFERROR(_xlfn.RANK.EQ(L13,L:L),""))/600,0),3) -> 0.91 | R13: =ROUND(IFERROR((601-IFERROR(_xlfn.RANK.EQ(M13,M:M),""))/600,0),3) -> 0.928 | S13: =VLOOKUP(A13,#REF!,11,0) -> #REF! | T13: =VLOOKUP(A13,#REF!,12,0) -> #REF! | U13: =VLOOKUP(A13,#REF!,13,0) -> #REF! | V13: =VLOOKUP(A13,#REF!,14,0) -> #REF! | W13: 3.055082 | X13: 0.39959249 | Y13: =VLOOKUP(C13,AR:AS,2,0) -> USA | Z13: =IF(Y13=Y$1,B13,IF(Y13=Y$2,B13,"")) | AB13: Cluster 3: Followers | AC13: Edith Cowan, South Australia | AR13: SOUTH AFRICA | AS13: ZAF | AT13: 3.2338538 | AU13: 0.068263435 | AW13: Harvard
A14: University of California Berkeley | B14: UCB | C14: USA | D14: =IFERROR(VLOOKUP(A14,eco_bus_institutions!A:D,3,0),"") -> 207 | E14: =IFERROR(VLOOKUP(A14,eco_institutions!A:D,3,0),"") -> 156 | F14: =IFERROR(VLOOKUP(A14,fin_institutions!A:D,3,0),"") -> 28 | G14: =IFERROR(VLOOKUP(A14,bus_institutions!A:D,3,0),0) -> 26 | H14: =IFERROR(VLOOKUP(A14,man_institutions!A:D,3,0),0) -> 45 | I14: =IFERROR(VLOOKUP(A14,eco_bus_institutions!A:D,4,0),0) -> 5.47 | J14: =IFERROR(VLOOKUP(A14,eco_institutions!A:D,4,0),0) -> 5.61 | K14: =IFERROR(VLOOKUP(A14,fin_institutions!A:D,4,0),0) -> 3.92 | L14: =IFERROR(VLOOKUP(A14,bus_institutions!A:D,4,0),0) -> 3.84 | M14: =IFERROR(VLOOKUP(A14,man_institutions!A:D,4,0),0) -> 2.78 | N14: =ROUND(IFERROR((601-_xlfn.RANK.EQ(I14,I:I))/600,0),3) -> 0.983 | O14: =ROUND(IFERROR((601-IFERROR(_xlfn.RANK.EQ(J14,J:J),""))/600,0),3) -> 0.982 | P14: =ROUND(IFERROR((601-IFERROR(_xlfn.RANK.EQ(K14,K:K),""))/600,0),3) -> 0.943 | Q14: =ROUND(IFERROR((601-IFERROR(_xlfn.RANK.EQ(L14,L:L),""))/600,0),3) -> 0.882 | R14: =ROUND(IFERROR((601-IFERROR(_xlfn.RANK.EQ(M14,M:M),""))/600,0),3) -> 0.84 | S14: =VLOOKUP(A14,#REF!,11,0) -> #REF! | T14: =VLOOKUP(A14,#REF!,12,0) -> #REF! | U14: =VLOOKUP(A14,#REF!,13,0) -> #REF! | V14: =VLOOKUP(A14,#REF!,14,0) -> #REF! | W14: 2.8276361 | X14: 0.56199511 | Y14: =VLOOKUP(C14,AR:AS,2,0) -> USA | Z14: =IF(Y14=Y$1,B14,IF(Y14=Y$2,B14,"")) | AB14: Cluster 4: Laggers | AC14: Curtin, Griffith, QUT, Newcastle, Swinburne | AR14: SLOVAKIA | AS14: SLK | AT14: 3.255072 | AU14: 0.29919178 | AW14: California Berkeley
A15: Boston University | B15: Boston | C15: USA | D15: =IFERROR(VLOOKUP(A15,eco_bus_institutions!A:D,3,0),"") -> 126 | E15: =IFERROR(VLOOKUP(A15,eco_institutions!A:D,3,0),"") -> 73 | F15: =IFERROR(VLOOKUP(A15,fin_institutions!A:D,3,0),"") -> 23 | G15: =IFERROR(VLOOKUP(A15,bus_institutions!A:D,3,0),0) -> 21 | H15: =IFERROR(VLOOKUP(A15,man_institutions!A:D,3,0),0) -> 30 | I15: =IFERROR(VLOOKUP(A15,eco_bus_institutions!A:D,4,0),0) -> 5.22 | J15: =IFERROR(VLOOKUP(A15,eco_institutions!A:D,4,0),0) -> 4.72 | K15: =IFERROR(VLOOKUP(A15,fin_institutions!A:D,4,0),0) -> 3.14 | L15: =IFERROR(VLOOKUP(A15,bus_institutions!A:D,4,0),0) -> 8 | M15: =IFERROR(VLOOKUP(A15,man_institutions!A:D,4,0),0) -> 6.27 | N15: =ROUND(IFERROR((601-_xlfn.RANK.EQ(I15,I:I))/600,0),3) -> 0.982 | O15: =ROUND(IFERROR((601-IFERROR(_xlfn.RANK.EQ(J15,J:J),""))/600,0),3) -> 0.972 | P15: =ROUND(IFERROR((601-IFERROR(_xlfn.RANK.EQ(K15,K:K),""))/600,0),3) -> 0.903 | Q15: =ROUND(IFERROR((601-IFERROR(_xlfn.RANK.EQ(L15,L:L),""))/600,0),3) -> 1 | R15: =ROUND(IFERROR((601-IFERROR(_xlfn.RANK.EQ(M15,M:M),""))/600,0),3) -> 0.988 | S15: =VLOOKUP(A15,#REF!,11,0) -> #REF! | T15: =VLOOKUP(A15,#REF!,12,0) -> #REF! | U15: =VLOOKUP(A15,#REF!,13,0) -> #REF! | V15: =VLOOKUP(A15,#REF!,14,0) -> #REF! | W15: 3.2338538 | X15: 0.068263435 | Y15: =VLOOKUP(C15,AR:AS,2,0) -> USA | Z15: =IF(Y15=Y$1,B15,IF(Y15=Y$2,B15,"")) | AR15: SINGAPORE | AS15: SGP | AT15: -0.17839576 | AU15: 2.5538865 | AW15: Boston
A16: Northwestern University | B16: Northwestern | C16: USA | D16: =IFERROR(VLOOKUP(A16,eco_bus_institutions!A:D,3,0),"") -> 180 | E16: =IFERROR(VLOOKUP(A16,eco_institutions!A:D,3,0),"") -> 102 | F16: =IFERROR(VLOOKUP(A16,fin_institutions!A:D,3,0),"") -> 9 | G16: =IFERROR(VLOOKUP(A16,bus_institutions!A:D,3,0),0) -> 48 | H16: =IFERROR(VLOOKUP(A16,man_institutions!A:D,3,0),0) -> 52 | I16: =IFERROR(VLOOKUP(A16,eco_bus_institutions!A:D,4,0),0) -> 5.16 | J16: =IFERROR(VLOOKUP(A16,eco_institutions!A:D,4,0),0) -> 5.24 | K16: =IFERROR(VLOOKUP(A16,fin_institutions!A:D,4,0),0) -> 5.24 | L16: =IFERROR(VLOOKUP(A16,bus_institutions!A:D,4,0),0) -> 5.76 | M16: =IFERROR(VLOOKUP(A16,man_institutions!A:D,4,0),0) -> 4.07 | N16: =ROUND(IFERROR((601-_xlfn.RANK.EQ(I16,I:I))/600,0),3) -> 0.98 | O16: =ROUND(IFERROR((601-IFERROR(_xlfn.RANK.EQ(J16,J:J),""))/600,0),3) -> 0.98 | P16: =ROUND(IFERROR((601-IFERROR(_xlfn.RANK.EQ(K16,K:K),""))/600,0),3) -> 0.983 | Q16: =ROUND(IFERROR((601-IFERROR(_xlfn.RANK.EQ(L16,L:L),""))/600,0),3) -> 0.975 | R16: =ROUND(IFERROR((601-IFERROR(_xlfn.RANK.EQ(M16,M:M),""))/600,0),3) -> 0.942 | S16: =VLOOKUP(A16,#REF!,11,0) -> #REF! | T16: =VLOOKUP(A16,#REF!,12,0) -> #REF! | U16: =VLOOKUP(A16,#REF!,13,0) -> #REF! | V16: =VLOOKUP(A16,#REF!,14,0) -> #REF! | W16: 3.255072 | X16: 0.29919178 | Y16: =VLOOKUP(C16,AR:AS,2,0) -> USA | Z16: =IF(Y16=Y$1,B16,IF(Y16=Y$2,B16,"")) | AR16: SERBIA | AS16: SERBIA | AT16: 2.941224 | AU16: 0.49513781 | AW16: Northwestern
A17: Pompeu Fabra University | B17: Pompeu Fabra | C17: SPAIN | D17: =IFERROR(VLOOKUP(A17,eco_bus_institutions!A:D,3,0),"") -> 80 | E17: =IFERROR(VLOOKUP(A17,eco_institutions!A:D,3,0),"") -> 55 | F17: =IFERROR(VLOOKUP(A17,fin_institutions!A:D,3,0),"") -> 16 | G17: =IFERROR(VLOOKUP(A17,bus_institutions!A:D,3,0),0) -> 14 | H17: =IFERROR(VLOOKUP(A17,man_institutions!A:D,3,0),0) -> 15 | I17: =IFERROR(VLOOKUP(A17,eco_bus_institutions!A:D,4,0),0) -> 5.16 | J17: =IFERROR(VLOOKUP(A17,eco_institutions!A:D,4,0),0) -> 6.16 | K17: =IFERROR(VLOOKUP(A17,fin_institutions!A:D,4,0),0) -> 1.57 | L17: =IFERROR(VLOOKUP(A17,bus_institutions!A:D,4,0),0) -> 1.08 | M17: =IFERROR(VLOOKUP(A17,man_institutions!A:D,4,0),0) -> 1.17 | N17: =ROUND(IFERROR((601-_xlfn.RANK.EQ(I17,I:I))/600,0),3) -> 0.98 | O17: =ROUND(IFERROR((601-IFERROR(_xlfn.RANK.EQ(J17,J:J),""))/600,0),3) -> 0.988 | P17: =ROUND(IFERROR((601-IFERROR(_xlfn.RANK.EQ(K17,K:K),""))/600,0),3) -> 0.723 | Q17: =ROUND(IFERROR((601-IFERROR(_xlfn.RANK.EQ(L17,L:L),""))/600,0),3) -> 0.087 | R17: =ROUND(IFERROR((601-IFERROR(_xlfn.RANK.EQ(M17,M:M),""))/600,0),3) -> 0.212 | S17: =VLOOKUP(A17,#REF!,11,0) -> #REF! | T17: =VLOOKUP(A17,#REF!,12,0) -> #REF! | U17: =VLOOKUP(A17,#REF!,13,0) -> #REF! | V17: =VLOOKUP(A17,#REF!,14,0) -> #REF! | W17: -0.17839576 | X17: 2.5538865 | Y17: =VLOOKUP(C17,AR:AS,2,0) -> SPAIN | Z17: =IF(Y17=Y$1,B17,IF(Y17=Y$2,B17,"")) | AR17: SCOTLAND | AS17: UK | AT17: -0.37184879 | AU17: 2.9955619 | AW17: Pompeu Fabra
A18: Columbia University | B18: Columbia | C18: USA | D18: =IFERROR(VLOOKUP(A18,eco_bus_institutions!A:D,3,0),"") -> 256 | E18: =IFERROR(VLOOKUP(A18,eco_institutions!A:D,3,0),"") -> 165 | F18: =IFERROR(VLOOKUP(A18,fin_institutions!A:D,3,0),"") -> 61 | G18: =IFERROR(VLOOKUP(A18,bus_institutions!A:D,3,0),0) -> 47 | H18: =IFERROR(VLOOKUP(A18,man_institutions!A:D,3,0),0) -> 39 | I18: =IFERROR(VLOOKUP(A18,eco_bus_institutions!A:D,4,0),0) -> 5.13 | J18: =IFERROR(VLOOKUP(A18,eco_institutions!A:D,4,0),0) -> 5.07 | K18: =IFERROR(VLOOKUP(A18,fin_institutions!A:D,4,0),0) -> 4.23 | L18: =IFERROR(VLOOKUP(A18,bus_institutions!A:D,4,0),0) -> 5.36 | M18: =IFERROR(VLOOKUP(A18,man_institutions!A:D,4,0),0) -> 2.62 | N18: =ROUND(IFERROR((601-_xlfn.RANK.EQ(I18,I:I))/600,0),3) -> 0.977 | O18: =ROUND(IFERROR((601-IFERROR(_xlfn.RANK.EQ(J18,J:J),""))/600,0),3) -> 0.977 | P18: =ROUND(IFERROR((601-IFERROR(_xlfn.RANK.EQ(K18,K:K),""))/600,0),3) -> 0.962 | Q18: =ROUND(IFERROR((601-IFERROR(_xlfn.RANK.EQ(L18,L:L),""))/600,0),3) -> 0.962 | R18: =ROUND(IFERROR((601-IFERROR(_xlfn.RANK.EQ(M18,M:M),""))/600,0),3) -> 0.808 | S18: =VLOOKUP(A18,#REF!,11,0) -> #REF! | T18: =VLOOKUP(A18,#REF!,12,0) -> #REF! | U18: =VLOOKUP(A18,#REF!,13,0) -> #REF! | V18: =VLOOKUP(A18,#REF!,14,0) -> #REF! | W18: 2.941224 | X18: 0.49513781 | Y18: =VLOOKUP(C18,AR:AS,2,0) -> USA | Z18: =IF(Y18=Y$1,B18,IF(Y18=Y$2,B18,"")) | AR18: SAUDI ARABIA | AS18: SAU | AT18: 2.4617441 | AU18: 0.75473318 | AW18: Columbia
A19: Centre for Economic Policy Research - UK | B19: CEPRUK | C19: ENGLAND | D19: =IFERROR(VLOOKUP(A19,eco_bus_institutions!A:D,3,0),"") -> 253 | E19: =IFERROR(VLOOKUP(A19,eco_institutions!A:D,3,0),"") -> 233 | F19: =IFERROR(VLOOKUP(A19,fin_institutions!A:D,3,0),"") -> 63 | G19: =IFERROR(VLOOKUP(A19,bus_institutions!A:D,3,0),0) -> 0 | H19: =IFERROR(VLOOKUP(A19,man_institutions!A:D,3,0),0) -> 0 | I19: =IFERROR(VLOOKUP(A19,eco_bus_institutions!A:D,4,0),0) -> 5.01 | J19: =IFERROR(VLOOKUP(A19,eco_institutions!A:D,4,0),0) -> 4.48 | K19: =IFERROR(VLOOKUP(A19,fin_institutions!A:D,4,0),0) -> 2.4 | L19: =IFERROR(VLOOKUP(A19,bus_institutions!A:D,4,0),0) -> 0 | M19: =IFERROR(VLOOKUP(A19,man_institutions!A:D,4,0),0) -> 0 | N19: =ROUND(IFERROR((601-_xlfn.RANK.EQ(I19,I:I))/600,0),3) -> 0.975 | O19: =ROUND(IFERROR((601-IFERROR(_xlfn.RANK.EQ(J19,J:J),""))/600,0),3) -> 0.97 | P19: =ROUND(IFERROR((601-IFERROR(_xlfn.RANK.EQ(K19,K:K),""))/600,0),3) -> 0.85 | Q19: =ROUND(IFERROR((601-IFERROR(_xlfn.RANK.EQ(L19,L:L),""))/600,0),3) -> 0.05 | R19: =ROUND(IFERROR((601-IFERROR(_xlfn.RANK.EQ(M19,M:M),""))/600,0),3) -> 0.04 | S19: =VLOOKUP(A19,#REF!,11,0) -> #REF! | T19: =VLOOKUP(A19,#REF!,12,0) -> #REF! | U19: =VLOOKUP(A19,#REF!,13,0) -> #REF! | V19: =VLOOKUP(A19,#REF!,14,0) -> #REF! | W19: -0.37184879 | X19: 2.9955619 | Y19: =VLOOKUP(C19,AR:AS,2,0) -> UK | Z19: =IF(Y19=Y$1,B19,IF(Y19=Y$2,B19,"")) | AR19: RUSSIA | AS19: RUS | AT19: 3.2167895 | AU19: 0.029288811 | AW19: Centre for Economic Policy Research - UK
A20: University of California Los Angeles | B20: UCLA | C20: USA | D20: =IFERROR(VLOOKUP(A20,eco_bus_institutions!A:D,3,0),"") -> 149 | E20: =IFERROR(VLOOKUP(A20,eco_institutions!A:D,3,0),"") -> 88 | F20: =IFERROR(VLOOKUP(A20,fin_institutions!A:D,3,0),"") -> 37 | G20: =IFERROR(VLOOKUP(A20,bus_institutions!A:D,3,0),0) -> 24 | H20: =IFERROR(VLOOKUP(A20,man_institutions!A:D,3,0),0) -> 38 | I20: =IFERROR(VLOOKUP(A20,eco_bus_institutions!A:D,4,0),0) -> 4.99 | J20: =IFERROR(VLOOKUP(A20,eco_institutions!A:D,4,0),0) -> 6.14 | K20: =IFERROR(VLOOKUP(A20,fin_institutions!A:D,4,0),0) -> 2.97 | L20: =IFERROR(VLOOKUP(A20,bus_institutions!A:D,4,0),0) -> 2.93 | M20: =IFERROR(VLOOKUP(A20,man_institutions!A:D,4,0),0) -> 2.46 | N20: =ROUND(IFERROR((601-_xlfn.RANK.EQ(I20,I:I))/600,0),3) -> 0.973 | O20: =ROUND(IFERROR((601-IFERROR(_xlfn.RANK.EQ(J20,J:J),""))/600,0),3) -> 0.987 | P20: =ROUND(IFERROR((601-IFERROR(_xlfn.RANK.EQ(K20,K:K),""))/600,0),3) -> 0.892 | Q20: =ROUND(IFERROR((601-IFERROR(_xlfn.RANK.EQ(L20,L:L),""))/600,0),3) -> 0.785 | R20: =ROUND(IFERROR((601-IFERROR(_xlfn.RANK.EQ(M20,M:M),""))/600,0),3) -> 0.783 | S20: =VLOOKUP(A20,#REF!,11,0) -> #REF! | T20: =VLOOKUP(A20,#REF!,12,0) -> #REF! | U20: =VLOOKUP(A20,#REF!,13,0) -> #REF! | V20: =VLOOKUP(A20,#REF!,14,0) -> #REF! | W20: 2.4617441 | X20: 0.75473318 | Y20: =VLOOKUP(C20,AR:AS,2,0) -> USA | Z20: =IF(Y20=Y$1,B20,IF(Y20=Y$2,B20,"")) | AR20: ROMANIA | AS20: ROM | AT20: -0.21512198 | AU20: 3.0851701 | AW20: California Los Angeles
A21: INSEAD Business School | B21: INSEAD | C21: FRANCE | D21: =IFERROR(VLOOKUP(A21,eco_bus_institutions!A:D,3,0),"") -> 89 | E21: =IFERROR(VLOOKUP(A21,eco_institutions!A:D,3,0),"") -> 21 | F21: =IFERROR(VLOOKUP(A21,fin_institutions!A:D,3,0),"") -> 11 | G21: =IFERROR(VLOOKUP(A21,bus_institutions!A:D,3,0),0) -> 45 | H21: =IFERROR(VLOOKUP(A21,man_institutions!A:D,3,0),0) -> 51 | I21: =IFERROR(VLOOKUP(A21,eco_bus_institutions!A:D,4,0),0) -> 4.98 | J21: =IFERROR(VLOOKUP(A21,eco_institutions!A:D,4,0),0) -> 2.79 | K21: =IFERROR(VLOOKUP(A21,fin_institutions!A:D,4,0),0) -> 4.07 | L21: =IFERROR(VLOOKUP(A21,bus_institutions!A:D,4,0),0) -> 6.65 | M21: =IFERROR(VLOOKUP(A21,man_institutions!A:D,4,0),0) -> 6 | N21: =ROUND(IFERROR((601-_xlfn.RANK.EQ(I21,I:I))/600,0),3) -> 0.972 | O21: =ROUND(IFERROR((601-IFERROR(_xlfn.RANK.EQ(J21,J:J),""))/600,0),3) -> 0.918 | P21: =ROUND(IFERROR((601-IFERROR(_xlfn.RANK.EQ(K21,K:K),""))/600,0),3) -> 0.958 | Q21: =ROUND(IFERROR((601-IFERROR(_xlfn.RANK.EQ(L21,L:L),""))/600,0),3) -> 0.99 | R21: =ROUND(IFERROR((601-IFERROR(_xlfn.RANK.EQ(M21,M:M),""))/600,0),3) -> 0.983 | S21: =VLOOKUP(A21,#REF!,11,0) -> #REF! | T21: =VLOOKUP(A21,#REF!,12,0) -> #REF! | U21: =VLOOKUP(A21,#REF!,13,0) -> #REF! | V21: =VLOOKUP(A21,#REF!,14,0) -> #REF! | W21: 3.2167895 | X21: 0.029288811 | Y21: =VLOOKUP(C21,AR:AS,2,0) -> FRA | Z21: =IF(Y21=Y$1,B21,IF(Y21=Y$2,B21,"")) | AR21: QATAR | AS21: QAT | AT21: 3.2537572 | AU21: 0.16279534 | AW21: INSEAD Business School
A22: Swiss Finance Institute (SFI) | B22: SFI | C22: SWITZERLAND | D22: =IFERROR(VLOOKUP(A22,eco_bus_institutions!A:D,3,0),"") -> 39 | E22: =IFERROR(VLOOKUP(A22,eco_institutions!A:D,3,0),"") -> 28 | F22: =IFERROR(VLOOKUP(A22,fin_institutions!A:D,3,0),"") -> 28 | G22: =IFERROR(VLOOKUP(A22,bus_institutions!A:D,3,0),0) -> 0 | H22: =IFERROR(VLOOKUP(A22,man_institutions!A:D,3,0),0) -> 0 | I22: =IFERROR(VLOOKUP(A22,eco_bus_institutions!A:D,4,0),0) -> 4.82 | J22: =IFERROR(VLOOKUP(A22,eco_institutions!A:D,4,0),0) -> 3.64 | K22: =IFERROR(VLOOKUP(A22,fin_institutions!A:D,4,0),0) -> 4.06 | L22: =IFERROR(VLOOKUP(A22,bus_institutions!A:D,4,0),0) -> 0 | M22: =IFERROR(VLOOKUP(A22,man_institutions!A:D,4,0),0) -> 0 | N22: =ROUND(IFERROR((601-_xlfn.RANK.EQ(I22,I:I))/600,0),3) -> 0.97 | O22: =ROUND(IFERROR((601-IFERROR(_xlfn.RANK.EQ(J22,J:J),""))/600,0),3) -> 0.953 | P22: =ROUND(IFERROR((601-IFERROR(_xlfn.RANK.EQ(K22,K:K),""))/600,0),3) -> 0.955 | Q22: =ROUND(IFERROR((601-IFERROR(_xlfn.RANK.EQ(L22,L:L),""))/600,0),3) -> 0.05 | R22: =ROUND(IFERROR((601-IFERROR(_xlfn.RANK.EQ(M22,M:M),""))/600,0),3) -> 0.04 | S22: =VLOOKUP(A22,#REF!,11,0) -> #REF! | T22: =VLOOKUP(A22,#REF!,12,0) -> #REF! | U22: =VLOOKUP(A22,#REF!,13,0) -> #REF! | V22: =VLOOKUP(A22,#REF!,14,0) -> #REF! | W22: -0.21512198 | X22: 3.0851701 | Y22: =VLOOKUP(C22,AR:AS,2,0) -> CHE | Z22: =IF(Y22=Y$1,B22,IF(Y22=Y$2,B22,"")) | AR22: PORTUGAL | AS22: PRT | AT22: 3.2521945 | AU22: 0.19565598 | AW22: Swiss Finance Institute (SFI)
A23: Washington University (WUSTL) | B23: WUSTL | C23: USA | D23: =IFERROR(VLOOKUP(A23,eco_bus_institutions!A:D,3,0),"") -> 83 | E23: =IFERROR(VLOOKUP(A23,eco_institutions!A:D,3,0),"") -> 46 | F23: =IFERROR(VLOOKUP(A23,fin_institutions!A:D,3,0),"") -> 29 | G23: =IFERROR(VLOOKUP(A23,bus_institutions!A:D,3,0),0) -> 11 | H23: =IFERROR(VLOOKUP(A23,man_institutions!A:D,3,0),0) -> 18 | I23: =IFERROR(VLOOKUP(A23,eco_bus_institutions!A:D,4,0),0) -> 4.59 | J23: =IFERROR(VLOOKUP(A23,eco_institutions!A:D,4,0),0) -> 3.75 | K23: =IFERROR(VLOOKUP(A23,fin_institutions!A:D,4,0),0) -> 4.33 | L23: =IFERROR(VLOOKUP(A23,bus_institutions!A:D,4,0),0) -> 6.42 | M23: =IFERROR(VLOOKUP(A23,man_institutions!A:D,4,0),0) -> 5.1 | N23: =ROUND(IFERROR((601-_xlfn.RANK.EQ(I23,I:I))/600,0),3) -> 0.968 | O23: =ROUND(IFERROR((601-IFERROR(_xlfn.RANK.EQ(J23,J:J),""))/600,0),3) -> 0.958 | P23: =ROUND(IFERROR((601-IFERROR(_xlfn.RANK.EQ(K23,K:K),""))/600,0),3) -> 0.963 | Q23: =ROUND(IFERROR((601-IFERROR(_xlfn.RANK.EQ(L23,L:L),""))/600,0),3) -> 0.982 | R23: =ROUND(IFERROR((601-IFERROR(_xlfn.RANK.EQ(M23,M:M),""))/600,0),3) -> 0.972 | S23: =VLOOKUP(A23,#REF!,11,0) -> #REF! | T23: =VLOOKUP(A23,#REF!,12,0) -> #REF! | U23: =VLOOKUP(A23,#REF!,13,0) -> #REF! | V23: =VLOOKUP(A23,#REF!,14,0) -> #REF! | W23: 3.2537572 | X23: 0.16279534 | Y23: =VLOOKUP(C23,AR:AS,2,0) -> USA | Z23: =IF(Y23=Y$1,B23,IF(Y23=Y$2,B23,"")) | AR23: POLAND | AS23: POL | AT23: 2.4268551 | AU23: 0.94449888 | AW23: Washington (WUSTL)
A24: Boston College | B24: Boston C | C24: USA | D24: =IFERROR(VLOOKUP(A24,eco_bus_institutions!A:D,3,0),"") -> 109 | E24: =IFERROR(VLOOKUP(A24,eco_institutions!A:D,3,0),"") -> 54 | F24: =IFERROR(VLOOKUP(A24,fin_institutions!A:D,3,0),"") -> 32 | G24: =IFERROR(VLOOKUP(A24,bus_institutions!A:D,3,0),0) -> 26 | H24: =IFERROR(VLOOKUP(A24,man_institutions!A:D,3,0),0) -> 29 | I24: =IFERROR(VLOOKUP(A24,eco_bus_institutions!A:D,4,0),0) -> 4.45 | J24: =IFERROR(VLOOKUP(A24,eco_institutions!A:D,4,0),0) -> 3.58 | K24: =IFERROR(VLOOKUP(A24,fin_institutions!A:D,4,0),0) -> 5.41 | L24: =IFERROR(VLOOKUP(A24,bus_institutions!A:D,4,0),0) -> 5.16 | M24: =IFERROR(VLOOKUP(A24,man_institutions!A:D,4,0),0) -> 5.79 | N24: =ROUND(IFERROR((601-_xlfn.RANK.EQ(I24,I:I))/600,0),3) -> 0.967 | O24: =ROUND(IFERROR((601-IFERROR(_xlfn.RANK.EQ(J24,J:J),""))/600,0),3) -> 0.948 | P24: =ROUND(IFERROR((601-IFERROR(_xlfn.RANK.EQ(K24,K:K),""))/600,0),3) -> 0.988 | Q24: =ROUND(IFERROR((601-IFERROR(_xlfn.RANK.EQ(L24,L:L),""))/600,0),3) -> 0.958 | R24: =ROUND(IFERROR((601-IFERROR(_xlfn.RANK.EQ(M24,M:M),""))/600,0),3) -> 0.98 | S24: =VLOOKUP(A24,#REF!,11,0) -> #REF! | T24: =VLOOKUP(A24,#REF!,12,0) -> #REF! | U24: =VLOOKUP(A24,#REF!,13,0) -> #REF! | V24: =VLOOKUP(A24,#REF!,14,0) -> #REF! | W24: 3.2521945 | X24: 0.19565598 | Y24: =VLOOKUP(C24,AR:AS,2,0) -> USA | Z24: =IF(Y24=Y$1,B24,IF(Y24=Y$2,B24,"")) | AR24: PAKISTAN | AS24: PAK | AT24: 2.8659921 | AU24: 0.57900989 | AW24: Boston College
A25: University of California San Diego | B25: UCSD | C25: USA | D25: =IFERROR(VLOOKUP(A25,eco_bus_institutions!A:D,3,0),"") -> 101 | E25: =IFERROR(VLOOKUP(A25,eco_institutions!A:D,3,0),"") -> 82 | F25: =IFERROR(VLOOKUP(A25,fin_institutions!A:D,3,0),"") -> 18 | G25: =IFERROR(VLOOKUP(A25,bus_institutions!A:D,3,0),0) -> 9 | H25: =IFERROR(VLOOKUP(A25,man_institutions!A:D,3,0),0) -> 7 | I25: =IFERROR(VLOOKUP(A25,eco_bus_institutions!A:D,4,0),0) -> 4.42 | J25: =IFERROR(VLOOKUP(A25,eco_institutions!A:D,4,0),0) -> 4.16 | K25: =IFERROR(VLOOKUP(A25,fin_institutions!A:D,4,0),0) -> 4.98 | L25: =IFERROR(VLOOKUP(A25,bus_institutions!A:D,4,0),0) -> 4.14 | M25: =IFERROR(VLOOKUP(A25,man_institutions!A:D,4,0),0) -> 1.65 | N25: =ROUND(IFERROR((601-_xlfn.RANK.EQ(I25,I:I))/600,0),3) -> 0.965 | O25: =ROUND(IFERROR((601-IFERROR(_xlfn.RANK.EQ(J25,J:J),""))/600,0),3) -> 0.968 | P25: =ROUND(IFERROR((601-IFERROR(_xlfn.RANK.EQ(K25,K:K),""))/600,0),3) -> 0.98 | Q25: =ROUND(IFERROR((601-IFERROR(_xlfn.RANK.EQ(L25,L:L),""))/600,0),3) -> 0.918 | R25: =ROUND(IFERROR((601-IFERROR(_xlfn.RANK.EQ(M25,M:M),""))/600,0),3) -> 0.565 | S25: =VLOOKUP(A25,#REF!,11,0) -> #REF! | T25: =VLOOKUP(A25,#REF!,12,0) -> #REF! | U25: =VLOOKUP(A25,#REF!,13,0) -> #REF! | V25: =VLOOKUP(A25,#REF!,14,0) -> #REF! | W25: 2.4268551 | X25: 0.94449888 | Y25: =VLOOKUP(C25,AR:AS,2,0) -> USA | Z25: =IF(Y25=Y$1,B25,IF(Y25=Y$2,B25,"")) | AR25: NORWAY | AS25: NOR | AT25: 3.0782438 | AU25: 0.28710048 | AW25: California San Diego
A26: Dartmouth College | B26: Dartmouth | C26: USA | D26: =IFERROR(VLOOKUP(A26,eco_bus_institutions!A:D,3,0),"") -> 54 | E26: =IFERROR(VLOOKUP(A26,eco_institutions!A:D,3,0),"") -> 30 | F26: =IFERROR(VLOOKUP(A26,fin_institutions!A:D,3,0),"") -> 12 | G26: =IFERROR(VLOOKUP(A26,bus_institutions!A:D,3,0),0) -> 10 | H26: =IFERROR(VLOOKUP(A26,man_institutions!A:D,3,0),0) -> 8 | I26: =IFERROR(VLOOKUP(A26,eco_bus_institutions!A:D,4,0),0) -> 4.3 | J26: =IFERROR(VLOOKUP(A26,eco_institutions!A:D,4,0),0) -> 4.82 | K26: =IFERROR(VLOOKUP(A26,fin_institutions!A:D,4,0),0) -> 4.61 | L26: =IFERROR(VLOOKUP(A26,bus_institutions!A:D,4,0),0) -> 3.35 | M26: =IFERROR(VLOOKUP(A26,man_institutions!A:D,4,0),0) -> 3.21 | N26: =ROUND(IFERROR((601-_xlfn.RANK.EQ(I26,I:I))/600,0),3) -> 0.963 | O26: =ROUND(IFERROR((601-IFERROR(_xlfn.RANK.EQ(J26,J:J),""))/600,0),3) -> 0.975 | P26: =ROUND(IFERROR((601-IFERROR(_xlfn.RANK.EQ(K26,K:K),""))/600,0),3) -> 0.97 | Q26: =ROUND(IFERROR((601-IFERROR(_xlfn.RANK.EQ(L26,L:L),""))/600,0),3) -> 0.84 | R26: =ROUND(IFERROR((601-IFERROR(_xlfn.RANK.EQ(M26,M:M),""))/600,0),3) -> 0.883 | S26: =VLOOKUP(A26,#REF!,11,0) -> #REF! | T26: =VLOOKUP(A26,#REF!,12,0) -> #REF! | U26: =VLOOKUP(A26,#REF!,13,0) -> #REF! | V26: =VLOOKUP(A26,#REF!,14,0) -> #REF! | W26: 2.8659921 | X26: 0.57900989 | Y26: =VLOOKUP(C26,AR:AS,2,0) -> USA | Z26: =IF(Y26=Y$1,B26,IF(Y26=Y$2,B26,"")) | AR26: NORTHERN IRELAND | AS26: UK | AT26: 2.965248 | AU26: 0.23678393 | AW26: Dartmouth College
... A44: University of California Irvine | B44: UCI | C44: USA | D44: =IFERROR(VLOOKUP(A44,eco_bus_institutions!A:D,3,0),"") -> 84 | E44: =IFERROR(VLOOKUP(A44,eco_institutions!A:D,3,0),"") -> 53 | F44: =IFERROR(VLOOKUP(A44,fin_institutions!A:D,3,0),"") -> 18 | G44: =IFERROR(VLOOKUP(A44,bus_institutions!A:D,3,0),0) -> 13 | H44: =IFERROR(VLOOKUP(A44,man_institutions!A:D,3,0),0) -> 21 | I44: =IFERROR(VLOOKUP(A44,eco_bus_institutions!A:D,4,0),0) -> 3.51 | J44: =IFERROR(VLOOKUP(A44,eco_institutions!A:D,4,0),0) -> 1.9 | K44: =IFERROR(VLOOKUP(A44,fin_institutions!A:D,4,0),0) -> 4.52 | L44: =IFERROR(VLOOKUP(A44,bus_institutions!A:D,4,0),0) -> 7.35 | M44: =IFERROR(VLOOKUP(A44,man_institutions!A:D,4,0),0) -> 7.32 | N44: =ROUND(IFERROR((601-_xlfn.RANK.EQ(I44,I:I))/600,0),3) -> 0.933 | O44: =ROUND(IFERROR((601-IFERROR(_xlfn.RANK.EQ(J44,J:J),""))/600,0),3) -> 0.818 | P44: =ROUND(IFERROR((601-IFERROR(_xlfn.RANK.EQ(K44,K:K),""))/600,0),3) -> 0.967 | Q44: =ROUND(IFERROR((601-IFERROR(_xlfn.RANK.EQ(L44,L:L),""))/600,0),3) -> 0.997 | R44: =ROUND(IFERROR((601-IFERROR(_xlfn.RANK.EQ(M44,M:M),""))/600,0),3) -> 0.997 | S44: =VLOOKUP(A44,#REF!,11,0) -> #REF! | T44: =VLOOKUP(A44,#REF!,12,0) -> #REF! | U44: =VLOOKUP(A44,#REF!,13,0) -> #REF! | V44: =VLOOKUP(A44,#REF!,14,0) -> #REF! | W44: 3.1129698 | X44: -0.23580961 | Y44: =VLOOKUP(C44,AR:AS,2,0) -> USA | Z44: =IF(Y44=Y$1,B44,IF(Y44=Y$2,B44,"")) | AR44: FINLAND | AS44: FIN | AT44: 3.0841456 | AU44: -0.061536574 | AW44: California Irvine
